Workbook

Sheet Hoja 1
A1: Tipo | B1: Nombre
A2: Taberna | B2: El Corazón de Plata
A3: Tiendas | B3: Reliquias del Dragón (objetos mágicos)
A4: Sitios importantes | B4: Palacio Real de Finesaux
B5: Plaza del Mercado Central
B6: Academia de Artes Bélicas
A7: Distritos | B7: Distrito de la Nobleza
B8: Barrio de los Artesanos

Sheet Hoja 2
A1: Año | B1: Evento | C1: Nación | D1: Ubicacion #1 | E1: Ubicacion #2 | F1: Ubicacion #3 | G1: Razas #1 | H1: Razas #2 | I1: Razas #3 | J1: Razas #4 | K1: Razas #5 | L1: Razas #6 | M1: Razas #7 | N1: Razas #8 | O1: Razas #9 | P1: Razas #10 | Q1: Razas #11 | R1: Razas #12 | S1: Razas #13 | T1: Razas #14
A2: 9071 | B2: La Primera Gran Migración | C2: Ayashii | D2: Himetsu | G2: Yokai | H2: Humanos | I2: Goblin | J2: Orcos | K2: Hombres Lagarto | L2: Hombres Pajaro | M2: Sagas | N2: Nagas | O2: Draconidos | P2: Enanos | Q2: Minotauros | R2: Elementales | S2: Hombres Gato | T2: Elfos
A3: 8964 | B3: Fragmentación inicial Clanes humanos | C3: Agreoum/Bastrea/Ascaria | D3: El Campo de Thyrene | G3: Orh | H3: Ilmar | I3: Bastian
A4: 8898 | B4: Los enanos descubren la primera veta de mithril | C4: Udrax | D4: Boomengird | G4: Martelys | H4: Runescribe | I4: Bronzeborn | J4: Silvershield
A5: 8845 | B5: Los elementales emergen en Aeon | C5: Aeon | D5: Aeon | G5: Elementales
A6: 8797 | B6: Primeras tribus goblins unifican Gliaddokx | C6: Giladdokx | D6: Cienagas del Oeste | G6: Zantox | H6: Fliark | I6: Gorthak | J6: Bleek
A7: 8765 | B7: El Gran Pacto | C7: Mistarium | D7: Mistarium | G7: Tieflings
A8: 8500 | B8: La Ascensión del Guardián del Abismo | C8: Ashye | D8: Fortaleza de Umbralia | E8: Praderas del Oro | G8: Sagas | H8: Drow | I8: Shardmind | J8: Shadar-kai
A9: 8400 | B9: La Guerra de las Zarpas | C9: Choubar | D9: Las Selvas Fronterizas, entre Bosmurg y Gongorguma | G9: Cara Loca | H9: Puño de Hierro | I9: Zarpa Sombria | J9: Piel Oscura
A10: 8300 | B10: La Rebelión de las Corrientes Oscuras | C10: Tabaxi | D10: Pantanos de Nezhura | G10: Diente de Niebla | H10: Espiral de Marfil
A11: 8200 | B11: El Juramento de las Llamas Eternas | C11: Gongorguma | D11: Gran Montaña de la Ceniza | G11: Puño de Lava
A12: 8000 | B12: El Asalto de las Bestias Aladas | C12: Choubar | D12: Las Selvas Fronterizas | G12: Cara Loca | H12: Alas Escarlata | I12: Ventobélico | J12: Zarpa Sombria
A13: 7993 | B13: Fundación de los clanes Yokai. | C13: Ayashii | D13: Himetsu | G13: Shinken | H13: Kazehana | I13: Hikarikami | J13: Honoun
A14: 7942 | B14: Primeros pueblos humanos en Bastrea | C14: Bastrea | D14: Riberas del Bast | G14: Bastrea
A15: 7942 | B15: Primeros pueblos humanos en Agreoum | C15: Aegroum
A16: 7941 | B16: Primeros pueblos elficos en Ecla | C16: Ecla
A17: 7941 | B17: Primeros pueblos orcos en Gongorguma | C17: Gongorguma
A18: 7938 | B18: Primeros pueblos gatos en Bosmurg | C18: Bosmurg
A19: 7937 | B19: Primeros pueblos minotauros en Esmua | C19: Esmua | G19: Gran Estepa | H19: Roca Partida
A20: 7937 | B20: Primeros pueblos humanos en Mistarium | C20: Mistarium | G20: Neblinia | H20: Filo Sombrío
A21: 7932 | B21: Primeros pueblos Yokai en Ayashii | C21: Ayashii
A22: 7932 | B22: Primeros pueblos en Ostad | C22: Ostad
A23: 7930 | B23: Formacion de Wulcain | C23: Wulcain
A24: 7900 | B24: El Pacto del Cristal Roto | C24: Choubar | D24: Bosque de Kelryth | G24: Tieflings | H24: Shadarmind
A25: 7891 | B25: Nagas Tabaxi crean la Ruta de las Escamas | C25: Tabaxi
A26: 7816 | B26: Primer pacto humano-enano en Udrax | C26: Udrax | D26: Montes Forja | G26: Udrax | H26: Bastrea
A28: 7744 | B28: Himetsumota se convierte en centro espiritual | C28: Ayashii | D28: Himetsu | E28: Los Jardines de las Llamas Eternas | F28: Las Cascadas Susurrantes | G28: Shinken | H28: Kazehana | I28: Hikarikami | J28: Honoun
A29: 7692 | B29: Formación de los clanes goblin en Gliaddokx | C29: Giladdokx | G29: Zorkul | H29: Ugrak | I29: Morvok | J29: Gnarz
A30: 7641 | B30: Primera alianza Aeon-Bastrea para proteger la Isla de la Convergencia. | C30: Aeon | D30: Llanuras del Eco
A31: 7632 | B31: Caida de los Cara Loca | C31: Bosmurg | D31: Llanuras Septrentionales | G31: Zarpa Sombria | H31: Cara Loca | I31: Colmillo Dorado
A32: 7600 | B32: La Purga de las Tormentas | C32: Choubar | D32: Llanuras de Ulda | G32: Ventobélico | H32: Ventoferreo
A33: 7400 | B33: La Conquista del Valle Esmeralda | C33: Choubar | D33: Las Selvas Fronterizas, entre Bosmurg y Gongorguma | G33: Hachadura | H33: Viento de Sombras
A34: 7200 | B34: El Tratado del Río Ardiente | C34: Choubar | D34: Río Ardiente
A35: 7023 | B35: Creación del consejo de clanes Yokai. | C35: Ayashii | G35: Shinken | H35: Kazehana | I35: Hikarikami | J35: Honoun
A36: 7000 | B36: Fundación de la Alianza Primaria | C36: Choubar | D36: Montañas Althir | E36: Bosque de Kelryth | G36: Ventoferreo | H36: Alas Escarlata | I36: Hierro Oscuro | J36: Oxido Hambriento | K36: Zarpa Sombría | L36: Colmillo Dorado
A37: 6967 | B37: Primer Conflicto entre Nagas y Goblins | C37: Giladdokx | D37: Selva Frondosa
A38: 6894 | B38: Primeros estudios mágicos en Ascaria | C38: Ascaria | D38: Academia de Arcania
A39: 6821 | B39: Fundación del primer templo en Ostad | C39: Ostad | D39: Pantanos Profundos
A40: 6719 | B40: Elementales cierran rutas interplanares. | C40: Aeon
A41: 6623 | B41: Fundación de la Biblioteca de Runas en Udrax | C41: Udrax | D41: Rhenor
...

Sheet Hoja 3
A1: Año | B1: Evento | C1: ="Clanes" -> Clanes | D1: ="Clanes" -> Clanes | E1: ="Clanes" -> Clanes | F1: ="Clanes" -> Clanes | G1: Ubicacion | H1: Pais
A2: 9XXX | B2: Gran Quebracion | G2: Egaroth | H2: Ayashii
A3: ='Hoja 2'!A2 -> 9071 | B3: ='Hoja 2'!B2 -> La Primera Gran Migración | C3: ="Clanes de los " & 'Hoja 2'!G2 -> Clanes de los Yokai | D3: ="Clanes de los " & 'Hoja 2'!H2 -> Clanes de los Humanos | E3: ="Clanes de los " & 'Hoja 2'!I2 -> Clanes de los Goblin | F3: ="Clanes de los " & 'Hoja 2'!J2 -> Clanes de los Orcos | G3: ='Hoja 2'!D2 -> Himetsu | H3: Aegroum
A4: ='Hoja 2'!A3 -> 8964 | B4: ='Hoja 2'!B3 -> Fragmentación inicial Clanes humanos | C4: ="Clanes de los " & 'Hoja 2'!G3 -> Clanes de los Orh | D4: ="Clanes de los " & 'Hoja 2'!H3 -> Clanes de los Ilmar | E4: ="Clanes de los " & 'Hoja 2'!I3 -> Clanes de los Bastian | F4: ="Clanes de los " & 'Hoja 2'!J3 -> Clanes de los | G4: ='Hoja 2'!D3 -> El Campo de Thyrene | H4: Udrax
A5: ='Hoja 2'!A4 -> 8898 | B5: ='Hoja 2'!B4 -> Los enanos descubren la primera veta de mithril | C5: ="Clanes de los " & 'Hoja 2'!G4 -> Clanes de los Martelys | D5: ="Clanes de los " & 'Hoja 2'!H4 -> Clanes de los Runescribe | E5: ="Clanes de los " & 'Hoja 2'!I4 -> Clanes de los Bronzeborn | F5: ="Clanes de los " & 'Hoja 2'!J4 -> Clanes de los Silvershield | G5: ='Hoja 2'!D4 -> Boomengird | H5: Boomengird
A6: 8845 | B6: ='Hoja 2'!B5 -> Los elementales emergen en Aeon | C6: ="Clanes de los " & 'Hoja 2'!G5 -> Clanes de los Elementales | D6: ="Clanes de los " & 'Hoja 2'!H5 -> Clanes de los | E6: ="Clanes de los " & 'Hoja 2'!I5 -> Clanes de los | F6: ="Clanes de los " & 'Hoja 2'!J5 -> Clanes de los | G6: ='Hoja 2'!D5 -> Aeon | H6: Ayashii
A7: ='Hoja 2'!A6 -> 8797 | B7: ='Hoja 2'!B6 -> Primeras tribus goblins unifican Gliaddokx | C7: ="Clanes de los " & 'Hoja 2'!G6 -> Clanes de los Zantox | D7: ="Clanes de los " & 'Hoja 2'!H6 -> Clanes de los Fliark | E7: ="Clanes de los " & 'Hoja 2'!I6 -> Clanes de los Gorthak | F7: ="Clanes de los " & 'Hoja 2'!J6 -> Clanes de los Bleek | G7: ='Hoja 2'!D6 -> Cienagas del Oeste | H7: Ayashii
A8: ='Hoja 2'!A7 -> 8765 | B8: ='Hoja 2'!B7 -> El Gran Pacto | C8: ="Clanes de los " & 'Hoja 2'!G7 -> Clanes de los Tieflings | D8: ="Clanes de los " & 'Hoja 2'!H7 -> Clanes de los | E8: ="Clanes de los " & 'Hoja 2'!I7 -> Clanes de los | F8: ="Clanes de los " & 'Hoja 2'!J7 -> Clanes de los | G8: ='Hoja 2'!D7 -> Mistarium | H8: Ayashii
A9: ='Hoja 2'!A8 -> 8500 | B9: ='Hoja 2'!B8 -> La Ascensión del Guardián del Abismo | C9: ="Clanes de los " & 'Hoja 2'!G8 -> Clanes de los Sagas | D9: ="Clanes de los " & 'Hoja 2'!H8 -> Clanes de los Drow | E9: ="Clanes de los " & 'Hoja 2'!I8 -> Clanes de los Shardmind | F9: ="Clanes de los " & 'Hoja 2'!J8 -> Clanes de los Shadar-kai | G9: ='Hoja 2'!D8 -> Fortaleza de Umbralia | H9: Ayashii
A10: ='Hoja 2'!A9 -> 8400 | B10: ='Hoja 2'!B9 -> La Guerra de las Zarpas | C10: ="Clanes de los " & 'Hoja 2'!G9 -> Clanes de los Cara Loca | D10: ="Clanes de los " & 'Hoja 2'!H9 -> Clanes de los Puño de Hierro | E10: ="Clanes de los " & 'Hoja 2'!I9 -> Clanes de los Zarpa Sombria | F10: ="Clanes de los " & 'Hoja 2'!J9 -> Clanes de los Piel Oscura | G10: ='Hoja 2'!D9 -> Las Selvas Fronterizas, entre Bosmurg y Gongorguma | H10: Ayashii
A11: ='Hoja 2'!A10 -> 8300 | B11: ='Hoja 2'!B10 -> La Rebelión de las Corrientes Oscuras | C11: ="Clanes de los " & 'Hoja 2'!G10 -> Clanes de los Diente de Niebla | D11: ="Clanes de los " & 'Hoja 2'!H10 -> Clanes de los Espiral de Marfil | E11: ="Clanes de los " & 'Hoja 2'!I10 -> Clanes de los | F11: ="Clanes de los " & 'Hoja 2'!J10 -> Clanes de los | G11: ='Hoja 2'!D10 -> Pantanos de Nezhura | H11: Ayashii
A12: ='Hoja 2'!A11 -> 8200 | B12: ='Hoja 2'!B11 -> El Juramento de las Llamas Eternas | C12: ="Clanes de los " & 'Hoja 2'!G11 -> Clanes de los Puño de Lava | D12: ="Clanes de los " & 'Hoja 2'!H11 -> Clanes de los | E12: ="Clanes de los " & 'Hoja 2'!I11 -> Clanes de los | F12: ="Clanes de los " & 'Hoja 2'!J11 -> Clanes de los | G12: ='Hoja 2'!D11 -> Gran Montaña de la Ceniza | H12: Ayashii
A13: ='Hoja 2'!A12 -> 8000 | B13: ='Hoja 2'!B12 -> El Asalto de las Bestias Aladas | C13: ="Clanes de los " & 'Hoja 2'!G12 -> Clanes de los Cara Loca | D13: ="Clanes de los " & 'Hoja 2'!H12 -> Clanes de los Alas Escarlata | E13: ="Clanes de los " & 'Hoja 2'!I12 -> Clanes de los Ventobélico | F13: ="Clanes de los " & 'Hoja 2'!J12 -> Clanes de los Zarpa Sombria | G13: ='Hoja 2'!D12 -> Las Selvas Fronterizas | H13: Ayashii
A14: ='Hoja 2'!A13 -> 7993 | B14: ='Hoja 2'!B13 -> Fundación de los clanes Yokai. | C14: ="Clanes de los " & 'Hoja 2'!G13 -> Clanes de los Shinken | D14: ="Clanes de los " & 'Hoja 2'!H13 -> Clanes de los Kazehana | E14: ="Clanes de los " & 'Hoja 2'!I13 -> Clanes de los Hikarikami | F14: ="Clanes de los " & 'Hoja 2'!J13 -> Clanes de los Honoun | G14: ='Hoja 2'!D13 -> Himetsu | H14: Ayashii
A15: ='Hoja 2'!A15 -> 7942 | B15: ='Hoja 2'!B15 -> Primeros pueblos humanos en Agreoum | C15: ="Clanes de los " & 'Hoja 2'!G15 -> Clanes de los | D15: ="Clanes de los " & 'Hoja 2'!H15 -> Clanes de los | E15: ="Clanes de los " & 'Hoja 2'!I15 -> Clanes de los | F15: ="Clanes de los " & 'Hoja 2'!J15 -> Clanes de los | G15: ='Hoja 2'!D15 | H15: Ayashii
A16: ='Hoja 2'!A16 -> 7941 | B16: ='Hoja 2'!B16 -> Primeros pueblos elficos en Ecla | C16: ="Clanes de los " & 'Hoja 2'!G16 -> Clanes de los | D16: ="Clanes de los " & 'Hoja 2'!H16 -> Clanes de los | E16: ="Clanes de los " & 'Hoja 2'!I16 -> Clanes de los | F16: ="Clanes de los " & 'Hoja 2'!J16 -> Clanes de los | G16: ='Hoja 2'!D16 | H16: Ayashii
A17: ='Hoja 2'!A17 -> 7941 | B17: ='Hoja 2'!B17 -> Primeros pueblos orcos en Gongorguma | C17: ="Clanes de los " & 'Hoja 2'!G17 -> Clanes de los | D17: ="Clanes de los " & 'Hoja 2'!H17 -> Clanes de los | E17: ="Clanes de los " & 'Hoja 2'!I17 -> Clanes de los | F17: ="Clanes de los " & 'Hoja 2'!J17 -> Clanes de los | G17: ='Hoja 2'!D17 | H17: Ayashii
A18: ='Hoja 2'!A18 -> 7938 | B18: ='Hoja 2'!B18 -> Primeros pueblos gatos en Bosmurg | C18: ="Clanes de los " & 'Hoja 2'!G18 -> Clanes de los | D18: ="Clanes de los " & 'Hoja 2'!H18 -> Clanes de los | E18: ="Clanes de los " & 'Hoja 2'!I18 -> Clanes de los | F18: ="Clanes de los " & 'Hoja 2'!J18 -> Clanes de los | G18: ='Hoja 2'!D18 | H18: Ayashii
A19: ='Hoja 2'!A19 -> 7937 | B19: ='Hoja 2'!B19 -> Primeros pueblos minotauros en Esmua | C19: ="Clanes de los " & 'Hoja 2'!G19 -> Clanes de los Gran Estepa | D19: ="Clanes de los " & 'Hoja 2'!H19 -> Clanes de los Roca Partida | E19: ="Clanes de los " & 'Hoja 2'!I19 -> Clanes de los | F19: ="Clanes de los " & 'Hoja 2'!J19 -> Clanes de los | G19: ='Hoja 2'!D19 | H19: Ayashii
A20: ='Hoja 2'!A20 -> 7937 | B20: ='Hoja 2'!B20 -> Primeros pueblos humanos en Mistarium | C20: ="Clanes de los " & 'Hoja 2'!G20 -> Clanes de los Neblinia | D20: ="Clanes de los " & 'Hoja 2'!H20 -> Clanes de los Filo Sombrío | E20: ="Clanes de los " & 'Hoja 2'!I20 -> Clanes de los | F20: ="Clanes de los " & 'Hoja 2'!J20 -> Clanes de los | G20: ='Hoja 2'!D20 | H20: Ayashii
A21: ='Hoja 2'!A21 -> 7932 | B21: ='Hoja 2'!B21 -> Primeros pueblos Yokai en Ayashii | C21: ="Clanes de los " & 'Hoja 2'!G21 -> Clanes de los | D21: ="Clanes de los " & 'Hoja 2'!H21 -> Clanes de los | E21: ="Clanes de los " & 'Hoja 2'!I21 -> Clanes de los | F21: ="Clanes de los " & 'Hoja 2'!J21 -> Clanes de los | G21: ='Hoja 2'!D21 | H21: Ayashii
A22: ='Hoja 2'!A22 -> 7932 | B22: ='Hoja 2'!B22 -> Primeros pueblos en Ostad | C22: ="Clanes de los " & 'Hoja 2'!G22 -> Clanes de los | D22: ="Clanes de los " & 'Hoja 2'!H22 -> Clanes de los | E22: ="Clanes de los " & 'Hoja 2'!I22 -> Clanes de los | F22: ="Clanes de los " & 'Hoja 2'!J22 -> Clanes de los | G22: ='Hoja 2'!D22 | H22: Ayashii
A23: ='Hoja 2'!A23 -> 7930 | B23: ='Hoja 2'!B23 -> Formacion de Wulcain | C23: ="Clanes de los " & 'Hoja 2'!G23 -> Clanes de los | D23: ="Clanes de los " & 'Hoja 2'!H23 -> Clanes de los | E23: ="Clanes de los " & 'Hoja 2'!I23 -> Clanes de los | F23: ="Clanes de los " & 'Hoja 2'!J23 -> Clanes de los | G23: ='Hoja 2'!D23 | H23: Ayashii
A24: ='Hoja 2'!A24 -> 7900 | B24: ='Hoja 2'!B24 -> El Pacto del Cristal Roto | C24: ="Clanes de los " & 'Hoja 2'!G24 -> Clanes de los Tieflings | D24: ="Clanes de los " & 'Hoja 2'!H24 -> Clanes de los Shadarmind | E24: ="Clanes de los " & 'Hoja 2'!I24 -> Clanes de los | F24: ="Clanes de los " & 'Hoja 2'!J24 -> Clanes de los | G24: ='Hoja 2'!D24 -> Bosque de Kelryth | H24: Ayashii
A25: ='Hoja 2'!A25 -> 7891 | B25: ='Hoja 2'!B25 -> Nagas Tabaxi crean la Ruta de las Escamas | C25: ="Clanes de los " & 'Hoja 2'!G25 -> Clanes de los | D25: ="Clanes de los " & 'Hoja 2'!H25 -> Clanes de los | E25: ="Clanes de los " & 'Hoja 2'!I25 -> Clanes de los | F25: ="Clanes de los " & 'Hoja 2'!J25 -> Clanes de los | G25: ='Hoja 2'!D25 | H25: Ayashii
A26: ='Hoja 2'!A26 -> 7816 | B26: ='Hoja 2'!B26 -> Primer pacto humano-enano en Udrax | C26: ="Clanes de los " & 'Hoja 2'!G26 -> Clanes de los Udrax | D26: ="Clanes de los " & 'Hoja 2'!H26 -> Clanes de los Bastrea | E26: ="Clanes de los " & 'Hoja 2'!I26 -> Clanes de los | F26: ="Clanes de los " & 'Hoja 2'!J26 -> Clanes de los | G26: ='Hoja 2'!D26 -> Montes Forja | H26: Ayashii
... A30: ='Hoja 2'!A30 -> 7641 | B30: ='Hoja 2'!B30 -> Primera alianza Aeon-Bastrea para proteger la Isla de la Convergencia. | C30: ="Clanes de los " & 'Hoja 2'!G30 -> Clanes de los | D30: ="Clanes de los " & 'Hoja 2'!H30 -> Clanes de los | E30: ="Clanes de los " & 'Hoja 2'!I30 -> Clanes de los | F30: ="Clanes de los " & 'Hoja 2'!J30 -> Clanes de los | G30: ='Hoja 2'!D30 -> Llanuras del Eco | H30: Ayashii
A31: ='Hoja 2'!A32 -> 7600 | B31: ='Hoja 2'!B32 -> La Purga de las Tormentas | C31: ="Clanes de los " & 'Hoja 2'!G32 -> Clanes de los Ventobélico | D31: ="Clanes de los " & 'Hoja 2'!H32 -> Clanes de los Ventoferreo | E31: ="Clanes de los " & 'Hoja 2'!I32 -> Clanes de los | F31: ="Clanes de los " & 'Hoja 2'!J32 -> Clanes de los | G31: ='Hoja 2'!D32 -> Llanuras de Ulda | H31: Ayashii
A32: ='Hoja 2'!A33 -> 7400 | B32: ='Hoja 2'!B33 -> La Conquista del Valle Esmeralda | C32: ="Clanes de los " & 'Hoja 2'!G33 -> Clanes de los Hachadura | D32: ="Clanes de los " & 'Hoja 2'!H33 -> Clanes de los Viento de Sombras | E32: ="Clanes de los " & 'Hoja 2'!I33 -> Clanes de los | F32: ="Clanes de los " & 'Hoja 2'!J33 -> Clanes de los | G32: ='Hoja 2'!D33 -> Las Selvas Fronterizas, entre Bosmurg y Gongorguma | H32: Ayashii
A33: ='Hoja 2'!A34 -> 7200 | B33: ='Hoja 2'!B34 -> El Tratado del Río Ardiente | C33: ="Clanes de los " & 'Hoja 2'!G35 -> Clanes de los Shinken | D33: ="Clanes de los " & 'Hoja 2'!H35 -> Clanes de los Kazehana | E33: ="Clanes de los " & 'Hoja 2'!I35 -> Clanes de los Hikarikami | F33: ="Clanes de los " & 'Hoja 2'!J35 -> Clanes de los Honoun | G33: ='Hoja 2'!D34 -> Río Ardiente | H33: Ayashii
A34: ='Hoja 2'!A35 -> 7023 | B34: ='Hoja 2'!B35 -> Creación del consejo de clanes Yokai. | C34: ="Clanes de los " & #REF! -> #REF! | D34: ="Clanes de los " & #REF! -> #REF! | E34: ="Clanes de los " & #REF! -> #REF! | F34: ="Clanes de los " & #REF! -> #REF! | G34: ='Hoja 2'!D35 | H34: Ayashii
A35: ='Hoja 2'!A37 -> 6967 | B35: ='Hoja 2'!B37 -> Primer Conflicto entre Nagas y Goblins | C35: ="Clanes de los " & 'Hoja 2'!G37 -> Clanes de los | D35: ="Clanes de los " & 'Hoja 2'!H37 -> Clanes de los | E35: ="Clanes de los " & 'Hoja 2'!I37 -> Clanes de los | F35: ="Clanes de los " & 'Hoja 2'!J37 -> Clanes de los | G35: ='Hoja 2'!D37 -> Selva Frondosa | H35: Ayashii
A36: ='Hoja 2'!A38 -> 6894 | B36: ='Hoja 2'!B38 -> Primeros estudios mágicos en Ascaria | C36: ="Clanes de los " & 'Hoja 2'!G38 -> Clanes de los | D36: ="Clanes de los " & 'Hoja 2'!H38 -> Clanes de los | E36: ="Clanes de los " & 'Hoja 2'!I38 -> Clanes de los | F36: ="Clanes de los " & 'Hoja 2'!J38 -> Clanes de los | G36: ='Hoja 2'!D38 -> Academia de Arcania | H36: Ayashii
A37: ='Hoja 2'!A39 -> 6821 | B37: ='Hoja 2'!B39 -> Fundación del primer templo en Ostad | C37: ="Clanes de los " & 'Hoja 2'!G39 -> Clanes de los | D37: ="Clanes de los " & 'Hoja 2'!H39 -> Clanes de los | E37: ="Clanes de los " & 'Hoja 2'!I39 -> Clanes de los | F37: ="Clanes de los " & 'Hoja 2'!J39 -> Clanes de los | G37: ='Hoja 2'!D39 -> Pantanos Profundos | H37: Ayashii
A38: ='Hoja 2'!A40 -> 6719 | B38: ='Hoja 2'!B40 -> Elementales cierran rutas interplanares. | C38: ="Clanes de los " & 'Hoja 2'!G40 -> Clanes de los | D38: ="Clanes de los " & 'Hoja 2'!H40 -> Clanes de los | E38: ="Clanes de los " & 'Hoja 2'!I40 -> Clanes de los | F38: ="Clanes de los " & 'Hoja 2'!J40 -> Clanes de los | G38: ='Hoja 2'!D40 | H38: Ayashii
A39: ='Hoja 2'!A41 -> 6623 | B39: ='Hoja 2'!B41 -> Fundación de la Biblioteca de Runas en Udrax | C39: ="Clanes de los " & 'Hoja 2'!G41 -> Clanes de los | D39: ="Clanes de los " & 'Hoja 2'!H41 -> Clanes de los | E39: ="Clanes de los " & 'Hoja 2'!I41 -> Clanes de los | F39: ="Clanes de los " & 'Hoja 2'!J41 -> Clanes de los | G39: ='Hoja 2'!D41 -> Rhenor | H39: Ayashii
A40: ='Hoja 2'!A43 -> 6002 | B40: ='Hoja 2'!B43 -> Nagas y Hombres Lagarto enfrentan a Bastrea en la Guerra del Pantano. | C40: ="Clanes de los " & 'Hoja 2'!G43 -> Clanes de los Freixes de Foc | D40: ="Clanes de los " & 'Hoja 2'!H43 -> Clanes de los Guillemot Velmont | E40: ="Clanes de los " & 'Hoja 2'!I43 -> Clanes de los Sabater Caballé | F40: ="Clanes de los " & 'Hoja 2'!J43 -> Clanes de los | G40: ='Hoja 2'!D43 | H40: Ayashii
A41: ='Hoja 2'!A44 -> 5970 | B41: ='Hoja 2'!B44 -> La Guerra de las Espadas Susurrantes | C41: ="Clanes de los " & 'Hoja 2'!G44 -> Clanes de los Tieflings | D41: ="Clanes de los " & 'Hoja 2'!H44 -> Clanes de los Drows | E41: ="Clanes de los " & 'Hoja 2'!I44 -> Clanes de los Shadar-kai | F41: ="Clanes de los " & 'Hoja 2'!J44 -> Clanes de los | G41: ='Hoja 2'!D44 -> Isla de la Penuria. | H41: Ayashii
A42: ='Hoja 2'!A45 -> 5961 | B42: ='Hoja 2'!B45 -> Inicio de las Guerras del Fuego. | C42: ="Clanes de los " & 'Hoja 2'!G45 -> Clanes de los Ignífera | D42: ="Clanes de los " & 'Hoja 2'!H45 -> Clanes de los Aqualis | E42: ="Clanes de los " & 'Hoja 2'!I45 -> Clanes de los Aerium | F42: ="Clanes de los " & 'Hoja 2'!J45 -> Clanes de los Terranox | G42: ='Hoja 2'!D45 -> Llanuras del Eco | H42: Ayashii
A43: ='Hoja 2'!A46 -> 5912 | B43: ='Hoja 2'!B46 -> Construcción de la Muralla de Ascaria | C43: ="Clanes de los " & 'Hoja 2'!G46 -> Clanes de los Mirathis | D43: ="Clanes de los " & 'Hoja 2'!H46 -> Clanes de los Kaelid | E43: ="Clanes de los " & 'Hoja 2'!I46 -> Clanes de los Eldrayne | F43: ="Clanes de los " & 'Hoja 2'!J46 -> Clanes de los | G43: ='Hoja 2'!D46 -> Finesaux | H43: Ayashii
...

Sheet Hoja 4
A1: ~ | B1: ~ | C1: ~ | D1: ~ | E1: ~ | F1: ~ | G1: ~ | H1: ~ | I1: ~ | J1: ~ | K1: ~ | L1: ~ | M1: ~ | N1: ~ | O1: ~ | P1: ~ | Q1: ~ | R1: ~ | S1: ~ | T1: ~ | U1: ~ | V1: ~ | W1: ~ | X1: ~ | Y1: ~ | Z1: ~
A2: ~ | B2: ~ | C2: ~ | D2: ~ | E2: Aeon | F2: Aeon | G2: Aeon | H2: Aeon | I2: Aeon | J2: Aeon | K2: Aeon | L2: ~ | M2: ~ | N2: ~ | O2: ~ | P2: Nocturnsea | Q2: Nocturnsea | R2: Nocturnsea | S2: Nocturnsea | T2: ~ | U2: ~ | V2: Mistarium | W2: ~ | X2: Mistarium | Y2: ~ | Z2: ~
A3: ~ | B3: ~ | C3: ~ | D3: ~ | E3: Aeon | F3: Aeon | G3: Aeon | H3: Aeon | I3: Aeon | J3: Aeon | K3: Aeon | L3: ~ | M3: ~ | N3: ~ | O3: ~ | P3: Nocturnsea | Q3: Nocturnsea | R3: Nocturnsea | S3: Nocturnsea | T3: ~ | U3: ~ | V3: ~ | W3: ~ | X3: Mistarium | Y3: Mistarium | Z3: ~
A4: ~ | B4: Ayashii | C4: Ayashii | D4: ~ | E4: Aeon | F4: Aeon | G4: Aeon | H4: Aeon | I4: Aeon | J4: Aeon | K4: Aeon | L4: ~ | M4: ~ | N4: ~ | O4: ~ | P4: ~ | Q4: ~ | R4: ~ | S4: ~ | T4: ~ | U4: ~ | V4: Mistarium | W4: ~ | X4: ~ | Y4: ~ | Z4: ~
A5: ~ | B5: Ayashii | C5: Ayashii | D5: ~ | E5: ~ | F5: ~ | G5: ~ | H5: ~ | I5: ~ | J5: ~ | K5: ~ | L5: ~ | M5: ~ | N5: ~ | O5: ~ | P5: ~ | Q5: Gongorguma | R5: Gongorguma | S5: ~ | T5: ~ | U5: ~ | V5: Mistarium | W5: ~ | X5: ~ | Y5: Gongorguma | Z5: ~
A6: ~ | B6: ~ | C6: ~ | D6: ~ | E6: ~ | F6: ~ | G6: ~ | H6: ~ | I6: ~ | J6: ~ | K6: ~ | L6: ~ | M6: ~ | N6: ~ | O6: ~ | P6: ~ | Q6: Gongorguma | R6: Gongorguma | S6: ~ | T6: ~ | U6: ~ | V6: ~ | W6: ~ | X6: Gongorguma | Y6: Gongorguma | Z6: ~
A7: ~ | B7: ~ | C7: ~ | D7: ~ | E7: ~ | F7: ~ | G7: ~ | H7: ~ | I7: ~ | J7: ~ | K7: ~ | L7: ~ | M7: Ostad | N7: ~ | O7: ~ | P7: ~ | Q7: Gongorguma | R7: Gongorguma | S7: Gongorguma | T7: Gongorguma | U7: Gongorguma | V7: Gongorguma | W7: Gongorguma | X7: Gongorguma | Y7: Gongorguma | Z7: ~
A8: ~ | B8: ~ | C8: ~ | D8: ~ | E8: ~ | F8: ~ | G8: ~ | H8: ~ | I8: Ostad | J8: Ostad | K8: Ostad | L8: Ostad | M8: Ostad | N8: ~ | O8: ~ | P8: ~ | Q8: ~ | R8: Gongorguma | S8: Gongorguma | T8: Gongorguma | U8: Gongorguma | V8: Gongorguma | W8: Gongorguma | X8: Gongorguma | Y8: ~ | Z8: ~
A9: ~ | B9: ~ | C9: ~ | D9: Ecla | E9: ~ | F9: ~ | G9: ~ | H9: ~ | I9: Ostad | J9: Ostad | K9: Ostad | L9: Ostad | M9: Ostad | N9: ~ | O9: ~ | P9: ~ | Q9: ~ | R9: ~ | S9: Gongorguma | T9: Gongorguma | U9: Gongorguma | V9: Gongorguma | W9: Gongorguma | X9: ~ | Y9: ~ | Z9: ~
A10: ~ | B10: Tabaxi | C10: ~ | D10: ~ | E10: ~ | F10: Ecla | G10: Ecla | H10: Ecla | I10: Udrax | J10: Gliaddokx | K10: Gliaddokx | L10: Gliaddokx | M10: Gliaddokx | N10: ~ | O10: ~ | P10: ~ | Q10: ~ | R10: ~ | S10: ~ | T10: Gongorguma | U10: Gongorguma | V10: Gongorguma | W10: Gongorguma | X10: ~ | Y10: ~ | Z10: ~
A11: ~ | B11: Tabaxi | C11: ~ | D11: ~ | E11: Ecla | F11: Ecla | G11: Ecla | H11: Ecla | I11: Udrax | J11: Udrax | K11: Gliaddokx | L11: Gliaddokx | M11: Gliaddokx | N11: ~ | O11: ~ | P11: ~ | Q11: ~ | R11: ~ | S11: ~ | T11: Choubar | U11: Choubar | V11: Choubar | W11: Choubar | X11: ~ | Y11: ~ | Z11: ~
A12: ~ | B12: Tabaxi | C12: Tabaxi | D12: ~ | E12: Ecla | F12: Ecla | G12: Ecla | H12: Ecla | I12: Udrax | J12: Udrax | K12: Udrax | L12: Udrax | M12: Gliaddokx | N12: ~ | O12: ~ | P12: ~ | Q12: ~ | R12: ~ | S12: ~ | T12: Ashye | U12: Ashye | V12: Choubar | W12: Choubar | X12: ~ | Y12: ~ | Z12: ~
... A26: ~ | B26: ~ | C26: ~ | D26: ~ | E26: ~ | F26: ~ | G26: ~ | H26: ~ | I26: ~ | J26: ~ | K26: ~ | L26: ~ | M26: ~ | N26: ~ | O26: ~ | P26: ~ | Q26: ~ | R26: ~ | S26: ~ | T26: ~ | U26: ~ | V26: ~ | W26: ~ | X26: ~ | Y26: ~ | Z26: ~

Sheet Hoja 5
A1: ... | B1: ... | C1: ... | D1: ... | E1: ... | F1: ... | G1: ... | H1: ... | I1: ... | J1: ... | K1: ... | L1: ... | M1: ... | N1: ... | O1: ... | P1: ...
A2: ... | B2: ~ | C2: ~ | D2: ~ | E2: ~ | F2: E | G2: E | H2: U | I2: U | J2: U | K2: U | L2: U | M2: 🟥 | N2: ~ | O2: ~ | P2: ...
A3: ... | B3: ~ | C3: ~ | D3: ~ | E3: ~ | F3: ~ | G3: ~ | H3: ~ | I3: ~ | J3: ~ | K3: C | L3: 🟥 | M3: 🟥 | N3: ~ | O3: ~ | P3: ...
A4: ... | B4: ~ | C4: ~ | D4: ~ | E4: C | F4: C | G4: 🟩 | H4: 🟩 | I4: 🟦 | J4: C | K4: C | L4: 🟥 | M4: ~ | N4: ~ | O4: ~ | P4: ...
A5: ... | B5: ~ | C5: I | D5: ~ | E5: C | F5: 🟩 | G5: 🟩 | H5: 🟩 | I5: 🟦 | J5: 🟦 | K5: C | L5: C | M5: ~ | N5: ~ | O5: ~ | P5: ...
A6: ... | B6: ~ | C6: ~ | D6: ~ | E6: C | F6: 🟩 | G6: 🟦 | H6: 🟦 | I6: 🟦 | J6: C | K6: C | L6: 🟧 | M6: ~ | N6: ~ | O6: ~ | P6: ...
A7: ... | B7: I | C7: ~ | D7: ~ | E7: C | F7: 🟦 | G7: 🟦 | H7: C | I7: C | J7: 🟧 | K7: 🟧 | L7: 🟧 | M7: ~ | N7: ~ | O7: ~ | P7: ...
A8: ... | B8: ~ | C8: ~ | D8: ~ | E8: 🟦 | F8: 🟦 | G8: C | H8: C | I8: C | J8: C | K8: 🟧 | L8: ~ | M8: ~ | N8: ~ | O8: ~ | P8: ...
A9: ... | B9: ~ | C9: I | D9: ~ | E9: C | F9: C | G9: C | H9: C | I9: C | J9: ~ | K9: ~ | L9: ~ | M9: ~ | N9: ~ | O9: ~ | P9: ...
A10: ... | B10: ~ | C10: ~ | D10: ~ | E10: ~ | F10: C | G10: C | H10: C | I10: ~ | J10: ~ | K10: ~ | L10: ~ | M10: ~ | N10: ~ | O10: ~ | P10: ...
A11: ... | B11: ... | C11: ... | D11: ... | E11: ... | F11: ... | G11: ... | H11: ... | I11: ... | J11: ... | K11: ... | L11: ... | M11: ... | N11: ... | O11: ... | P11: ...
A13: ... | B13: ... | C13: ... | D13: ... | E13: ... | F13: ... | G13: ... | H13: ... | I13: ... | J13: ... | K13: ... | L13: ... | M13: ... | N13: ... | O13: ... | P13: ...
... A22: ... | B22: ~ | C22: ~ | D22: ~ | E22: ~ | F22: C | G22: C | H22: C | I22: ~ | J22: ~ | K22: ~ | L22: ~ | M22: ~ | N22: ~ | O22: ~ | P22: ...
B23: ~ | C23: ~ | D23: ~ | E23: ~ | F23: ~ | G23: ~ | H23: ~ | I23: ~ | J23: ~ | K23: ~ | L23: ~ | M23: ~ | N23: ~ | O23: ~ | P23: ...
A24: ... | B24: ... | C24: ... | D24: ... | E24: ... | F24: ... | G24: ... | H24: ... | I24: ... | J24: ... | K24: ... | L24: ... | M24: ... | N24: ... | O24: ... | P24: ...
