Workbook

Sheet Index
B2: Index | D2: Campañas
B3: Campañas | D3: Campaña 01
B4: Loots | D4: Campaña 02 | E4: Campaña 02.2 | F4: Campaña 02.4
B5: Enemigos | D5: Campaña 3
B6: Secretos
B7: Finales
B8: Objetos
B9: Años

Sheet Clases  Razas
A1: RAZAS/CREADORES | B1: EGOS | C1: EROS | D1: CHRONOS | E1: SOFÍA | F1: ENVIDIA | G1: VIDA | H1: MUERTE | I1: VENTAJAS | J1: DESVENTAJAS
A2: Hombres Lagarto | B2: SI | C2: NO | D2: SI | E2: SI | F2: NO | G2: NEUTRAL | H2: SI | I2: FUE+CONS | J2: INT+CAR | K2: "+3, +3 | -3, -3"
A3: Hombres Pájaro | B3: NO | C3: SI | D3: NEUTRAL | E3: SI | F3: NO | G3: SI | H3: NEUTRAL | I3: DES | J3: CONS+INT | K3: "+6 | -3, -3"
A4: Hombres Gato | B4: NEUTRAL | C4: NEUTRAL | D4: NO | E4: SI | F4: SI | G4: SI | H4: NEUTRAL | I4: CAR+DES+SAB | J4: INT+FUE+CONS | K4: "+2,+2 +2 | -2, -2, -2"
A5: Minotauros | B5: SI | C5: SI | D5: NEUTRAL | E5: NO | F5: SI | G5: SI | H5: NO | I5: CONS+FUE | J5: SAB+INT | K5: "+3, +3 | -3, -3"
A6: Sagas | B6: SI | C6: SI | D6: NEUTRAL | E6: NO | F6: SI | G6: NO | H6: SI | I6: FUE+INT | J6: CONS+CAR | K6: "+3, +3 | -3, -3"
A7: Orcos | B7: NEUTRAL | C7: SI | D7: SI | E7: SI | F7: NEUTRAL | G7: SI | H7: NO | I7: FUE+CONS+CAR | J7: DES | K7: "+2, +2, +2 | -6"
A8: Medianos | B8: NO | C8: NEUTRAL | D8: SI | E8: NO | F8: NO | G8: NEUTRAL | H8: SI | I8: INT+DES | J8: CONS | K8: "+3,+3 | -6"
A9: Elfos | B9: NEUTRAL | C9: SI | D9: SI | E9: SI | F9: NO | G9: SI | H9: NO | I9: CAR+INT+SAB+DES | J9: CONS+FUE | K9: "+2, +1, +1,+ 2 | -3, -3"
A10: Enanos | B10: SI | C10: NO | D10: NEUTRAL | E10: SI | F10: SI | G10: NEUTRAL | H10: SI | I10: CONS+FUE+SAB | J10: CAR+INT | K10: "+3, +1, +2 | -3, -3"
A11: Yokai | B11: NO | C11: SI | D11: SI | E11: NEUTRAL | F11: NEUTRAL | G11: NO | H11: SI | I11: CAR+INT | J11: CONS | K11: "+3 ,+3 | -6"
A12: Poseídos | B12: NEUTRAL | C12: NO | D12: NEUTRAL | E12: SI | F12: SI | G12: NO | H12: SI | I12: DES+SAB | J12: CAR+CONS | K12: "+3,+3 | -3, -3"
A13: Elfos Oscuros | B13: NEUTRAL | C13: NO | D13: NEUTRAL | E13: SI | F13: SI | G13: NO | H13: SI | I13: DES+INT+SAB | J13: CAR+FUE | K13: "+3,+1,+2 | -3, -3"
... A20: Perdidos | B20: SI | C20: NEUTRAL | D20: NO | E20: SI | F20: SI | G20: NO | H20: SI | I20: INT+CAR | J20: FUE+CONS | K20: "+3,+3 | -3, -3"
A22: CLASES | B22: VENTAJAS | C22: DESVENTAJAS | D22: COMPETENCIAS MARICALES | E22: COMPETENCIAS MAGICAS | F22: DEBILIDADES | G22: FORTALEZAS | H22: SALVACIONES | I22: PERDICIONES | J22: NIVELES | K22: ESPECIALIZACION | L22: PROFESIONES | M22: MORALIDAD | N22: ATRIBUTOS
A23: PALADIN | B23: CONS | C23: DES | D23: Bastones, Mazas, Esapadas cortas | E23: Control de Vida, Bendiciones, Curaciones, Magia de evocación media. | F23: Sombras | G23: Luz | H23: CONS+INT Luz | I23: CAR+DES Oscuridad | J23: 3-5-7-10-13-16-19 | K23: BENDICIONES | L23: Cualquier oficio noble y respetuoso. | M23: LEGAL | N23: Monturas
A24: GUERRERO | B24: FUE | C24: CAR | D24: Armas afiladas | E24: Moral. | F24: Magia de evasión | G24: Ataque cuerpo a cuerpo | H24: FUE+CONS | I24: SAB+INT | J24: 3-5-7-10-13-16-19 | K24: ESPADA LARGA | L24: Mercenario, caballero, herrero... | M24: NEUTRAL | N24: Monturas, Estrategia militar.
A25: MAGO | B25: SAB+INT | C25: FUE+CONS | D25: Bastones, ballestas. | E25: Cualquier magia en la que se especialice. | F25: Ataque cuerpo a cuerpo | G25: Magia a distancia. | H25: SAB+INT | I25: FUE+CONS | J25: 3-5-7-10-13-16-19 | K25: CREACIÓN DE PERGAMINOS MÁGICOS. | L25: Alquimista, escritor, investigador. | M25: LEGAL/NEUTRAL | N25: Conocimiento rúnico.
A26: HECHICERO | B26: INT+CAR | C26: DES+CONS | D26: Espadas cortas, dagas, varitas. | E26: Imbuir armas, hechizos elementales. | F26: Contrahechizos. | G26: Prestidigitación. | H26: INT+CAR Somnolencia | I26: DES+CONS Veneno | J26: 3-5-7-10-13-16-19 | K26: Magia de combate cuerpo a cuerpo. | L26: Escritor, investigador, caballero. | M26: NEUTRAL | N26: Monturas mágicas.
A27: BRUJO | B27: SAB+CAR | C27: INT+CONS | D27: Dagas, bastones, ballestas. | E27: Invocaciones, hechizos de combate, control de masas. | F27: Ataques no mágicos. | G27: Escudos mágicos. | H27: SAB+CAR Oscuridad | I27: INT+CONS Luz | J27: 3-5-7-10-13-16-19 | K27: Mágia demoníaca, armas cortas. | L27: Alquimista, escritor, investigador. | M27: CAOTICO NEUTRAL | N27: Control de masas.
A28: PÍCARO | B28: CAR+DES | C28: FUE+CONS | D28: Dagas, bastones, ballestas. | E28: Ocultación, sombras. | F28: Luz, ataques mágicos. | G28: Sigilo, contraataque. | H28: CAR+DES Acrobacias, Sigilo, Veneno. | I28: FUE+CONS Magia. | J28: 3-5-7-10-13-16-19 | K28: Armas cortas, Sigilo, Estados alterados. | L28: Ladrón, espía, actor, mercenario. | M28: CAOTICO NEUTRAL | N28: Anonimato.
A29: BARDO | B29: INT+CAR | C29: FUE+CONS | D29: Instrumentos, armas cortas, ballesta. | E29: Control de masas, bendiciones, control de vida. | F29: Ataque cuerpo a cuerpo. | G29: Interpretación, apoyo. | H29: INT+CAR Interpretación | I29: FUE+CONS Seducción. | J29: 3-5-7-10-13-16-19 | K29: Instrumentos, Persuasión. | L29: Artista, vendedor. | M29: CAOTICO/LEGAL | N29: Magia musical.
A30: BÁRBARO | B30: FUE+CONS | C30: SAB+INT | D30: Armas pesadas, Armas arrojadizas. | E30: Moral. | F30: Ataques mágicos, Moral. | G30: Ataque cuerpo a cuerpo, Moral. | H30: FUE+CONS Adrenalina | I30: INT+SAB Magia. | J30: 3-5-7-10-13-16-19 | K30: Armas pesadas, Ataque múltiple, Sed de Sangre. | L30: Caballero, mercenario, herrero... | M30: CAOTICO/LEGAL | N30: Resistencia.
A31: ARTIFICIERO | B31: INT+CAR+DES | C31: FUE+CONS | D31: Armas de fuego, Explosivos. | E31: Tecnología. | F31: Ataque cuerpo a cuerpo. | G31: Ataque a distancia, huida. | H31: INT+CAR+DES Tecnología. | I31: FUE+CONS Falla de energía. | J31: 3-5-7-10-13-16-19 | K31: Armas de fuego, Ataque a distancia. | L31: Profesor, Vendedor, Investigador. | M31: CAOTICO NEUTRAL | N31: Puntería.
A32: DRUIDA | B32: INT+SAB | C32: CAR+CONS | D32: Bastones, armas cuerpo a cuerpo, armas marciales. | E32: Magia de la naturaleza, Taumaturgia. | F32: Ataque cuerpo a cuerpo. | G32: Magia Lunar. | H32: INT+SAB Fortaleza Salvaje. | I32: CAR+CONS | J32: 3-5-7-10-13-16-19 | K32: Conexión con la naturaleza, druidismo variado. | L32: Boticario, leñador. | M32: CAOTICO/LEGAL | N32: Naturaleza.
A33: CAZADOR | B33: DES+INT | C33: FUE+CONS | D33: Ballestas, armas cortas, arcos. | E33: Control de la naturaleza, venenos, camuflaje. | F33: Magia, Armas pesadas. | G33: Ataque a distancia, huida. | H33: DES+INT | I33: FUE+CONS | J33: 3-5-7-10-13-16-19 | K33: Agilidad en combate, Sigilo. | L33: Leñador, Comerciante. | M33: LEGAL NEUTRAL | N33: Puntería.
A34: CHAMÁN | B34: SAB+CAR | C34: DES+CONS | D34: Lucha cuerpo a cuerpo, bastones. | E34: Invocación totémica, bendiciones elementales. | F34: Corrupción, ataque a distancia. | G34: Ataque cuerpo a cuerpo, apoyo grupal. | H34: SAB+CAR Regeneración Natural. | I34: DES+CONS Recuperaciones lentas. | J34: 3-5-7-10-13-16-19 | K34: Combate cuerpo a cuerpo, magia elemental. | L34: Monje, escritor, comerciante. | M34: CAOTICO/LEGAL | N34: Contacto con los espíritus.

Sheet LVL
B2: ='Bonificadores - Bastrea Guerrer'!E1 -> Humano de Bastrea, Guerrero de Nivel 30 | G2: 30 | I2: ='Bonificadores - Ascaria Guerrer'!E1 -> Humano de Ascaria, Guerrero de Nivel 30 | N2: 30
B3: ='Bonificadores - Bastrea Guerrer'!E2 -> Fue | C3: ='Bonificadores - Bastrea Guerrer'!F2 -> Des | D3: ='Bonificadores - Bastrea Guerrer'!G2 -> Con | E3: ='Bonificadores - Bastrea Guerrer'!H2 -> Int | F3: ='Bonificadores - Bastrea Guerrer'!I2 -> Sab | G3: ='Bonificadores - Bastrea Guerrer'!J2 -> Car | I3: ='Bonificadores - Ascaria Guerrer'!E2 -> Fue | J3: ='Bonificadores - Ascaria Guerrer'!F2 -> Des | K3: ='Bonificadores - Ascaria Guerrer'!G2 -> Con | L3: ='Bonificadores - Ascaria Guerrer'!H2 -> Int | M3: ='Bonificadores - Ascaria Guerrer'!I2 -> Sab | N3: ='Bonificadores - Ascaria Guerrer'!J2 -> Car
B4: ='Bonificadores - Bastrea Guerrer'!E3 -> 76 | C4: ='Bonificadores - Bastrea Guerrer'!F3 -> 44 | D4: ='Bonificadores - Bastrea Guerrer'!G3 -> 9 | E4: ='Bonificadores - Bastrea Guerrer'!H3 -> 10 | F4: ='Bonificadores - Bastrea Guerrer'!I3 -> 40 | G4: ='Bonificadores - Bastrea Guerrer'!J3 -> 11 | I4: ='Bonificadores - Ascaria Guerrer'!E3 -> 44 | J4: ='Bonificadores - Ascaria Guerrer'!F3 -> 12 | K4: ='Bonificadores - Ascaria Guerrer'!G3 -> 10 | L4: ='Bonificadores - Ascaria Guerrer'!H3 -> 42 | M4: ='Bonificadores - Ascaria Guerrer'!I3 -> 41 | N4: ='Bonificadores - Ascaria Guerrer'!J3 -> 11
B5: ='Bonificadores - Bastrea Guerrer'!E4 -> 30.746659 | C5: ='Bonificadores - Bastrea Guerrer'!F4 -> 14.519507 | D5: ='Bonificadores - Bastrea Guerrer'!G4 -> -3 | E5: ='Bonificadores - Bastrea Guerrer'!H4 -> -2 | F5: ='Bonificadores - Bastrea Guerrer'!I4 -> 12.55258 | G5: ='Bonificadores - Bastrea Guerrer'!J4 -> -2 | I5: ='Bonificadores - Ascaria Guerrer'!E4 -> 14.519507 | J5: ='Bonificadores - Ascaria Guerrer'!F4 -> -1 | K5: ='Bonificadores - Ascaria Guerrer'!G4 -> -2 | L5: ='Bonificadores - Ascaria Guerrer'!H4 -> 13.536044 | M5: ='Bonificadores - Ascaria Guerrer'!I4 -> 13.044312 | N5: ='Bonificadores - Ascaria Guerrer'!J4 -> -2
B7: ='Bonificadores - Bastrea Paladin'!E1 -> Humano de Bastrea, Paladin de Nivel 30 | G7: 30 | I7: ='Bonificadores - Ascaria Paladin'!E1 -> Humano de Ascaria, Paladin de Nivel 30 | N7: 30
B8: ='Bonificadores - Bastrea Paladin'!E2 -> Fue | C8: ='Bonificadores - Bastrea Paladin'!F2 -> Des | D8: ='Bonificadores - Bastrea Paladin'!G2 -> Con | E8: ='Bonificadores - Bastrea Paladin'!H2 -> Int | F8: ='Bonificadores - Bastrea Paladin'!I2 -> Sab | G8: ='Bonificadores - Bastrea Paladin'!J2 -> Car | I8: ='Bonificadores - Ascaria Paladin'!E2 -> Fue | J8: ='Bonificadores - Ascaria Paladin'!F2 -> Des | K8: ='Bonificadores - Ascaria Paladin'!G2 -> Con | L8: ='Bonificadores - Ascaria Paladin'!H2 -> Int | M8: ='Bonificadores - Ascaria Paladin'!I2 -> Sab | N8: ='Bonificadores - Ascaria Paladin'!J2 -> Car
B9: ='Bonificadores - Bastrea Paladin'!E3 -> 44 | C9: ='Bonificadores - Bastrea Paladin'!F3 -> 43 | D9: ='Bonificadores - Bastrea Paladin'!G3 -> 39 | E9: ='Bonificadores - Bastrea Paladin'!H3 -> 10 | F9: ='Bonificadores - Bastrea Paladin'!I3 -> 42 | G9: ='Bonificadores - Bastrea Paladin'!J3 -> 12 | I9: ='Bonificadores - Ascaria Paladin'!E3 -> 14 | J9: ='Bonificadores - Ascaria Paladin'!F3 -> 11 | K9: ='Bonificadores - Ascaria Paladin'!G3 -> 40 | L9: ='Bonificadores - Ascaria Paladin'!H3 -> 42 | M9: ='Bonificadores - Ascaria Paladin'!I3 -> 41 | N9: ='Bonificadores - Ascaria Paladin'!J3 -> 12
B10: ='Bonificadores - Bastrea Paladin'!E4 -> 14.519507 | C10: ='Bonificadores - Bastrea Paladin'!F4 -> 14.027776 | D10: ='Bonificadores - Bastrea Paladin'!G4 -> 12.060848 | E10: ='Bonificadores - Bastrea Paladin'!H4 -> -2 | F10: ='Bonificadores - Bastrea Paladin'!I4 -> 13.536044 | G10: ='Bonificadores - Bastrea Paladin'!J4 -> -1 | I10: ='Bonificadores - Ascaria Paladin'!E4 -> 0 | J10: ='Bonificadores - Ascaria Paladin'!F4 -> -2 | K10: ='Bonificadores - Ascaria Paladin'!G4 -> 12.55258 | L10: ='Bonificadores - Ascaria Paladin'!H4 -> 13.536044 | M10: ='Bonificadores - Ascaria Paladin'!I4 -> 13.044312 | N10: ='Bonificadores - Ascaria Paladin'!J4 -> -1

Sheet Niveles de Creador
A1: Lvl | B1: Tipo | C1: Apoyo | D1: Fisico | E1: Magia | G1: =C1 -> Apoyo | J1: =D1 -> Fisico | M1: =E1 -> Magia
A2: 1 | B2: Gurkazaal | C2: Sacrificio | D2: Destructor | E2: Susurro Demoniaco | G2: =C2 -> Sacrificio | H2: Pierdes la mitad de la vida, pero curas el doble a un aliado que puedas tocar. | J2: =D2 -> Destructor | K2: Te atacan con ventaja y atacas con ventaja. | M2: =E2 -> Susurro Demoniaco | N2: Tus ataques magicos hacen 1/4 a los enemigos adyacentes a tu objetivo 1 turno.
A3: 1 | B3: ='Clases Razas'!D1 -> CHRONOS | C3: Mano de luz | D3: Fuerza interna | E3: Destello luminiscente | G3: =C3 -> Mano de luz | H3: Al tocar a una criatura le curas 1d4 de puntos de golpe. | J3: =D3 -> Fuerza interna | K3: Suma +1 a tus tiradas de ataque. (+2 si se trata de un demonio) | M3: =E3 -> Destello luminiscente | N3: Un destello surge de ti, dejando cegados durante dos turnos a tus enemigos adyacentes.
A4: 1 | B4: ='Clases Razas'!E1 -> SOFÍA | C4: Tiempo radiante | D4: Confianza Extrema | E4: Ayuda incomensurable | G4: =C4 -> Tiempo radiante | H4: Iluminas con tu saber a un aliado cercano proporcionando +1 en sus tiradas de sabiduría. | J4: =D4 -> Confianza Extrema | K4: Si atacas conjuntamente con otro aliado, se convierte en golpe crítico. | M4: =E4 -> Ayuda incomensurable | N4: Proporcionas +1 a la Destreza de un aliado cercano.
A5: 1 | B5: ='Clases Razas'!F1 -> ENVIDIA | C5: Manos largas | D5: Desarme | E5: Ilusionista | G5: =C5 -> Manos largas | H5: Al acertar un ataque, lanzas un dado d100 para comprobar si has robado algún objeto a tu enemigo. | J5: =D5 -> Desarme | K5: Si aciertas un ataque con una tirada superior a 17, desarmas al enemigo. | M5: =E5 -> Ilusionista | N5: Creas una imagen doble de ti, haciendo que tires con ventaja en las tiradas de ataque.
A6: 1 | B6: ='Clases Razas'!G1 -> VIDA | C6: Guía divina | D6: Golpe sanador | E6: Potencia celestial | G6: =C6 -> Guía divina | H6: Guías a un aliado, lo que le proporciona 1d6 en sus tiradas de salvación. | J6: =D6 -> Golpe sanador | K6: Si aciertas un ataque con una tirada superior a 17, absorbes el daño ocasionado, curándote esa cantidad. | M6: =E6 -> Potencia celestial | N6: Sacrificas la mitad de tu vida para realizar un hechizo de 1 nivel superior al actual.
A7: 1 | B7: ='Clases Razas'!H1 -> MUERTE | C7: Bloqueo necrótico | D7: Ataque maldito | E7: Invocación decrepita | G7: =C7 -> Bloqueo necrótico | H7: Creas un escudo necrótico que devuelve el daño de un ataque o hechizo a quien lo ha realizado. | J7: =D7 -> Ataque maldito | K7: Muerte te otorga 1d4 de dañó necrótico en tu siguiente ataque. | M7: =E7 -> Invocación decrepita | N7: Invocas a un no muerto de nivel 1/4 que te ayudará en una pelea. Una vez finalizada, se desvanecerá.
A8: 1 | B8: ='Clases Razas'!B1 -> EGOS | C8: Aliento moral | D8: Crítico asegurado | E8: Renovación mágica | G8: =C8 -> Aliento moral | H8: Animas a un aliado, haciendo que tenga ventaja en su siguiente tirada. | J8: =D8 -> Crítico asegurado | K8: Te permite cambiar el resultado de una tirada por un crítico. No se aplican a tiradas de pifia. | M8: =E8 -> Renovación mágica | N8: Te permite realizar un hechizo que no puedas usar en ese turno.
A9: 1 | B9: ='Clases Razas'!C1 -> EROS | C9: Seducción mortífera | D9: Amor tóxico | E9: Succión de espíritu | G9: =C9 -> Seducción mortífera | H9: Seduces a un enemigo, atacándole con ventaja. | J9: =D9 -> Amor tóxico | K9: Generas desventaja en el siguiente turno de un enemigo. | M9: =E9 -> Succión de espíritu | N9: Succionas vida de un enemigo, curándote 1d4. En caso de sobrevivir, el enemigo tirará con desventaja durante 2 turnos.
A10: 2 | B10: =B2 -> Gurkazaal | C10: =C2 &$C$43 -> Sacrificio de Nivel 2 | D10: =D2 &$C$43 -> Destructor de Nivel 2 | E10: =E2 &$C$43 -> Susurro Demoniaco de Nivel 2 | G10: =C10 -> Sacrificio de Nivel 2 | J10: =D10 -> Destructor de Nivel 2 | M10: =E10 -> Susurro Demoniaco de Nivel 2
A11: 2 | B11: =B3 -> CHRONOS | C11: =C3 &$C$43 -> Mano de luz de Nivel 2 | D11: =D3 &$C$43 -> Fuerza interna de Nivel 2 | E11: =E3 &$C$43 -> Destello luminiscente de Nivel 2 | G11: =C11 -> Mano de luz de Nivel 2 | J11: =D11 -> Fuerza interna de Nivel 2 | M11: =E11 -> Destello luminiscente de Nivel 2
A12: 2 | B12: =B4 -> SOFÍA | C12: =C4 &$C$43 -> Tiempo radiante de Nivel 2 | D12: =D4 &$C$43 -> Confianza Extrema de Nivel 2 | E12: =E4 &$C$43 -> Ayuda incomensurable de Nivel 2 | G12: =C12 -> Tiempo radiante de Nivel 2 | J12: =D12 -> Confianza Extrema de Nivel 2 | M12: =E12 -> Ayuda incomensurable de Nivel 2
A13: 2 | B13: =B5 -> ENVIDIA | C13: =C5 &$C$43 -> Manos largas de Nivel 2 | D13: =D5 &$C$43 -> Desarme de Nivel 2 | E13: =E5 &$C$43 -> Ilusionista de Nivel 2 | G13: =C13 -> Manos largas de Nivel 2 | J13: =D13 -> Desarme de Nivel 2 | M13: =E13 -> Ilusionista de Nivel 2
A14: 2 | B14: =B6 -> VIDA | C14: =C6 &$C$43 -> Guía divina de Nivel 2 | D14: =D6 &$C$43 -> Golpe sanador de Nivel 2 | E14: =E6 &$C$43 -> Potencia celestial de Nivel 2 | G14: =C14 -> Guía divina de Nivel 2 | J14: =D14 -> Golpe sanador de Nivel 2 | M14: =E14 -> Potencia celestial de Nivel 2
A15: 2 | B15: =B7 -> MUERTE | C15: =C7 &$C$43 -> Bloqueo necrótico de Nivel 2 | D15: =D7 &$C$43 -> Ataque maldito de Nivel 2 | E15: =E7 &$C$43 -> Invocación decrepita de Nivel 2 | G15: =C15 -> Bloqueo necrótico de Nivel 2 | J15: =D15 -> Ataque maldito de Nivel 2 | M15: =E15 -> Invocación decrepita de Nivel 2
A16: 2 | B16: =B8 -> EGOS | C16: =C8 &$C$43 -> Aliento moral de Nivel 2 | D16: =D8 &$C$43 -> Crítico asegurado de Nivel 2 | E16: =E8 &$C$43 -> Renovación mágica de Nivel 2 | G16: =C16 -> Aliento moral de Nivel 2 | J16: =D16 -> Crítico asegurado de Nivel 2 | M16: =E16 -> Renovación mágica de Nivel 2
A17: 2 | B17: =B9 -> EROS | C17: =C9 &$C$43 -> Seducción mortífera de Nivel 2 | D17: =D9 &$C$43 -> Amor tóxico de Nivel 2 | E17: =E9 &$C$43 -> Succión de espíritu de Nivel 2 | G17: =C17 -> Seducción mortífera de Nivel 2 | J17: =D17 -> Amor tóxico de Nivel 2 | M17: =E17 -> Succión de espíritu de Nivel 2
A18: 3 | B18: =B10 -> Gurkazaal | C18: =C2&$C$44 -> Sacrificio de Nivel 3 | D18: =D2&$C$44 -> Destructor de Nivel 3 | E18: =E2&$C$44 -> Susurro Demoniaco de Nivel 3 | G18: =C18 -> Sacrificio de Nivel 3 | J18: =D18 -> Destructor de Nivel 3 | M18: =E18 -> Susurro Demoniaco de Nivel 3
A19: 3 | B19: =B11 -> CHRONOS | C19: =C3&$C$44 -> Mano de luz de Nivel 3 | D19: =D3&$C$44 -> Fuerza interna de Nivel 3 | E19: =E3&$C$44 -> Destello luminiscente de Nivel 3 | G19: =C19 -> Mano de luz de Nivel 3 | J19: =D19 -> Fuerza interna de Nivel 3 | M19: =E19 -> Destello luminiscente de Nivel 3
A20: 3 | B20: =B12 -> SOFÍA | C20: =C4&$C$44 -> Tiempo radiante de Nivel 3 | D20: =D4&$C$44 -> Confianza Extrema de Nivel 3 | E20: =E4&$C$44 -> Ayuda incomensurable de Nivel 3 | G20: =C20 -> Tiempo radiante de Nivel 3 | J20: =D20 -> Confianza Extrema de Nivel 3 | M20: =E20 -> Ayuda incomensurable de Nivel 3
A21: 3 | B21: =B13 -> ENVIDIA | C21: =C5&$C$44 -> Manos largas de Nivel 3 | D21: =D5&$C$44 -> Desarme de Nivel 3 | E21: =E5&$C$44 -> Ilusionista de Nivel 3 | G21: =C21 -> Manos largas de Nivel 3 | J21: =D21 -> Desarme de Nivel 3 | M21: =E21 -> Ilusionista de Nivel 3
A22: 3 | B22: =B14 -> VIDA | C22: =C6&$C$44 -> Guía divina de Nivel 3 | D22: =D6&$C$44 -> Golpe sanador de Nivel 3 | E22: =E6&$C$44 -> Potencia celestial de Nivel 3 | G22: =C22 -> Guía divina de Nivel 3 | J22: =D22 -> Golpe sanador de Nivel 3 | M22: =E22 -> Potencia celestial de Nivel 3
A23: 3 | B23: =B15 -> MUERTE | C23: =C7&$C$44 -> Bloqueo necrótico de Nivel 3 | D23: =D7&$C$44 -> Ataque maldito de Nivel 3 | E23: =E7&$C$44 -> Invocación decrepita de Nivel 3 | G23: =C23 -> Bloqueo necrótico de Nivel 3 | J23: =D23 -> Ataque maldito de Nivel 3 | M23: =E23 -> Invocación decrepita de Nivel 3
A24: 3 | B24: =B16 -> EGOS | C24: =C8&$C$44 -> Aliento moral de Nivel 3 | D24: =D8&$C$44 -> Crítico asegurado de Nivel 3 | E24: =E8&$C$44 -> Renovación mágica de Nivel 3 | G24: =C24 -> Aliento moral de Nivel 3 | J24: =D24 -> Crítico asegurado de Nivel 3 | M24: =E24 -> Renovación mágica de Nivel 3
A25: 3 | B25: =B17 -> EROS | C25: =C9&$C$44 -> Seducción mortífera de Nivel 3 | D25: =D9&$C$44 -> Amor tóxico de Nivel 3 | E25: =E9&$C$44 -> Succión de espíritu de Nivel 3 | G25: =C25 -> Seducción mortífera de Nivel 3 | J25: =D25 -> Amor tóxico de Nivel 3 | M25: =E25 -> Succión de espíritu de Nivel 3
A26: 4 | B26: =B18 -> Gurkazaal | C26: - | D26: - | E26: - | G26: =C26 -> - | J26: =D26 -> - | M26: =E26 -> -
A27: 4 | B27: =B19 -> CHRONOS | C27: - | D27: - | E27: - | G27: =C27 -> - | J27: =D27 -> - | M27: =E27 -> -
A28: 4 | B28: =B20 -> SOFÍA | C28: - | D28: - | E28: - | G28: =C28 -> - | J28: =D28 -> - | M28: =E28 -> -
A29: 4 | B29: =B21 -> ENVIDIA | C29: - | D29: - | E29: - | G29: =C29 -> - | J29: =D29 -> - | M29: =E29 -> -
A30: 4 | B30: =B22 -> VIDA | C30: - | D30: - | E30: - | G30: =C30 -> - | J30: =D30 -> - | M30: =E30 -> -
A31: 4 | B31: =B23 -> MUERTE | C31: - | D31: - | E31: - | G31: =C31 -> - | J31: =D31 -> - | M31: =E31 -> -
A32: 4 | B32: =B24 -> EGOS | C32: - | D32: - | E32: - | G32: =C32 -> - | J32: =D32 -> - | M32: =E32 -> -
A33: 4 | B33: =B25 -> EROS | C33: - | D33: - | E33: - | G33: =C33 -> - | J33: =D33 -> - | M33: =E33 -> -
A34: 5 | B34: =B26 -> Gurkazaal | C34: Castigo | D34: Pulverizador | E34: Purgatorio | G34: =C34 -> Castigo | J34: =D34 -> Pulverizador | M34: =E34 -> Purgatorio
A35: 5 | B35: =B27 -> CHRONOS | C35: Canción del tiempo | D35: Volver a empezar | E35: Infinita confusión | G35: =C35 -> Canción del tiempo | J35: =D35 -> Volver a empezar | M35: =E35 -> Infinita confusión
A36: 5 | B36: =B28 -> SOFÍA | C36: Saber de Ekait | D36: Hermandad del conocimiento | E36: Estandarte de Ranmont | G36: =C36 -> Saber de Ekait | J36: =D36 -> Hermandad del conocimiento | M36: =E36 -> Estandarte de Ranmont
A37: 5 | B37: =B29 -> ENVIDIA | C37: Ley de Tabaxi | D37: Azote de filos | E37: Guardia de Ashye | G37: =C37 -> Ley de Tabaxi | J37: =D37 -> Azote de filos | M37: =E37 -> Guardia de Ashye
... A41: 5 | B41: =B33 -> EROS | C41: Melodía de Ayashii | D41: Suicidio emocional | E41: Rosario sinuoso | G41: =C41 -> Melodía de Ayashii | J41: =D41 -> Suicidio emocional | M41: =E41 -> Rosario sinuoso
C43: de Nivel 2
C44: de Nivel 3

Sheet Campañas
A1: Campañas | B1: Misiones | C1: Mapas | D1: DLC | E1: NPCs | F1: Oro | G1: EXP | H1: Enfrentamientos | I1: Objetos | J1: Año | K1: Party | L1: Total
A2: 1 | B2: ='Campaña 01'!C2 -> Matanza de Boundington | C2: Boundington | D2: 1 Raza (Sagas) | J2: ='Campaña 01'!$C$4&" "&'Campaña 01'!$D$4 -> 757 Despertar Elemental | K2: 4
A3: 2 | B3: ='Campaña 02'!C1 -> Segundo asedio a Ranmont | C3: Tierra Santa | D3: 2 SubRazas( Sagas) | J3: ='Campaña 02'!C4&" "&'Campaña 02'!D4 -> 864 Despertar Elemental | K3: 4
A4: Sho-Noco | B4: Primer nivel Creador | K4: 4
A5: Bonus 2 | B5: ='Bonus 02'!D2 -> Escapada de Boundington | C5: Bosque, Perishton | D5: 2 Clases | J5: ='Bonus 02'!$D$4&" "&'Bonus 02'!$E$4 -> 757 Despertar Elemental | K5: 4
A6: Bonus 2.2 | B6: ='Bonus 02.2'!C1 -> Incursion en las Santas Montañas | C6: Santas Montañas | D6: 2 Cambios de Raza | J6: ='Bonus 02.2'!$C$4&" "&'Bonus 02.2'!$D$4 -> - Despertar Elemental | K6: 4
A7: Bonus 2.4 | B7: ='Bonus 02.4'!C1 -> La lagrima de Perishton | C7: Templo de los Perdidos | D7: Objetos y Hechizos | J7: ='Bonus 02.4'!$C$4&" "&'Bonus 02.4'!$D$4 -> - Despertar Elemental | K7: 4
A8: Sho-Noco | B8: Segundo nivel Creador | K8: 4
A9: 5 | B9: Adalides en Ceaseton | D9: Bestiario ampliado | K9: 4
A10: 6 | B10: Escape de Tierra Santa | D10: Historia sobre Gurkazaal Ampliada | K10: 4
A11: Sho-Noco | B11: Entreguerras - Tercer nivel Creador | K11: 4
A12: 7 | B12: Adalides en Boundington | D12: Historia sobre Sho-Noco | K12: 4
A13: 8 | B13: Doomsburry | D13: Primera Danza | K13: 4
A14: 9 | B14: Batalla nocturna de Velours | D14: 2 Clases | K14: 4
A15: 10 | B15: Asedio de Argent | D15: 2 Cambios de Raza | K15: 4
A16: 11 | B16: La Carga de los Muertos | D16: 1 Raza (Yokai) | K16: 4
K17: 4
K18: 4
K19: 4
K20: 4
K21: 4
K22: 4
K23: 4
K24: 4
K25: 4
K26: 4
K27: 4
K28: 4
K29: 4

Sheet Loots
A1: Loot | B1: Tipo | C1: Objeto | D1: Tirada de Objetos | E1: Enemigo | F1: Campaña | G1: Cantidad | H1: Experiencia
A2: 11 | B2: Oro | C2: =Objetos!A3 -> Equipo Cultista | D2: =Objetos!E3 -> 1d20 ( +10) | E2: =Enemigos!A2 -> Cultista | F2: Campaña 1 | G2: =Enemigos!B2 -> 29 | H2: 25
A3: 1.9 | B3: Oro | C3: =Objetos!A7 -> Equipo Venides | D3: =Objetos!E7 -> 1d20 (+23) | E3: =Enemigos!A4 -> Venides | F3: Campaña 1 | G3: 1 | H3: 100
A4: 0.3 | B4: Plata | C4: =Objetos!A23 -> Equipo Soldado | D4: =Objetos!E23 -> 1d20 (+23) | E4: =Enemigos!A3 -> Guard | F4: Campaña 1 | G4: 20 | H4: 25
A5: 0.6 | B5: Oro | C5: =Objetos!A11 -> Equipo Edul | D5: =Objetos!E11 -> 1d20 ( +25) | E5: =Enemigos!A5 -> Edul | F5: Campaña 1 | G5: 1 | H5: 225
A6: 0.7 | B6: Oro | C6: =Objetos!A15 -> Equipo Venira | D6: =Objetos!E15 -> 1d20 ( +25) | E6: =Enemigos!A6 -> Venira | F6: Campaña 1 | G6: 1 | H6: 225
A7: 50 | B7: Oro | C7: =Objetos!A19 -> Equipo Sandes | D7: =Objetos!E19 -> 1d20 ( +10) | E7: =Enemigos!A11 -> Sandes | F7: Campaña 1 | G7: 1 | H7: 450

Sheet Secretos
A1: Secreto | B1: Objetivo | C1: Recompensa

Sheet Finales
A1: Campaña | B1: Finales | C1: Desenlace | D1: Obtener | E1: Perder | F1: Descripcion
A2: 1 | B2: Bueno | C2: ='Campaña 01'!C5 -> Ganas la confianza de Venides y pasas a la CAMPAÑA Nº2, esta nos hablara de como Venides logra llegar de nuevo a Nefaria y que se encuentra o descubre por el camino.
A3: 1 | B3: Malo | C3: ='Campaña 01'!C6 -> En este traicionamos la confianza de Venides y no salvamos a Verina ni Edul, podemos intentar recuperar la confianza de Venides ayudandolo cuando nos lo encontremos en medio camino, CAMPAÑA Nº2.2
A4: 1 | B4: Neutro | C4: ='Campaña 01'!C7 -> En este traicionamos a Venides y matamos a Verina y Edul y nos aliamos con Sandes, CAMPAÑA Nº2.4
A5: 2 | B5: Bueno | C5: ='Bonus 02'!D5 -> Ganas la confianza de Venides y pasas a la CAMPAÑA Nº2.2, esta nos hablara de como Venides logra llegar de nuevo a Perishton y que se encuentra o descubre por el camino.
A6: 2 | B6: Malo | C6: ='Bonus 02'!D7 -> En este traicionamos a Venides y matamos a Verina y Edul y nos aliamos con Sandes, CAMPAÑA Nº2.4
A7: 2 | B7: Neutro | C7: ='Bonus 02'!D6 -> En este traicionamos la confianza de Venides y/o no salvamos a Verina y/o Edul, podemos intentar recuperar la confianza de Venides ayudandolo cuando nos lo encontremos en medio camino, CAMPAÑA Nº2.2
A8: 45324 | B8: Bueno | C8: ='Bonus 02.2'!C6 -> Te infiltras en las montañas dentro del culto de los perdidos, Venides y Verina huyran de Perishton, te acompañara Edul a investigar dentro de la fortaleza disfrazado como perdido. -> Campaña nº 2.4 Bueno
A9: 45324 | B9: Malo | C9: =#REF! -> #REF!
A10: 45324 | B10: Neutro | C10: ='Bonus 02.2'!C7 -> Te uniras al culto y seras coordialmente invitado a la secta, cuando entres dentro te daras cuenta que todo era una mentira de Sandes para matarte y satisfacer sus experimentos. -> Campaña nº 2.4 Malo
A11: 45384 | B11: Bueno | C11: ='Bonus 02.4'!C5 -> Consigues boikotear los planes -> Campaña nº3
A12: 45384 | B12: Malo | C12: ='Bonus 02.4'!C7 -> Mueres como sacrificio y cierras la campaña de estos 4 aventureros, la campaña seguira pero con otros personajes, puedes seguir usando los mismos personajes, ya que no afecta en nada a la vida de los jugadores, ni su curso con Sho-noco. -> Campaña nº3
A13: 45384 | B13: Neutro | C13: ='Bonus 02.4'!C6 -> Si muere Edul se considerara final medio, perdiendo confianza de Venira y Venides. -> Campaña nº3
A14: 3
A15: 3
A16: 3

Sheet Enemigos
A1: Enemigos | B1: Cantidad | C1: Experiencia Total | D1: Grupos de 1 | 3 | 5 | E1: Oro | F1: Campaña | G1: Referencia
A2: Cultista | B2: 29 | C2: =Loots!H2 -> 25 | D2: x 1 | x 1.5 | x 2 | E2: =Loots!A2*B2&" "&Loots!B2 -> 319 Oro | F2: ='Campañas'!A2 -> 1 | G2: https://docs.google.com/document/d/1zUUtLsxeaTC_XeO_rt3fEol7W0CCaufyvmkdK0PNrL0/edit#heading=h.kz35zn7w2aus
A3: Guard | B3: 20 | C3: =Loots!H4 -> 25 | D3: x 1 | x 1.5 | x 2 | E3: =Loots!A4*B3&" "&Loots!B4 -> 6 Plata | F3: 1 | G3: https://docs.google.com/document/d/1zUUtLsxeaTC_XeO_rt3fEol7W0CCaufyvmkdK0PNrL0/edit#heading=h.upm2wip3u64n
A4: Venides | B4: 1 | C4: =Loots!H3 -> 100 | D4: x 1 | E4: =Loots!A3*B4&" "&Loots!B3 -> 1.9 Oro | F4: 1 | G4: https://docs.google.com/document/d/1zUUtLsxeaTC_XeO_rt3fEol7W0CCaufyvmkdK0PNrL0/edit#heading=h.dzofc0ph94fl
A5: Edul | B5: 1 | C5: =Loots!H5 -> 225 | D5: x 1 | E5: =Loots!A5*B5&" "&Loots!B5 -> 0.6 Oro | F5: 1 | G5: https://docs.google.com/document/d/1zUUtLsxeaTC_XeO_rt3fEol7W0CCaufyvmkdK0PNrL0/edit#heading=h.x6pzy8h32b73
A6: Venira | B6: 1 | C6: =Loots!H6 -> 225 | D6: x 1 | E6: =Loots!A6*B6&" "&Loots!B6 -> 0.7 Oro | F6: 1 | G6: https://docs.google.com/document/d/1zUUtLsxeaTC_XeO_rt3fEol7W0CCaufyvmkdK0PNrL0/edit#heading=h.x6pzy8h32b73
A7: Sandes | B7: 1 | C7: =Loots!H7 -> 450 | D7: x 1.5 | E7: =Loots!A7*B7&" "&Loots!B7 -> 50 Oro | F7: 1 | G7: https://docs.google.com/document/d/1zUUtLsxeaTC_XeO_rt3fEol7W0CCaufyvmkdK0PNrL0/edit#heading=h.x6pzy8h32b73
A8: Venides | B8: 1 | C8: =Loots!H8 | D8: x 1 | E8: =Loots!A8*B8&" "&Loots!B8 -> 0 | F8: 2 | G8: https://docs.google.com/document/d/1zUUtLsxeaTC_XeO_rt3fEol7W0CCaufyvmkdK0PNrL0/edit#heading=h.dzofc0ph94fl
A9: Edul | B9: 1 | C9: =Loots!H9 | D9: x 1 | E9: =Loots!A9*B9&" "&Loots!B9 -> 0 | F9: 2 | G9: https://docs.google.com/document/d/1zUUtLsxeaTC_XeO_rt3fEol7W0CCaufyvmkdK0PNrL0/edit#heading=h.x6pzy8h32b73
A10: Venira | B10: 1 | C10: =Loots!H10 | D10: x 1 | E10: =Loots!A10*B10&" "&Loots!B10 -> 0 | F10: 2 | G10: https://docs.google.com/document/d/1zUUtLsxeaTC_XeO_rt3fEol7W0CCaufyvmkdK0PNrL0/edit#heading=h.x6pzy8h32b73
A11: Sandes | B11: 1 | C11: =Loots!H11 | D11: x 1.5 | E11: =Loots!A11*B11&" "&Loots!B11 -> 0 | F11: 2 | G11: https://docs.google.com/document/d/1zUUtLsxeaTC_XeO_rt3fEol7W0CCaufyvmkdK0PNrL0/edit#heading=h.x6pzy8h32b73
D12: x 1 | F12: ='Campañas'!A14 -> 9
D13: x 1 | F13: ='Campañas'!A15 -> 10
D14: x 1 | F14: ='Campañas'!A16 -> 11
D15: x 1 | F15: ='Campañas'!A17
D16: x 1 | F16: ='Campañas'!A18
D17: x 1 | F17: =#REF! -> #REF!
D18: x 1 | F18: =#REF! -> #REF!
D19: x 1 | F19: =#REF! -> #REF!
D20: x 1 | F20: ='Campañas'!A22
D21: x 1 | F21: ='Campañas'!A23
D22: x 1 | F22: ='Campañas'!A24
D23: x 1 | F23: ='Campañas'!A25
D24: x 1 | F24: ='Campañas'!A26

Sheet Años
A1: Despertar elemental | C1: 2838 | D1: =VLOOKUP(E1,B5:C1010,2,FALSE) -> 603 | E1: =AD5 -> 2235
A2: B.F | C2: 1735 | D2: 1003 | E2: =AE5 -> 603
B4: Before Forcast | F4: Before Forcast | G4: Despertar Elemental | J4: Before Forcast | K4: Despertar Elemental | N4: Before Forcast | O4: Despertar Elemental | R4: Before Forcast | S4: Despertar Elemental | V4: Before Forcast | W4: Despertar Elemental | Z4: Before Forcast | AA4: Despertar Elemental | AD4: Before Forcast | AE4: Despertar Elemental | AH4: Before Forcast | AI4: Despertar Elemental | AL4: Before Forcast | AM4: Despertar Elemental | AN4: Eventos | AP4: Before Forcast | AQ4: Despertar Elemental | AR4: La Gran Alianza | AS4: Gongorguma | AT4: Eventos | AV4: Before Forcast | AW4: Despertar Elemental | AX4: La Gran Alianza | AY4: Gongorguma | AZ4: Eventos | BB4: Before Forcast | BC4: La Gran Alianza | BD4: Neo Gongorguma | BE4: Eventos | BG4: Before Forcast | BH4: La Gran Alianza | BI4: Neo Gongorguma | BJ4: Eventos | BL4: Before Forcast | BM4: La Gran Alianza | BN4: Neo Gongorguma | BO4: Resistencia | BP4: Eventos | BR4: Before Forcast | BS4: La Gran Alianza | BT4: Resistencia | BU4: Eventos | BW4: Before Forcast | BX4: La Gran Alianza | BY4: Ascaria | BZ4: Resistencia | CA4: Eventos | CC4: Before Forcast | CD4: Ascaria | CE4: Resistencia | CF4: Eventos | CH4: Before Forcast | CI4: Ascaria | CJ4: Resistencia | CK4: Eventos | CM4: Before Forcast | CN4: Ascaria | CO4: Resistencia | CP4: Eventos | CR4: Before Forcast | CS4: Ascaria | CT4: Resistencia | CU4: Eventos | CW4: Before Forcast | CX4: Ascaria | CY4: Resistencia | CZ4: Eventos | DB4: Before Forcast | DC4: Ascaria | DD4: Resistencia | DE4: Eventos | DG4: Before Forcast | DH4: Ascaria | DI4: Resistencia | DJ4: Eventos | DL4: Before Forcast | DM4: Ascaria | DN4: Resistencia | DO4: Eventos | DQ4: Before Forcast | DR4: Ascaria | DS4: Resistencia | DT4: Eventos | DV4: Before Forcast | DW4: After Forcast | DX4: Ascaria | DY4: Resistencia | DZ4: Eventos
B5: 2837 | C5: 1 | F5: 2580 | J5: 2810 | K5: 28 | N5: 2695 | O5: 143 | R5: 2580 | S5: 258 | V5: 2465 | W5: 373 | Z5: 2350 | AA5: 488 | AD5: 2235 | AE5: 603 | AH5: 2120 | AI5: 718 | AL5: 2005 | AM5: 833 | AP5: 1890 | AQ5: 948 | AR5: - | AS5: - | AV5: 1775 | AW5: 1063 | AX5: 40 | AY5: 30 | BB5: 1665 | BC5: 150 | BD5: 1 | BG5: 1550 | BH5: 265 | BI5: 115 | BL5: 1435 | BM5: 380 | BN5: 230 | BR5: 1320 | BS5: 495 | BT5: 75 | BW5: 1205 | BX5: 610 | BY5: - | BZ5: 190 | CC5: 1090 | CD5: 69 | CE5: 305 | CH5: 975 | CI5: 184 | CJ5: 420 | CM5: 860 | CN5: 299 | CO5: 535 | CR5: 745 | CS5: 414 | CT5: 650 | CW5: 630 | CX5: 529 | CY5: 760 | DB5: 515 | DC5: 644 | DD5: 875 | DG5: 400 | DH5: 759 | DI5: 990 | DL5: 285 | DM5: 874 | DN5: 1105 | DQ5: 170 | DR5: 989 | DS5: 1220 | DV5: 55 | DW5: - | DX5: 1104 | DY5: 1335
B6: =B5-1 -> 2836 | C6: 2 | F6: 2575 | J6: 2805 | K6: 33 | N6: 2690 | O6: 148 | R6: 2575 | S6: 263 | V6: 2460 | W6: 378 | Z6: 2345 | AA6: 493 | AD6: 2230 | AE6: 608 | AH6: 2115 | AI6: 723 | AL6: 2000 | AM6: 838 | AP6: 1885 | AQ6: 953 | AR6: - | AS6: - | AV6: 1770 | AW6: 1068 | AX6: 45 | AY6: 35 | BB6: 1660 | BC6: 155 | BD6: 5 | BG6: 1545 | BH6: 270 | BI6: 120 | BL6: 1430 | BM6: 385 | BN6: 235 | BR6: 1315 | BS6: 500 | BT6: 80 | BW6: 1200 | BX6: 615 | BY6: - | BZ6: 195 | CC6: 1085 | CD6: 74 | CE6: 310 | CH6: 970 | CI6: 189 | CJ6: 425 | CM6: 855 | CN6: 304 | CO6: 540 | CR6: 740 | CS6: 419 | CT6: 655 | CW6: 625 | CX6: 534 | CY6: 765 | DB6: 510 | DC6: 649 | DD6: 880 | DG6: 395 | DH6: 764 | DI6: 995 | DL6: 280 | DM6: 879 | DN6: 1110 | DQ6: 165 | DR6: 994 | DS6: 1225 | DV6: 50 | DW6: - | DX6: 1109 | DY6: 1340
B7: =B6-1 -> 2835 | C7: 3 | F7: 2570 | J7: 2800 | K7: 38 | N7: 2685 | O7: 153 | R7: 2570 | S7: 268 | V7: 2455 | W7: 383 | Z7: 2340 | AA7: 498 | AD7: 2225 | AE7: 613 | AH7: 2110 | AI7: 728 | AL7: 1995 | AM7: 843 | AP7: 1880 | AQ7: 958 | AR7: - | AS7: - | AV7: 1765 | AW7: 1073 | AX7: 50 | AY7: 40 | BB7: 1655 | BC7: 160 | BD7: 10 | BG7: 1540 | BH7: 275 | BI7: 125 | BL7: 1425 | BM7: 390 | BN7: 240 | BR7: 1310 | BS7: 505 | BT7: 85 | BW7: 1195 | BX7: 620 | BY7: - | BZ7: 200 | CC7: 1080 | CD7: 79 | CE7: 315 | CH7: 965 | CI7: 194 | CJ7: 430 | CM7: 850 | CN7: 309 | CO7: 545 | CR7: 735 | CS7: 424 | CT7: 660 | CW7: 620 | CX7: 539 | CY7: 770 | DB7: 505 | DC7: 654 | DD7: 885 | DG7: 390 | DH7: 769 | DI7: 1000 | DL7: 275 | DM7: 884 | DN7: 1115 | DQ7: 160 | DR7: 999 | DS7: 1230 | DV7: 45 | DW7: - | DX7: 1114 | DY7: 1345
B8: =B7-1 -> 2834 | C8: 4 | F8: 2565 | J8: 2795 | K8: 43 | N8: 2680 | O8: 158 | R8: 2565 | S8: 273 | V8: 2450 | W8: 388 | Z8: 2335 | AA8: 503 | AD8: 2220 | AE8: 618 | AH8: 2105 | AI8: 733 | AL8: 1990 | AM8: 848 | AP8: 1875 | AQ8: 963 | AR8: - | AS8: - | AV8: 1760 | AW8: 1078 | AX8: 55 | AY8: 45 | BB8: 1650 | BC8: 165 | BD8: 15 | BG8: 1535 | BH8: 280 | BI8: 130 | BL8: 1420 | BM8: 395 | BN8: 245 | BR8: 1305 | BS8: 510 | BT8: 90 | BW8: 1190 | BX8: 625 | BY8: - | BZ8: 205 | CC8: 1075 | CD8: 84 | CE8: 320 | CH8: 960 | CI8: 199 | CJ8: 435 | CM8: 845 | CN8: 314 | CO8: 550 | CR8: 730 | CS8: 429 | CT8: 665 | CW8: 615 | CX8: 544 | CY8: 775 | DB8: 500 | DC8: 659 | DD8: 890 | DG8: 385 | DH8: 774 | DI8: 1005 | DL8: 270 | DM8: 889 | DN8: 1120 | DQ8: 155 | DR8: 1004 | DS8: 1235 | DV8: 40 | DW8: - | DX8: 1119 | DY8: 1350
B9: =B8-1 -> 2833 | C9: 5 | F9: 2560 | J9: 2790 | K9: 48 | N9: 2675 | O9: 163 | R9: 2560 | S9: 278 | V9: 2445 | W9: 393 | Z9: 2330 | AA9: 508 | AD9: 2215 | AE9: 623 | AH9: 2100 | AI9: 738 | AL9: 1985 | AM9: 853 | AP9: 1870 | AQ9: 968 | AR9: - | AS9: - | AV9: 1755 | AW9: 1083 | AX9: 60 | AY9: 50 | BB9: 1645 | BC9: 170 | BD9: 20 | BG9: 1530 | BH9: 285 | BI9: 135 | BL9: 1415 | BM9: 400 | BN9: 250 | BR9: 1300 | BS9: 515 | BT9: 95 | BW9: 1185 | BX9: 630 | BY9: - | BZ9: 210 | CC9: 1070 | CD9: 89 | CE9: 325 | CH9: 955 | CI9: 204 | CJ9: 440 | CM9: 840 | CN9: 319 | CO9: 555 | CR9: 725 | CS9: 434 | CT9: 670 | CW9: 610 | CX9: 549 | CY9: 780 | DB9: 495 | DC9: 664 | DD9: 895 | DG9: 380 | DH9: 779 | DI9: 1010 | DL9: 265 | DM9: 894 | DN9: 1125 | DQ9: 150 | DR9: 1009 | DS9: 1240 | DV9: 35 | DW9: - | DX9: 1124 | DY9: 1355
B10: =B9-1 -> 2832 | C10: 6 | F10: 2555 | J10: 2785 | K10: 53 | N10: 2670 | O10: 168 | R10: 2555 | S10: 283 | V10: 2440 | W10: 398 | Z10: 2325 | AA10: 513 | AD10: 2210 | AE10: 628 | AH10: 2095 | AI10: 743 | AL10: 1980 | AM10: 858 | AP10: 1865 | AQ10: 973 | AR10: - | AS10: - | AV10: 1750 | AW10: 1088 | AX10: 65 | AY10: 55 | BB10: 1640 | BC10: 175 | BD10: 25 | BG10: 1525 | BH10: 290 | BI10: 140 | BL10: 1410 | BM10: 405 | BN10: 255 | BR10: 1295 | BS10: 520 | BT10: 100 | BW10: 1180 | BX10: 635 | BY10: - | BZ10: 215 | CC10: 1065 | CD10: 94 | CE10: 330 | CH10: 950 | CI10: 209 | CJ10: 445 | CM10: 835 | CN10: 324 | CO10: 560 | CR10: 720 | CS10: 439 | CT10: 675 | CW10: 605 | CX10: 554 | CY10: 785 | DB10: 490 | DC10: 669 | DD10: 900 | DG10: 375 | DH10: 784 | DI10: 1015 | DL10: 260 | DM10: 899 | DN10: 1130 | DQ10: 145 | DR10: 1014 | DS10: 1245 | DV10: 30 | DW10: - | DX10: 1129 | DY10: 1360
B11: =B10-1 -> 2831 | C11: 7 | F11: 2550 | J11: 2780 | K11: 58 | N11: 2665 | O11: 173 | R11: 2550 | S11: 288 | V11: 2435 | W11: 403 | Z11: 2320 | AA11: 518 | AD11: 2205 | AE11: 633 | AH11: 2090 | AI11: 748 | AL11: 1975 | AM11: 863 | AP11: 1860 | AQ11: 978 | AR11: - | AS11: - | AV11: 1745 | AW11: 1093 | AX11: 70 | AY11: 60 | BB11: 1635 | BC11: 180 | BD11: 30 | BG11: 1520 | BH11: 295 | BI11: 145 | BL11: 1405 | BM11: 410 | BN11: 260 | BR11: 1290 | BS11: 525 | BT11: 105 | BW11: 1175 | BX11: 640 | BY11: - | BZ11: 220 | CC11: 1060 | CD11: 99 | CE11: 335 | CH11: 945 | CI11: 214 | CJ11: 450 | CM11: 830 | CN11: 329 | CO11: 565 | CR11: 715 | CS11: 444 | CT11: 680 | CW11: 600 | CX11: 559 | CY11: 790 | DB11: 485 | DC11: 674 | DD11: 905 | DG11: 370 | DH11: 789 | DI11: 1020 | DL11: 255 | DM11: 904 | DN11: 1135 | DQ11: 140 | DR11: 1019 | DS11: 1250 | DV11: 25 | DW11: - | DX11: 1134 | DY11: 1365
B12: =B11-1 -> 2830 | C12: 8 | F12: 2545 | J12: 2775 | K12: 63 | N12: 2660 | O12: 178 | R12: 2545 | S12: 293 | V12: 2430 | W12: 408 | Z12: 2315 | AA12: 523 | AD12: 2200 | AE12: 638 | AH12: 2085 | AI12: 753 | AL12: 1970 | AM12: 868 | AP12: 1855 | AQ12: 983 | AR12: - | AS12: - | AV12: 1740 | AW12: 1098 | AX12: 75 | AY12: 65 | BB12: 1630 | BC12: 185 | BD12: 35 | BG12: 1515 | BH12: 300 | BI12: 150 | BL12: 1400 | BM12: 415 | BN12: 265 | BR12: 1285 | BS12: 530 | BT12: 110 | BW12: 1170 | BX12: 645 | BY12: - | BZ12: 225 | CC12: 1055 | CD12: 104 | CE12: 340 | CH12: 940 | CI12: 219 | CJ12: 455 | CM12: 825 | CN12: 334 | CO12: 570 | CR12: 710 | CS12: 449 | CT12: 685 | CW12: 595 | CX12: 564 | CY12: 795 | DB12: 480 | DC12: 679 | DD12: 910 | DG12: 365 | DH12: 794 | DI12: 1025 | DL12: 250 | DM12: 909 | DN12: 1140 | DQ12: 135 | DR12: 1024 | DS12: 1255 | DV12: 20 | DW12: - | DX12: 1139 | DY12: 1370
B13: =B12-1 -> 2829 | C13: 9 | F13: 2540 | J13: 2770 | K13: 68 | N13: 2655 | O13: 183 | R13: 2540 | S13: 298 | V13: 2425 | W13: 413 | Z13: 2310 | AA13: 528 | AD13: 2195 | AE13: 643 | AH13: 2080 | AI13: 758 | AL13: 1965 | AM13: 873 | AP13: 1850 | AQ13: 988 | AR13: - | AS13: - | AV13: 1735 | AW13: 1103 | AX13: 80 | AY13: 70 | BB13: 1625 | BC13: 190 | BD13: 40 | BG13: 1510 | BH13: 305 | BI13: 155 | BL13: 1395 | BM13: 420 | BN13: 270 | BO13: 0 | BR13: 1280 | BS13: 535 | BT13: 115 | BW13: 1165 | BX13: 650 | BY13: - | BZ13: 230 | CC13: 1050 | CD13: 109 | CE13: 345 | CH13: 935 | CI13: 224 | CJ13: 460 | CM13: 820 | CN13: 339 | CO13: 575 | CR13: 705 | CS13: 454 | CT13: 690 | CW13: 590 | CX13: 569 | CY13: 800 | DB13: 475 | DC13: 684 | DD13: 915 | DG13: 360 | DH13: 799 | DI13: 1030 | DL13: 245 | DM13: 914 | DN13: 1145 | DQ13: 130 | DR13: 1029 | DS13: 1260 | DV13: 15 | DW13: - | DX13: 1144 | DY13: 1375
B14: =B13-1 -> 2828 | C14: 10 | F14: 2535 | J14: 2765 | K14: 73 | N14: 2650 | O14: 188 | R14: 2535 | S14: 303 | V14: 2420 | W14: 418 | Z14: 2305 | AA14: 533 | AD14: 2190 | AE14: 648 | AH14: 2075 | AI14: 763 | AL14: 1960 | AM14: 878 | AP14: 1845 | AQ14: 993 | AR14: - | AS14: - | AV14: 1730 | AW14: - | AX14: 85 | AY14: 75 | BB14: 1620 | BC14: 195 | BD14: 45 | BG14: 1505 | BH14: 310 | BI14: 160 | BL14: 1390 | BM14: 425 | BN14: 275 | BO14: 5 | BR14: 1275 | BS14: 540 | BT14: 120 | BW14: 1160 | BX14: - | BY14: 0 | BZ14: 235 | CC14: 1045 | CD14: 114 | CE14: 350 | CH14: 930 | CI14: 229 | CJ14: 465 | CM14: 815 | CN14: 344 | CO14: 580 | CR14: 700 | CS14: 459 | CT14: 695 | CW14: 585 | CX14: 574 | CY14: 805 | DB14: 470 | DC14: 689 | DD14: 920 | DG14: 355 | DH14: 804 | DI14: 1035 | DL14: 240 | DM14: 919 | DN14: 1150 | DQ14: 125 | DR14: 1034 | DS14: 1265 | DV14: 10 | DW14: - | DX14: 1149 | DY14: 1380
B15: =B14-1 -> 2827 | C15: 11 | F15: 2875 | J15: 2760 | K15: 78 | N15: 2645 | O15: 193 | R15: 2530 | S15: 308 | V15: 2415 | W15: 423 | Z15: 2300 | AA15: 538 | AD15: 2185 | AE15: 653 | AH15: 2070 | AI15: 768 | AL15: 1955 | AM15: 883 | AP15: 1840 | AQ15: 998 | AR15: - | AS15: - | AV15: 1725 | AW15: - | AX15: 90 | AY15: 80 | BB15: 1615 | BC15: 200 | BD15: 50 | BG15: 1500 | BH15: 315 | BI15: 165 | BL15: 1385 | BM15: 430 | BN15: 280 | BO15: 10 | BR15: 1270 | BS15: 545 | BT15: 125 | BW15: 1155 | BX15: - | BY15: 4 | BZ15: 240 | CC15: 1040 | CD15: 119 | CE15: 355 | CH15: 925 | CI15: 234 | CJ15: 470 | CM15: 810 | CN15: 349 | CO15: 585 | CR15: 695 | CS15: 464 | CT15: 700 | CW15: 580 | CX15: 579 | CY15: 810 | DB15: 465 | DC15: 694 | DD15: 925 | DG15: 350 | DH15: 809 | DI15: 1040 | DL15: 235 | DM15: 924 | DN15: 1155 | DQ15: 120 | DR15: 1039 | DS15: 1270 | DV15: 5 | DW15: - | DX15: 1154 | DY15: 1385
B16: =B15-1 -> 2826 | C16: 12 | F16: 2870 | J16: 2755 | K16: 83 | N16: 2640 | O16: 198 | R16: 2525 | S16: 313 | V16: 2410 | W16: 428 | Z16: 2295 | AA16: 543 | AD16: 2180 | AE16: 658 | AH16: 2065 | AI16: 773 | AL16: 1950 | AM16: 888 | AP16: 1835 | AQ16: 1003 | AR16: - | AS16: - | AV16: 1720 | AW16: - | AX16: 95 | AY16: 85 | BB16: 1610 | BC16: 205 | BD16: 55 | BG16: 1495 | BH16: 320 | BI16: 170 | BL16: 1380 | BM16: 435 | BN16: 285 | BO16: 15 | BR16: 1265 | BS16: 550 | BT16: 130 | BW16: 1150 | BX16: - | BY16: 9 | BZ16: 245 | CC16: 1035 | CD16: 124 | CE16: 360 | CH16: 920 | CI16: 239 | CJ16: 475 | CM16: 805 | CN16: 354 | CO16: 590 | CR16: 690 | CS16: 469 | CT16: 705 | CW16: 575 | CX16: 584 | CY16: 815 | DB16: 460 | DC16: 699 | DD16: 930 | DG16: 345 | DH16: 814 | DI16: 1045 | DL16: 230 | DM16: 929 | DN16: 1160 | DQ16: 115 | DR16: 1044 | DS16: 1275 | DV16: 0 | DW16: 0 | DX16: 1159 | DY16: 1390
B17: =B16-1 -> 2825 | C17: 13 | F17: 2865 | J17: 2750 | K17: 88 | N17: 2635 | O17: 203 | R17: 2520 | S17: 318 | V17: 2405 | W17: 433 | Z17: 2290 | AA17: 548 | AD17: 2175 | AE17: 663 | AH17: 2060 | AI17: 778 | AL17: 1945 | AM17: 893 | AP17: 1830 | AQ17: 1008 | AR17: - | AS17: - | AV17: 1715 | AW17: - | AX17: 100 | AY17: 90 | BB17: 1605 | BC17: 210 | BD17: 60 | BG17: 1490 | BH17: 325 | BI17: 175 | BL17: 1375 | BM17: 440 | BN17: 290 | BO17: 20 | BR17: 1260 | BS17: 555 | BT17: 135 | BW17: 1145 | BX17: - | BY17: 14 | BZ17: 250 | CC17: 1030 | CD17: 129 | CE17: 365 | CH17: 915 | CI17: 244 | CJ17: 480 | CM17: 800 | CN17: 359 | CO17: 595 | CR17: 685 | CS17: 474 | CT17: 710 | CW17: 570 | CX17: 589 | CY17: 820 | DB17: 455 | DC17: 704 | DD17: 935 | DG17: 340 | DH17: 819 | DI17: 1050 | DL17: 225 | DM17: 934 | DN17: 1165 | DQ17: 110 | DR17: 1049 | DS17: 1280 | DV17: - | DW17: 5
B18: =B17-1 -> 2824 | C18: 14 | F18: 2860 | J18: 2745 | K18: 93 | N18: 2630 | O18: 208 | R18: 2515 | S18: 323 | V18: 2400 | W18: 438 | Z18: 2285 | AA18: 553 | AD18: 2170 | AE18: 668 | AH18: 2055 | AI18: 783 | AL18: 1940 | AM18: 898 | AP18: 1825 | AQ18: 1013 | AR18: - | AS18: - | AV18: 1710 | AW18: - | AX18: 105 | AY18: 95 | BB18: 1600 | BC18: 215 | BD18: 65 | BG18: 1485 | BH18: 330 | BI18: 180 | BL18: 1370 | BM18: 445 | BN18: 295 | BO18: 25 | BR18: 1255 | BS18: 560 | BT18: 140 | BW18: 1140 | BX18: - | BY18: 19 | BZ18: 255 | CC18: 1025 | CD18: 134 | CE18: 370 | CH18: 910 | CI18: 249 | CJ18: 485 | CM18: 795 | CN18: 364 | CO18: 600 | CR18: 680 | CS18: 479 | CT18: 715 | CW18: 565 | CX18: 594 | CY18: 825 | DB18: 450 | DC18: 709 | DD18: 940 | DG18: 335 | DH18: 824 | DI18: 1055 | DL18: 220 | DM18: 939 | DN18: 1170 | DQ18: 105 | DR18: 1054 | DS18: 1285 | DV18: - | DW18: 10
B19: =B18-1 -> 2823 | C19: 15 | F19: 2855 | J19: 2740 | K19: 98 | N19: 2625 | O19: 213 | R19: 2510 | S19: 328 | V19: 2395 | W19: 443 | Z19: 2280 | AA19: 558 | AD19: 2165 | AE19: 673 | AH19: 2050 | AI19: 788 | AL19: 1935 | AM19: 903 | AP19: 1820 | AQ19: 1018 | AR19: - | AS19: - | AV19: 1705 | AW19: - | AX19: 110 | AY19: 100 | BB19: 1595 | BC19: 220 | BD19: 70 | BG19: 1480 | BH19: 335 | BI19: 185 | BL19: 1365 | BM19: 450 | BN19: 300 | BO19: 30 | BR19: 1250 | BS19: 565 | BT19: 145 | BW19: 1135 | BX19: - | BY19: 24 | BZ19: 260 | CC19: 1020 | CD19: 139 | CE19: 375 | CH19: 905 | CI19: 254 | CJ19: 490 | CM19: 790 | CN19: 369 | CO19: 605 | CR19: 675 | CS19: 484 | CT19: 720 | CW19: 560 | CX19: 599 | CY19: 830 | DB19: 445 | DC19: 714 | DD19: 945 | DG19: 330 | DH19: 829 | DI19: 1060 | DL19: 215 | DM19: 944 | DN19: 1175 | DQ19: 100 | DR19: 1059 | DS19: 1290 | DV19: - | DW19: 15
B20: =B19-1 -> 2822 | C20: 16 | F20: 2850 | J20: 2735 | K20: 103 | N20: 2620 | O20: 218 | R20: 2505 | S20: 333 | V20: 2390 | W20: 448 | Z20: 2275 | AA20: 563 | AD20: 2160 | AE20: 678 | AH20: 2045 | AI20: 793 | AL20: 1930 | AM20: 908 | AP20: 1815 | AQ20: 1023 | AR20: 1 | AS20: - | AV20: 1700 | AW20: - | AX20: 115 | AY20: 105 | BB20: 1590 | BC20: 225 | BD20: 75 | BG20: 1475 | BH20: 340 | BI20: 190 | BL20: 1360 | BM20: 455 | BN20: 305 | BO20: 35 | BR20: 1245 | BS20: 570 | BT20: 150 | BW20: 1130 | BX20: - | BY20: 29 | BZ20: 265 | CC20: 1015 | CD20: 144 | CE20: 380 | CH20: 900 | CI20: 259 | CJ20: 495 | CM20: 785 | CN20: 374 | CO20: 610 | CR20: 670 | CS20: 489 | CT20: 725 | CW20: 555 | CX20: 604 | CY20: 835 | DB20: 440 | DC20: 719 | DD20: 950 | DG20: 325 | DH20: 834 | DI20: 1065 | DL20: 210 | DM20: 949 | DN20: 1180 | DQ20: 95 | DR20: 1064 | DS20: 1295 | DV20: - | DW20: 20
B21: =B20-1 -> 2821 | C21: 17 | F21: 2845 | J21: 2730 | K21: 108 | N21: 2615 | O21: 223 | R21: 2500 | S21: 338 | V21: 2385 | W21: 453 | Z21: 2270 | AA21: 568 | AD21: 2155 | AE21: 683 | AH21: 2040 | AI21: 798 | AL21: 1925 | AM21: 913 | AP21: 1810 | AQ21: 1028 | AR21: 5 | AS21: - | AV21: 1695 | AW21: - | AX21: 120 | AY21: 110 | BB21: 1585 | BC21: 230 | BD21: 80 | BG21: 1470 | BH21: 345 | BI21: 195 | BL21: 1355 | BM21: 460 | BN21: 310 | BO21: 40 | BR21: 1240 | BS21: 575 | BT21: 155 | BW21: 1125 | BX21: - | BY21: 34 | BZ21: 270 | CC21: 1010 | CD21: 149 | CE21: 385 | CH21: 895 | CI21: 264 | CJ21: 500 | CM21: 780 | CN21: 379 | CO21: 615 | CR21: 665 | CS21: 494 | CT21: 730 | CW21: 550 | CX21: 609 | CY21: 840 | DB21: 435 | DC21: 724 | DD21: 955 | DG21: 320 | DH21: 839 | DI21: 1070 | DL21: 205 | DM21: 954 | DN21: 1185 | DQ21: 90 | DR21: 1069 | DS21: 1300 | DV21: - | DW21: 25
B22: =B21-1 -> 2820 | C22: 18 | F22: 2837 | G22: 1 | H22: Mensaje de Egaroth | J22: 2725 | K22: 113 | N22: 2610 | O22: 228 | R22: 2495 | S22: 343 | V22: 2380 | W22: 458 | Z22: 2265 | AA22: 573 | AD22: 2150 | AE22: 688 | AH22: 2035 | AI22: 803 | AL22: 1920 | AM22: 918 | AP22: 1805 | AQ22: 1033 | AR22: 10 | AS22: 0 | AV22: 1690 | AW22: - | AX22: 125 | AY22: 115 | BB22: 1580 | BC22: 235 | BD22: 85 | BG22: 1465 | BH22: 350 | BI22: 200 | BL22: 1350 | BM22: 465 | BN22: 315 | BO22: 45 | BR22: 1235 | BS22: 580 | BT22: 160 | BW22: 1120 | BX22: - | BY22: 39 | BZ22: 275 | CC22: 1005 | CD22: 154 | CE22: 390 | CH22: 890 | CI22: 269 | CJ22: 505 | CM22: 775 | CN22: 384 | CO22: 620 | CR22: 660 | CS22: 499 | CT22: 735 | CW22: 545 | CX22: 614 | CY22: 845 | DB22: 430 | DC22: 729 | DD22: 960 | DG22: 315 | DH22: 844 | DI22: 1075 | DL22: 200 | DM22: 959 | DN22: 1190 | DQ22: 85 | DR22: 1074 | DS22: 1305 | DV22: - | DW22: 30
B23: =B22-1 -> 2819 | C23: 19 | F23: 2835 | G23: 3 | J23: 2720 | K23: 118 | N23: 2605 | O23: 233 | R23: 2490 | S23: 348 | V23: 2375 | W23: 463 | Z23: 2260 | AA23: 578 | AD23: 2145 | AE23: 693 | AH23: 2030 | AI23: 808 | AL23: 1915 | AM23: 923 | AP23: 1800 | AQ23: 1038 | AR23: 15 | AS23: 5 | AV23: 1685 | AW23: - | AX23: 130 | AY23: 120 | BB23: 1575 | BC23: 240 | BD23: 90 | BG23: 1460 | BH23: 355 | BI23: 205 | BL23: 1345 | BM23: 470 | BN23: 320 | BO23: 50 | BR23: 1230 | BS23: 585 | BT23: 165 | BW23: 1115 | BX23: - | BY23: 44 | BZ23: 280 | CC23: 1000 | CD23: 159 | CE23: 395 | CH23: 885 | CI23: 274 | CJ23: 510 | CM23: 770 | CN23: 389 | CO23: 625 | CR23: 655 | CS23: 504 | CT23: 740 | CW23: 540 | CX23: 619 | CY23: 850 | DB23: 425 | DC23: 734 | DD23: 965 | DG23: 310 | DH23: 849 | DI23: 1080 | DL23: 195 | DM23: 964 | DN23: 1195 | DQ23: 80 | DR23: 1079 | DS23: 1310 | DV23: - | DW23: 35
B24: =B23-1 -> 2818 | C24: 20 | F24: 2830 | G24: 8 | J24: 2715 | K24: 123 | N24: 2600 | O24: 238 | R24: 2485 | S24: 353 | V24: 2370 | W24: 468 | Z24: 2255 | AA24: 583 | AD24: 2140 | AE24: 698 | AH24: 2025 | AI24: 813 | AL24: 1910 | AM24: 928 | AP24: 1795 | AQ24: 1043 | AR24: 20 | AS24: 10 | AV24: 1680 | AW24: - | AX24: 135 | AY24: 125 | BB24: 1570 | BC24: 245 | BD24: 95 | BG24: 1455 | BH24: 360 | BI24: 210 | BL24: 1340 | BM24: 475 | BN24: 325 | BO24: 55 | BR24: 1225 | BS24: 590 | BT24: 170 | BW24: 1110 | BX24: - | BY24: 49 | BZ24: 285 | CC24: 995 | CD24: 164 | CE24: 400 | CH24: 880 | CI24: 279 | CJ24: 515 | CM24: 765 | CN24: 394 | CO24: 630 | CR24: 650 | CS24: 509 | CT24: 745 | CW24: 535 | CX24: 624 | CY24: 855 | DB24: 420 | DC24: 739 | DD24: 970 | DG24: 305 | DH24: 854 | DI24: 1085 | DL24: 190 | DM24: 969 | DN24: 1200 | DQ24: 75 | DR24: 1084 | DS24: 1315 | DV24: - | DW24: 40
B25: =B24-1 -> 2817 | C25: 21 | F25: 2825 | G25: 13 | J25: 2710 | K25: 128 | N25: 2595 | O25: 243 | R25: 2480 | S25: 358 | V25: 2365 | W25: 473 | Z25: 2250 | AA25: 588 | AD25: 2135 | AE25: 703 | AH25: 2020 | AI25: 818 | AL25: 1905 | AM25: 933 | AP25: 1790 | AQ25: 1048 | AR25: 25 | AS25: 15 | AV25: 1675 | AW25: - | AX25: 140 | AY25: 130 | BB25: 1565 | BC25: 250 | BD25: 100 | BG25: 1450 | BH25: 365 | BI25: 215 | BL25: 1335 | BM25: 480 | BN25: 330 | BO25: 60 | BR25: 1220 | BS25: 595 | BT25: 175 | BW25: 1105 | BX25: - | BY25: 54 | BZ25: 290 | CC25: 990 | CD25: 169 | CE25: 405 | CH25: 875 | CI25: 284 | CJ25: 520 | CM25: 760 | CN25: 399 | CO25: 635 | CR25: 645 | CS25: 514 | CT25: 750 | CW25: 530 | CX25: 629 | CY25: 860 | DB25: 415 | DC25: 744 | DD25: 975 | DG25: 300 | DH25: 859 | DI25: 1090 | DL25: 185 | DM25: 974 | DN25: 1205 | DQ25: 70 | DR25: 1089 | DS25: 1320 | DV25: - | DW25: 45
B26: =B25-1 -> 2816 | C26: 22 | F26: 2820 | G26: 18 | J26: 2705 | K26: 133 | N26: 2590 | O26: 248 | R26: 2475 | S26: 363 | V26: 2360 | W26: 478 | Z26: 2245 | AA26: 593 | AD26: 2130 | AE26: 708 | AH26: 2015 | AI26: 823 | AL26: 1900 | AM26: 938 | AP26: 1785 | AQ26: 1053 | AR26: 30 | AS26: 20 | AV26: 1670 | AW26: - | AX26: 145 | AY26: 135 | BB26: 1560 | BC26: 255 | BD26: 105 | BG26: 1445 | BH26: 370 | BI26: 220 | BL26: 1330 | BM26: 485 | BN26: 335 | BO26: 65 | BR26: 1215 | BS26: 600 | BT26: 180 | BW26: 1100 | BX26: - | BY26: 59 | BZ26: 295 | CC26: 985 | CD26: 174 | CE26: 410 | CH26: 870 | CI26: 289 | CJ26: 525 | CM26: 755 | CN26: 404 | CO26: 640 | CR26: 640 | CS26: 519 | CT26: 755 | CW26: 525 | CX26: 634 | CY26: 865 | DB26: 410 | DC26: 749 | DD26: 980 | DG26: 295 | DH26: 864 | DI26: 1095 | DL26: 180 | DM26: 979 | DN26: 1210 | DQ26: 65 | DR26: 1094 | DS26: 1325 | DV26: - | DW26: 50
B27: =B26-1 -> 2815 | C27: 23 | F27: 2815 | G27: 23 | J27: 2700 | K27: 138 | N27: 2585 | O27: 253 | R27: 2470 | S27: 368 | V27: 2355 | W27: 483 | Z27: 2240 | AA27: 598 | AD27: 2125 | AE27: 713 | AH27: 2010 | AI27: 828 | AL27: 1895 | AM27: 943 | AP27: 1780 | AQ27: 1058 | AR27: 35 | AS27: 25 | AV27: 1665 | AW27: - | AX27: 150 | AY27: - | BB27: 1555 | BC27: 260 | BD27: 110 | BG27: 1440 | BH27: 375 | BI27: 225 | BL27: 1325 | BM27: 490 | BN27: 340 | BO27: 70 | BR27: 1210 | BS27: 605 | BT27: 185 | BW27: 1095 | BX27: - | BY27: 64 | BZ27: 300 | CC27: 980 | CD27: 179 | CE27: 415 | CH27: 865 | CI27: 294 | CJ27: 530 | CM27: 750 | CN27: 409 | CO27: 645 | CR27: 635 | CS27: 524 | CT27: 760 | CW27: 520 | CX27: 639 | CY27: 870 | DB27: 405 | DC27: 754 | DD27: 985 | DG27: 290 | DH27: 869 | DI27: 1100 | DL27: 175 | DM27: 984 | DN27: 1215 | DQ27: 60 | DR27: 1099 | DS27: 1330 | DV27: - | DW27: 55
B28: =B27-1 -> 2814 | C28: 24
B29: =B28-1 -> 2813 | C29: 25
B30: =B29-1 -> 2812 | C30: 26
B31: =B30-1 -> 2811 | C31: 27
B32: =B31-1 -> 2810 | C32: 28
B33: =B32-1 -> 2809 | C33: 29
B34: =B33-1 -> 2808 | C34: 30
B35: =B34-1 -> 2807 | C35: 31
B36: =B35-1 -> 2806 | C36: 32
B37: =B36-1 -> 2805 | C37: 33
B38: =B37-1 -> 2804 | C38: 34
B39: =B38-1 -> 2803 | C39: 35
... B1007: =B1006-1 -> 1835 | C1007: 1003

Sheet Objetos
A1: Nombre | B1: Stats | C1: Precio | D1: Descripcion | E1: Dif Obtencion | F1: Enemigo drop | G1: Rangos 1-10 | 11 -15 | 16-19 | 20
A2: OBJETOS DE CAMPAÑA
A3: Equipo Cultista | D3: =A32 -> Tunica Sencilla | E3: 1d20 ( +10) | F3: =Loots!E2&", " -> Cultista, | G3: =H3&", "&I3 -> 1-10, Ropas rotas y arma pequeña + 1 pieza de oro | H3: 1-10 | I3: Ropas rotas y arma pequeña + 1 pieza de oro
G4: =H4&", "&I4 -> 11-15, Arma y alguna pieza de ropa entera + 3 piezas de oro | H4: 11-15 | I4: Arma y alguna pieza de ropa entera + 3 piezas de oro
G5: =H5&", "&I5 -> 16-19, El equipo exacto + 11 piezas de oro | H5: 16-19 | I5: El equipo exacto + 11 piezas de oro
G6: =H6&", "&I6 -> 20, Equipo del cultista +1 y 15 piezas de oro | H6: 20 | I6: Equipo del cultista +1 y 15 piezas de oro
A7: Equipo Venides | E7: 1d20 (+23) | F7: =Loots!E3&", " -> Venides, | G7: =H7&", "&I7 -> 1-10, Ropas rotas y arma pequeña + 1 pieza de plata | H7: 1-10 | I7: Ropas rotas y arma pequeña + 1 pieza de plata
G8: =H8&", "&I8 -> 11-15, Arma y alguna pieza de ropa entera + 30 piezas de plata | H8: 11-15 | I8: Arma y alguna pieza de ropa entera + 30 piezas de plata
G9: =H9&", "&I9 -> 16-19, El equipo exacto + 45 piezas de plata | H9: 16-19 | I9: El equipo exacto + 45 piezas de plata
G10: =H10&", "&I10 -> 20, Equipo del cultista +1 y 1 pieza de oro | H10: 20 | I10: Equipo del cultista +1 y 1 pieza de oro
A11: Equipo Edul | E11: 1d20 ( +25) | F11: =Loots!E5&", " -> Edul, | G11: =H11&", "&I11 -> 1-10, Ropas rotas y arma pequeña + 1 pieza de plata | H11: 1-10 | I11: Ropas rotas y arma pequeña + 1 pieza de plata
G12: =H12&", "&I12 -> 11-15, Arma y alguna pieza de ropa entera + 30 piezas de plata | H12: 11-15 | I12: Arma y alguna pieza de ropa entera + 30 piezas de plata
G13: =H13&", "&I13 -> 16-19, El equipo exacto + 45 piezas de plata | H13: 16-19 | I13: El equipo exacto + 45 piezas de plata
G14: =H14&", "&I14 -> 20, Equipo del cultista y 1 pieza de oro | H14: 20 | I14: Equipo del cultista y 1 pieza de oro
A15: Equipo Venira | E15: 1d20 ( +25) | F15: =Loots!E6&", " -> Venira, | G15: =H15&", "&I15 -> 1-10, Ropas rotas y arma pequeña + 1 pieza de plata | H15: 1-10 | I15: Ropas rotas y arma pequeña + 1 pieza de plata
G16: =H16&", "&I16 -> 11-15, Arma y alguna pieza de ropa entera + 30 piezas de plata | H16: 11-15 | I16: Arma y alguna pieza de ropa entera + 30 piezas de plata
G17: =H17&", "&I17 -> 16-19, El equipo exacto + 45 piezas de plata | H17: 16-19 | I17: El equipo exacto + 45 piezas de plata
G18: =H18&", "&I18 -> 20, Equipo del cultista y 1 pieza de oro | H18: 20 | I18: Equipo del cultista y 1 pieza de oro
A19: Equipo Sandes | E19: 1d20 ( +10) | F19: =Loots!E7&", " -> Sandes, | G19: =H19&", "&I19 -> 1-10, Ropas rotas y arma pequeña + 15 pieza de oro | H19: 1-10 | I19: Ropas rotas y arma pequeña + 15 pieza de oro
G20: =H20&", "&I20 -> 11-15, Arma y alguna pieza de ropa entera + 50 piezas de oro | H20: 11-15 | I20: Arma y alguna pieza de ropa entera + 50 piezas de oro
G21: =H21&", "&I21 -> 16-19, El equipo exacto + 50 piezas de oro | H21: 16-19 | I21: El equipo exacto + 50 piezas de oro
G22: =H22&", "&I22 -> 20, Equipo del cultista +1 y 100 piezas de oro | H22: 20 | I22: Equipo del cultista +1 y 100 piezas de oro
A23: Equipo Soldado | D23: =A28 -> Armadura Sencilla | E23: 1d20 (+23) | F23: =Loots!E19&", " -> , | G23: =H23&", "&I23 -> 1-10, Ropas rotas y arma pequeña + 1 pieza de plata | H23: 1-10 | I23: Ropas rotas y arma pequeña + 1 pieza de plata
G24: =H24&", "&I24 -> 11-15, Arma y alguna pieza de ropa entera + 12 piezas de plata | H24: 11-15 | I24: Arma y alguna pieza de ropa entera + 12 piezas de plata
G25: =H25&", "&I25 -> 16-19, El equipo exacto + 32 piezas de plata | H25: 16-19 | I25: El equipo exacto + 32 piezas de plata
G26: =H26&", "&I26 -> 20, Equipo del cultista +1 y 1 pieza de oro | H26: 20 | I26: Equipo del cultista +1 y 1 pieza de oro
A27: INVENTARIO DE OBJETOS
A28: Armadura Sencilla | B28: 10 de CA | F28: =Loots!E23&", " -> , | G28: =H28&", "&I28 -> ,
G29: =H29&", "&I29 -> ,
G30: =H30&", "&I30 -> ,
G31: =H31&", "&I31 -> ,
A32: Tunica Sencilla | B32: 7 de CA | F32: =Loots!E27&", " -> , | G32: =H32&", "&I32 -> ,
G33: =H33&", "&I33 -> ,
G34: =H34&", "&I34 -> ,
G35: =H35&", "&I35 -> ,

Sheet Campaña 01
B2: Titulo | C2: Matanza de Boundington
B3: Descripcion | C3: En esta campaña, deberemos acompañar a Venides en su investigación por la capital de Boundingotn, esto nos llevarà a una pequeña introducción que guiara a los jugadores a saber mas sobre los perdidos y sus artimañas para traer a gente a sus cultos, investigaremos diferentes partes de la ciudad donde podremos convivir con los hijos de Boundington. Si ayudan a Venides veran un poco sobre la vida y como los perdidos engañaron y conquistaron todo a su paso sin ningun tipo de miedo. También veremos como los perdidos no son la paz que prometen ser, despues de 3 dias de investigación tendremos que sobrevivir de una epica que nos pondra contra las cuerdas para intentar sobrevivir de la ciudad.
B4: Año | C4: 757 | D4: Despertar Elemental | E4: Loot | G4: Experiencia | H4: =(Enemigos!C2*Enemigos!B2)+(Enemigos!B3*Enemigos!C3)+Enemigos!C7 -> 1675 | I4: Combates | J4: "+5"
B5: Final Bueno | C5: Ganas la confianza de Venides y pasas a la CAMPAÑA Nº2, esta nos hablara de como Venides logra llegar de nuevo a Nefaria y que se encuentra o descubre por el camino.
B6: Final Medio | C6: En este traicionamos la confianza de Venides y no salvamos a Verina ni Edul, podemos intentar recuperar la confianza de Venides ayudandolo cuando nos lo encontremos en medio camino, CAMPAÑA Nº2.2
B7: Final Malo | C7: En este traicionamos a Venides y matamos a Verina y Edul y nos aliamos con Sandes, CAMPAÑA Nº2.4

Sheet Campaña 02
B1: Titulo | C1: Segundo asedio a Ranmont
B2: Descripcion Neutra
B3: Descripcion Buena | C3: Tendremos la mision de salvar al Rey antes de que el asedio consiga entrar en el segundo circulo de la ciudad, en esta mision nuestro objetivo es entrar al corazon de Ranmont y de allí abrir una via de escape para la familia real de Ascaria.
B4: Año | C4: 864 | D4: Despertar Elemental | E4: Loot | G4: Experiencia | I4: Combates | J4: 3
B5: Final Bueno
B6: Final Neutro
B7: Final Malo

Sheet Bonus 02
C2: Titulo | D2: Escapada de Boundington
C3: Descripcion | D3: Venides huye de Boundington de camino a Nefaria, pero durante el camino Edul y Venira nos insisten a pasar antes por Perishton, para salvar el pueblo, de camino se pueden encontrar con bandidos o monstruos a parte del experimento de los perdidos.
C4: Año | D4: 757 | E4: Despertar Elemental | F4: Loot | H4: Experiencia | J4: Combates | K4: 3
C5: Final Bueno | D5: Ganas la confianza de Venides y pasas a la CAMPAÑA Nº2.2, esta nos hablara de como Venides logra llegar de nuevo a Perishton y que se encuentra o descubre por el camino.
C6: Final Medio | D6: En este traicionamos la confianza de Venides y/o no salvamos a Verina y/o Edul, podemos intentar recuperar la confianza de Venides ayudandolo cuando nos lo encontremos en medio camino, CAMPAÑA Nº2.2
C7: Final Malo | D7: En este traicionamos a Venides y matamos a Verina y Edul y nos aliamos con Sandes, CAMPAÑA Nº2.4

Sheet Bonus 02.2
B1: Titulo | C1: Incursion en las Santas Montañas
B2: Descripcion Neutra | C2: Llegas a Perishton huyendo de un monstruo creado por los perdidos una aberracion de la naturaleza, allí tienes que decidir si seguiras confiando en los perdidos o dar la mano a Venides, si eliges lo segundo, los aventureros podran encontrarla y seguir con la historia buena, sino seran victimas de las mentiras de Sandes y alli descubriran que Edul y Venira tenian razón, si no los matas y simplemente no los rescataste en la CAMPAÑA 01 aqui tendras la oportunidad de salvarlos, si los mataste, estaras solo si no te alias con Venides. (Sandes sera tu "amigo")
