Workbook

Sheet Hoja 1
B2: ='Bonificadores - Bastrea Guerrero'!E1 -> #REF! | G2: 1 | J2: ='Bonificadores - Ascaria Guerrero'!E1 -> #REF! | O2: 1
B3: ='Bonificadores - Bastrea Guerrero'!E2 -> #REF! | C3: ='Bonificadores - Bastrea Guerrero'!F2 -> #REF! | D3: ='Bonificadores - Bastrea Guerrero'!G2 -> #REF! | E3: ='Bonificadores - Bastrea Guerrero'!H2 -> #REF! | F3: ='Bonificadores - Bastrea Guerrero'!I2 -> #REF! | G3: ='Bonificadores - Bastrea Guerrero'!J2 -> #REF! | J3: ='Bonificadores - Ascaria Guerrero'!E2 -> #REF! | K3: ='Bonificadores - Ascaria Guerrero'!F2 -> #REF! | L3: ='Bonificadores - Ascaria Guerrero'!G2 -> #REF! | M3: ='Bonificadores - Ascaria Guerrero'!H2 -> #REF! | N3: ='Bonificadores - Ascaria Guerrero'!I2 -> #REF! | O3: ='Bonificadores - Ascaria Guerrero'!J2 -> #REF!
A4: ="Vida "&'Bonificadores - Bastrea Guerrero'!F7 -> #REF! | B4: ='Bonificadores - Bastrea Guerrero'!E3 -> #REF! | C4: ='Bonificadores - Bastrea Guerrero'!F3 -> #REF! | D4: ='Bonificadores - Bastrea Guerrero'!G3 -> #REF! | E4: ='Bonificadores - Bastrea Guerrero'!H3 -> #REF! | F4: ='Bonificadores - Bastrea Guerrero'!I3 -> #REF! | G4: ='Bonificadores - Bastrea Guerrero'!J3 -> #REF! | I4: ="Vida "&'Bonificadores - Ascaria Guerrero'!F7 -> #REF! | J4: ='Bonificadores - Ascaria Guerrero'!E3 -> #REF! | K4: ='Bonificadores - Ascaria Guerrero'!F3 -> #REF! | L4: ='Bonificadores - Ascaria Guerrero'!G3 -> #REF! | M4: ='Bonificadores - Ascaria Guerrero'!H3 -> #REF! | N4: ='Bonificadores - Ascaria Guerrero'!I3 -> #REF! | O4: ='Bonificadores - Ascaria Guerrero'!J3 -> #REF!
A5: ="Armadura "&'Bonificadores - Bastrea Guerrero'!G7 -> #REF! | B5: ='Bonificadores - Bastrea Guerrero'!E4 -> #REF! | C5: ='Bonificadores - Bastrea Guerrero'!F4 -> #REF! | D5: ='Bonificadores - Bastrea Guerrero'!G4 -> #REF! | E5: ='Bonificadores - Bastrea Guerrero'!H4 -> #REF! | F5: ='Bonificadores - Bastrea Guerrero'!I4 -> #REF! | G5: ='Bonificadores - Bastrea Guerrero'!J4 -> #REF! | I5: ="Armadura "&'Bonificadores - Bastrea Guerrero'!N7 -> #REF! | J5: ='Bonificadores - Ascaria Guerrero'!E4 -> #REF! | K5: ='Bonificadores - Ascaria Guerrero'!F4 -> #REF! | L5: ='Bonificadores - Ascaria Guerrero'!G4 -> #REF! | M5: ='Bonificadores - Ascaria Guerrero'!H4 -> #REF! | N5: ='Bonificadores - Ascaria Guerrero'!I4 -> #REF! | O5: ='Bonificadores - Ascaria Guerrero'!J4 -> #REF!
B7: ='Bonificadores - Bastrea Paladin'!E1 -> Humano de Bastrea, Paladin de Nivel 1 | G7: 1 | J7: ='Bonificadores - Ascaria Paladin'!E1 -> #REF! | O7: 1
B8: ='Bonificadores - Bastrea Paladin'!E2 -> Fue | C8: ='Bonificadores - Bastrea Paladin'!F2 -> Des | D8: ='Bonificadores - Bastrea Paladin'!G2 -> Con | E8: ='Bonificadores - Bastrea Paladin'!H2 -> Int | F8: ='Bonificadores - Bastrea Paladin'!I2 -> Sab | G8: ='Bonificadores - Bastrea Paladin'!J2 -> Car | J8: ='Bonificadores - Ascaria Paladin'!E2 -> #REF! | K8: ='Bonificadores - Ascaria Paladin'!F2 -> #REF! | L8: ='Bonificadores - Ascaria Paladin'!G2 -> #REF! | M8: ='Bonificadores - Ascaria Paladin'!H2 -> #REF! | N8: ='Bonificadores - Ascaria Paladin'!I2 -> #REF! | O8: ='Bonificadores - Ascaria Paladin'!J2 -> #REF!
A9: ="Vida "&'Bonificadores - Bastrea Paladin'!F7 -> Vida 7 | B9: ='Bonificadores - Bastrea Paladin'!E3 -> 16 | C9: ='Bonificadores - Bastrea Paladin'!F3 -> 11 | D9: ='Bonificadores - Bastrea Paladin'!G3 -> 11 | E9: ='Bonificadores - Bastrea Paladin'!H3 -> 10 | F9: ='Bonificadores - Bastrea Paladin'!I3 -> 14 | G9: ='Bonificadores - Bastrea Paladin'!J3 -> 7 | I9: ="Vida "&'Bonificadores - Bastrea Guerrero'!M12 -> #REF! | J9: ='Bonificadores - Ascaria Paladin'!E3 -> #REF! | K9: ='Bonificadores - Ascaria Paladin'!F3 -> #REF! | L9: ='Bonificadores - Ascaria Paladin'!G3 -> #REF! | M9: ='Bonificadores - Ascaria Paladin'!H3 -> #REF! | N9: ='Bonificadores - Ascaria Paladin'!I3 -> #REF! | O9: ='Bonificadores - Ascaria Paladin'!J3 -> #REF!
A10: ="Armadura "&'Bonificadores - Bastrea Paladin'!G7 -> Armadura 11 | B10: ='Bonificadores - Bastrea Paladin'!E4 -> 4 | C10: ='Bonificadores - Bastrea Paladin'!F4 -> 1 | D10: ='Bonificadores - Bastrea Paladin'!G4 -> -1 | E10: ='Bonificadores - Bastrea Paladin'!H4 -> 0 | F10: ='Bonificadores - Bastrea Paladin'!I4 -> 3 | G10: ='Bonificadores - Bastrea Paladin'!J4 -> -3 | I10: ="Armadura "&'Bonificadores - Bastrea Guerrero'!N12 -> #REF! | J10: ='Bonificadores - Ascaria Paladin'!E4 -> #REF! | K10: ='Bonificadores - Ascaria Paladin'!F4 -> #REF! | L10: ='Bonificadores - Ascaria Paladin'!G4 -> #REF! | M10: ='Bonificadores - Ascaria Paladin'!H4 -> #REF! | N10: ='Bonificadores - Ascaria Paladin'!I4 -> #REF! | O10: ='Bonificadores - Ascaria Paladin'!J4 -> #REF!
B12: ='Bonificadores - Bastrea Mago'!E1 -> #REF! | G12: 1 | J12: ='Bonificadores - Ascaria Mago'!E1 -> #REF! | O12: 1
B13: ='Bonificadores - Bastrea Mago'!E2 -> #REF! | C13: ='Bonificadores - Bastrea Mago'!F2 -> #REF! | D13: ='Bonificadores - Bastrea Mago'!G2 -> #REF! | E13: ='Bonificadores - Bastrea Mago'!H2 -> #REF! | F13: ='Bonificadores - Bastrea Mago'!I2 -> #REF! | G13: ='Bonificadores - Bastrea Mago'!J2 -> #REF! | J13: ='Bonificadores - Ascaria Mago'!E2 -> #REF! | K13: ='Bonificadores - Ascaria Mago'!F2 -> #REF! | L13: ='Bonificadores - Ascaria Mago'!G2 -> #REF! | M13: ='Bonificadores - Ascaria Mago'!H2 -> #REF! | N13: ='Bonificadores - Ascaria Mago'!I2 -> #REF! | O13: ='Bonificadores - Ascaria Mago'!J2 -> #REF!
A14: ="Vida "&'Bonificadores - Bastrea Mago'!F7 -> #REF! | B14: ='Bonificadores - Bastrea Mago'!E3 -> #REF! | C14: ='Bonificadores - Bastrea Mago'!F3 -> #REF! | D14: ='Bonificadores - Bastrea Mago'!G3 -> #REF! | E14: ='Bonificadores - Bastrea Mago'!H3 -> #REF! | F14: ='Bonificadores - Bastrea Mago'!I3 -> #REF! | G14: ='Bonificadores - Bastrea Mago'!J3 -> #REF! | I14: ="Vida "&'Bonificadores - Bastrea Guerrero'!M17 -> #REF! | J14: ='Bonificadores - Ascaria Mago'!E3 -> #REF! | K14: ='Bonificadores - Ascaria Mago'!F3 -> #REF! | L14: ='Bonificadores - Ascaria Mago'!G3 -> #REF! | M14: ='Bonificadores - Ascaria Mago'!H3 -> #REF! | N14: ='Bonificadores - Ascaria Mago'!I3 -> #REF! | O14: ='Bonificadores - Ascaria Mago'!J3 -> #REF!
A15: ="Armadura "&'Bonificadores - Bastrea Mago'!G7 -> #REF! | B15: ='Bonificadores - Bastrea Mago'!E4 -> #REF! | C15: ='Bonificadores - Bastrea Mago'!F4 -> #REF! | D15: ='Bonificadores - Bastrea Mago'!G4 -> #REF! | E15: ='Bonificadores - Bastrea Mago'!H4 -> #REF! | F15: ='Bonificadores - Bastrea Mago'!I4 -> #REF! | G15: ='Bonificadores - Bastrea Mago'!J4 -> #REF! | I15: ="Armadura "&'Bonificadores - Bastrea Guerrero'!N17 -> #REF! | J15: ='Bonificadores - Ascaria Mago'!E4 -> #REF! | K15: ='Bonificadores - Ascaria Mago'!F4 -> #REF! | L15: ='Bonificadores - Ascaria Mago'!G4 -> #REF! | M15: ='Bonificadores - Ascaria Mago'!H4 -> #REF! | N15: ='Bonificadores - Ascaria Mago'!I4 -> #REF! | O15: ='Bonificadores - Ascaria Mago'!J4 -> #REF!

Sheet Bonificadores - Bastrea Paladin
A1: Tiradas | B1: Bonificadores | E1: =M1& " de " &M2& ", " & M3 & " de Nivel " & $L$2 -> Humano de Bastrea, Paladin de Nivel 1 | L1: Nivel | M1: Humano | R1: Bonus Actual Fuerza | S1: Bonus Actual Destreza | T1: Bonus Actual Constitucion | U1: Bonus Actual Inteligencia | V1: Bonus Actual Sabiduria | W1: Bonus Actual Carisma | X1: LVL | Y1: Bonus
A2: 0-1 | B2: -7 | E2: Fue | F2: Des | G2: Con | H2: Int | I2: Sab | J2: Car | L2: ='Hoja 1'!G7 -> 1 | M2: Bastrea | R2: =LOOKUP($X2+$A$48+$A$53,$X$2:$X$101,$Y$2:$Y$101) -> -3 | S2: =LOOKUP($X2+$B$48+$B$53,$X$2:$X$101,$Y$2:$Y$101) -> -4 | T2: =LOOKUP($X2+$C$48+$C$53,$X$2:$X$101,$Y$2:$Y$101) -> #N/A | U2: =LOOKUP($X2+$A$50+$A$55,$X$2:$X$101,$Y$2:$Y$101) -> -5 | V2: =LOOKUP($X2+$B$50+$B$55,$X$2:$X$101,$Y$2:$Y$101) -> -4 | W2: =LOOKUP($X2+$C$50+$C$55,$X$2:$X$101,$Y$2:$Y$101) -> #N/A | X2: 1 | Y2: -5 | Z2: =($F$9*$X$2+$X$2) -> 7 | AA2: =($F$9*X2+1*1) -> 7
A3: 45353 | B3: -6 | E3: =A43 -> 16 | F3: =B43 -> 11 | G3: =C43 -> 11 | H3: =A45 -> 10 | I3: =B45 -> 14 | J3: =C45 -> 7 | M3: Paladin | R3: =LOOKUP($X3+$A$48+$A$53,$X$2:$X$101,$Y$2:$Y$101) -> -3 | S3: =LOOKUP($X3+$B$48+$B$53,$X$2:$X$101,$Y$2:$Y$101) -> -4 | T3: =LOOKUP($X3+$C$48+$C$53,$X$2:$X$101,$Y$2:$Y$101) -> #N/A | U3: =LOOKUP($X3+$A$50+$A$55,$X$2:$X$101,$Y$2:$Y$101) -> -4 | V3: =LOOKUP($X3+$B$50+$B$55,$X$2:$X$101,$Y$2:$Y$101) -> -3 | W3: =LOOKUP($X3+$C$50+$C$55,$X$2:$X$101,$Y$2:$Y$101) -> #N/A | X3: 2 | Y3: -4 | Z3: =Z2+($F$9) -> 13 | AA3: =AA2+($F$9*X3+X3*1) -> 21
A4: 45416 | B4: -5 | E4: =LOOKUP(A43,$X$2:$X$101,R$2:R$21) -> 4 | F4: =LOOKUP(B43,$X$2:$X$101,S$2:S$21) -> 1 | G4: =LOOKUP(C43,$X$2:$X$101,T$2:T$21) -> -1 | H4: =LOOKUP(A45,$X$2:$X$101,U$2:U$21) -> 0 | I4: =LOOKUP(B45,$X$2:$X$101,V$2:V$21) -> 3 | J4: =LOOKUP(C45,$X$2:$X$101,W$2:W$21) -> -3 | R4: =LOOKUP($X4+$A$48+$A$53,$X$2:$X$101,$Y$2:$Y$101) -> -2 | S4: =LOOKUP($X4+$B$48+$B$53,$X$2:$X$101,$Y$2:$Y$101) -> -3 | T4: =LOOKUP($X4+$C$48+$C$53,$X$2:$X$101,$Y$2:$Y$101) -> #N/A | U4: =LOOKUP($X4+$A$50+$A$55,$X$2:$X$101,$Y$2:$Y$101) -> -4 | V4: =LOOKUP($X4+$B$50+$B$55,$X$2:$X$101,$Y$2:$Y$101) -> -3 | W4: =LOOKUP($X4+$C$50+$C$55,$X$2:$X$101,$Y$2:$Y$101) -> #N/A | X4: 3 | Y4: -4 | Z4: =Z3+($F$9) -> 19 | AA4: =AA3+($F$9*X4+X4*1) -> 42
A5: 45479 | B5: -4 | R5: =LOOKUP($X5+$A$48+$A$53,$X$2:$X$101,$Y$2:$Y$101) -> -2 | S5: =LOOKUP($X5+$B$48+$B$53,$X$2:$X$101,$Y$2:$Y$101) -> -3 | T5: =LOOKUP($X5+$C$48+$C$53,$X$2:$X$101,$Y$2:$Y$101) -> -5 | U5: =LOOKUP($X5+$A$50+$A$55,$X$2:$X$101,$Y$2:$Y$101) -> -3 | V5: =LOOKUP($X5+$B$50+$B$55,$X$2:$X$101,$Y$2:$Y$101) -> -2 | W5: =LOOKUP($X5+$C$50+$C$55,$X$2:$X$101,$Y$2:$Y$101) -> -5 | X5: 4 | Y5: -3 | Z5: =Z4+($F$9) -> 25 | AA5: =AA4+($F$9*X5+X5*1) -> 70
A6: 45543 | B6: -3 | F6: Vida | G6: Armadura | I6: Armadura Objeto | R6: =LOOKUP($X6+$A$48+$A$53,$X$2:$X$101,$Y$2:$Y$101) -> -1 | S6: =LOOKUP($X6+$B$48+$B$53,$X$2:$X$101,$Y$2:$Y$101) -> -2 | T6: =LOOKUP($X6+$C$48+$C$53,$X$2:$X$101,$Y$2:$Y$101) -> -4 | U6: =LOOKUP($X6+$A$50+$A$55,$X$2:$X$101,$Y$2:$Y$101) -> -3 | V6: =LOOKUP($X6+$B$50+$B$55,$X$2:$X$101,$Y$2:$Y$101) -> -2 | W6: =LOOKUP($X6+$C$50+$C$55,$X$2:$X$101,$Y$2:$Y$101) -> -4 | X6: 5 | Y6: -3 | Z6: =Z5+($F$9) -> 31 | AA6: =AA5+($F$9*X6+X6*1) -> 105
A7: 45606 | B7: -2 | E7: 12 | F7: =LOOKUP(L2,$X$2:$X$101,$Z$2:$Z$101) -> 7 | G7: =(E4/2)+G4+I7 -> 11 | I7: 10 | J7: Armadura De Placas Sencilla | R7: =LOOKUP($X7+$A$48+$A$53,$X$2:$X$101,$Y$2:$Y$101) -> -1 | S7: =LOOKUP($X7+$B$48+$B$53,$X$2:$X$101,$Y$2:$Y$101) -> -2 | T7: =LOOKUP($X7+$C$48+$C$53,$X$2:$X$101,$Y$2:$Y$101) -> -4 | U7: =LOOKUP($X7+$A$50+$A$55,$X$2:$X$101,$Y$2:$Y$101) -> -2 | V7: =LOOKUP($X7+$B$50+$B$55,$X$2:$X$101,$Y$2:$Y$101) -> -1 | W7: =LOOKUP($X7+$C$50+$C$55,$X$2:$X$101,$Y$2:$Y$101) -> -4 | X7: 6 | Y7: -2 | Z7: =Z6+($F$9) -> 37 | AA7: =AA6+($F$9*X7+X7*1) -> 147
A8: 12-13 | B8: -1 | R8: =LOOKUP($X8+$A$48+$A$53,$X$2:$X$101,$Y$2:$Y$101) -> 0 | S8: =LOOKUP($X8+$B$48+$B$53,$X$2:$X$101,$Y$2:$Y$101) -> -1 | T8: =LOOKUP($X8+$C$48+$C$53,$X$2:$X$101,$Y$2:$Y$101) -> -3 | U8: =LOOKUP($X8+$A$50+$A$55,$X$2:$X$101,$Y$2:$Y$101) -> -2 | V8: =LOOKUP($X8+$B$50+$B$55,$X$2:$X$101,$Y$2:$Y$101) -> -1 | W8: =LOOKUP($X8+$C$50+$C$55,$X$2:$X$101,$Y$2:$Y$101) -> -3 | X8: 7 | Y8: -2 | Z8: =Z7+($F$9) -> 43 | AA8: =AA7+($F$9*X8+X8*1) -> 196
A9: 14-15 | B9: 0 | F9: 6 | R9: =LOOKUP($X9+$A$48+$A$53,$X$2:$X$101,$Y$2:$Y$101) -> 0 | S9: =LOOKUP($X9+$B$48+$B$53,$X$2:$X$101,$Y$2:$Y$101) -> -1 | T9: =LOOKUP($X9+$C$48+$C$53,$X$2:$X$101,$Y$2:$Y$101) -> -3 | U9: =LOOKUP($X9+$A$50+$A$55,$X$2:$X$101,$Y$2:$Y$101) -> -1 | V9: =LOOKUP($X9+$B$50+$B$55,$X$2:$X$101,$Y$2:$Y$101) -> 0 | W9: =LOOKUP($X9+$C$50+$C$55,$X$2:$X$101,$Y$2:$Y$101) -> -3 | X9: 8 | Y9: -1 | Z9: =Z8+($F$9) -> 49 | AA9: =AA8+($F$9*X9+X9*1) -> 252
A10: 16-17 | B10: =1 -> 1 | E10: 4 | F10: =2 -> 2 | G10: / Habilidad + Nivel Creador + Bonus Inicial | I10: Creador 1 | J10: 1 + habilidad | K10: =F10+F11+F12+F13+F14 -> 10 | M10: =(E3+F3+G3+H3+I3+J3+K10+K16)/6 -> 13.833333 | R10: =LOOKUP($X10+$A$48+$A$53,$X$2:$X$101,$Y$2:$Y$101) -> 1 | S10: =LOOKUP($X10+$B$48+$B$53,$X$2:$X$101,$Y$2:$Y$101) -> 0 | T10: =LOOKUP($X10+$C$48+$C$53,$X$2:$X$101,$Y$2:$Y$101) -> -2 | U10: =LOOKUP($X10+$A$50+$A$55,$X$2:$X$101,$Y$2:$Y$101) -> -1 | V10: =LOOKUP($X10+$B$50+$B$55,$X$2:$X$101,$Y$2:$Y$101) -> 0 | W10: =LOOKUP($X10+$C$50+$C$55,$X$2:$X$101,$Y$2:$Y$101) -> -2 | X10: 9 | Y10: -1 | Z10: =Z9+($F$9) -> 55 | AA10: =AA9+($F$9*X10+X10*1) -> 315
A11: 18-19 | B11: =1 -> 1 | E11: 8 | F11: 2 | G11: / Habilidad + Nivel Creador | I11: Creador 2 | J11: 2 + habilidad | R11: =LOOKUP($X11+$A$48+$A$53,$X$2:$X$101,$Y$2:$Y$101) -> 1 | S11: =LOOKUP($X11+$B$48+$B$53,$X$2:$X$101,$Y$2:$Y$101) -> 0 | T11: =LOOKUP($X11+$C$48+$C$53,$X$2:$X$101,$Y$2:$Y$101) -> -2 | U11: =LOOKUP($X11+$A$50+$A$55,$X$2:$X$101,$Y$2:$Y$101) -> 0 | V11: =LOOKUP($X11+$B$50+$B$55,$X$2:$X$101,$Y$2:$Y$101) -> 1 | W11: =LOOKUP($X11+$C$50+$C$55,$X$2:$X$101,$Y$2:$Y$101) -> -2 | X11: 10 | Y11: 0 | Z11: =Z10+($F$9) -> 61 | AA11: =AA10+($F$9*X11+X11*1) -> 385
A12: 20-21 | B12: 2 | E12: 12 | F12: 2 | G12: / Habilidad + Nivel Creador | I12: Creador 3 | J12: 3 + habilidad | R12: =LOOKUP($X12+$A$48+$A$53,$X$2:$X$101,$Y$2:$Y$101) -> 2 | S12: =LOOKUP($X12+$B$48+$B$53,$X$2:$X$101,$Y$2:$Y$101) -> 1 | T12: =LOOKUP($X12+$C$48+$C$53,$X$2:$X$101,$Y$2:$Y$101) -> -1 | U12: =LOOKUP($X12+$A$50+$A$55,$X$2:$X$101,$Y$2:$Y$101) -> 0 | V12: =LOOKUP($X12+$B$50+$B$55,$X$2:$X$101,$Y$2:$Y$101) -> 1 | W12: =LOOKUP($X12+$C$50+$C$55,$X$2:$X$101,$Y$2:$Y$101) -> -1 | X12: 11 | Y12: 0 | Z12: =Z11+($F$9) -> 67 | AA12: =AA11+($F$9*X12+X12*1) -> 462
A13: 22-23 | B13: 2 | E13: 16 | F13: 2 | G13: / Habilidad + Nivel Creador | I13: Creador 4 | J13: 4 + habilidad | R13: =LOOKUP($X13+$A$48+$A$53,$X$2:$X$101,$Y$2:$Y$101) -> 2 | S13: =LOOKUP($X13+$B$48+$B$53,$X$2:$X$101,$Y$2:$Y$101) -> 1 | T13: =LOOKUP($X13+$C$48+$C$53,$X$2:$X$101,$Y$2:$Y$101) -> -1 | U13: =LOOKUP($X13+$A$50+$A$55,$X$2:$X$101,$Y$2:$Y$101) -> 1 | V13: =LOOKUP($X13+$B$50+$B$55,$X$2:$X$101,$Y$2:$Y$101) -> 2 | W13: =LOOKUP($X13+$C$50+$C$55,$X$2:$X$101,$Y$2:$Y$101) -> -1 | X13: 12 | Y13: 1 | Z13: =Z12+($F$9) -> 73 | AA13: =AA12+($F$9*X13+X13*1) -> 546
A14: 24-25 | B14: 3 | E14: 19 | F14: 2 | G14: / Habilidad + Nivel Creador | I14: Creador 5 | J14: 5 + habilidad | R14: =LOOKUP($X14+$A$48+$A$53,$X$2:$X$101,$Y$2:$Y$101) -> 3 | S14: =LOOKUP($X14+$B$48+$B$53,$X$2:$X$101,$Y$2:$Y$101) -> 2 | T14: =LOOKUP($X14+$C$48+$C$53,$X$2:$X$101,$Y$2:$Y$101) -> 0 | U14: =LOOKUP($X14+$A$50+$A$55,$X$2:$X$101,$Y$2:$Y$101) -> 1 | V14: =LOOKUP($X14+$B$50+$B$55,$X$2:$X$101,$Y$2:$Y$101) -> 2 | W14: =LOOKUP($X14+$C$50+$C$55,$X$2:$X$101,$Y$2:$Y$101) -> 0 | X14: 13 | Y14: 1 | Z14: =Z13+($F$9) -> 79 | AA14: =AA13+($F$9*X14+X14*1) -> 637
A15: 26-27 | B15: 3 | R15: =LOOKUP($X15+$A$48+$A$53,$X$2:$X$101,$Y$2:$Y$101) -> 3 | S15: =LOOKUP($X15+$B$48+$B$53,$X$2:$X$101,$Y$2:$Y$101) -> 2 | T15: =LOOKUP($X15+$C$48+$C$53,$X$2:$X$101,$Y$2:$Y$101) -> 0 | U15: =LOOKUP($X15+$A$50+$A$55,$X$2:$X$101,$Y$2:$Y$101) -> 2 | V15: =LOOKUP($X15+$B$50+$B$55,$X$2:$X$101,$Y$2:$Y$101) -> 3 | W15: =LOOKUP($X15+$C$50+$C$55,$X$2:$X$101,$Y$2:$Y$101) -> 0 | X15: 14 | Y15: 2 | Z15: =Z14+($F$9) -> 85 | AA15: =AA14+($F$9*X15+X15*1) -> 735
A16: 28-29 | B16: =4 -> 4 | E16: 3 | F16: 1 | G16: / Habilidad de Subclase | I16: Subclase 1 | K16: =F16+F17+F18+F19+F20+F21+F22+F23 -> 4 | R16: =LOOKUP($X16+$A$48+$A$53,$X$2:$X$101,$Y$2:$Y$101) -> 4 | S16: =LOOKUP($X16+$B$48+$B$53,$X$2:$X$101,$Y$2:$Y$101) -> 3 | T16: =LOOKUP($X16+$C$48+$C$53,$X$2:$X$101,$Y$2:$Y$101) -> 1 | U16: =LOOKUP($X16+$A$50+$A$55,$X$2:$X$101,$Y$2:$Y$101) -> 2 | V16: =LOOKUP($X16+$B$50+$B$55,$X$2:$X$101,$Y$2:$Y$101) -> 3 | W16: =LOOKUP($X16+$C$50+$C$55,$X$2:$X$101,$Y$2:$Y$101) -> 1 | X16: 15 | Y16: 2 | Z16: =Z15+($F$9) -> 91 | AA16: =AA15+($F$9*X16+X16*1) -> 840
A17: 30-31 | B17: =4 -> 4 | E17: 5 | F17: 0 | G17: / Habilidad de Subclase | I17: Subclase 2 | R17: =LOOKUP($X17+$A$48+$A$53,$X$2:$X$101,$Y$2:$Y$101) -> 4 | S17: =LOOKUP($X17+$B$48+$B$53,$X$2:$X$101,$Y$2:$Y$101) -> 3 | T17: =LOOKUP($X17+$C$48+$C$53,$X$2:$X$101,$Y$2:$Y$101) -> 1 | U17: =LOOKUP($X17+$A$50+$A$55,$X$2:$X$101,$Y$2:$Y$101) -> 3 | V17: =LOOKUP($X17+$B$50+$B$55,$X$2:$X$101,$Y$2:$Y$101) -> 4 | W17: =LOOKUP($X17+$C$50+$C$55,$X$2:$X$101,$Y$2:$Y$101) -> 1 | X17: 16 | Y17: 3 | Z17: =Z16+($F$9) -> 97 | AA17: =AA16+($F$9*X17+X17*1) -> 952
A18: 32-33 | B18: 5 | E18: 7 | F18: 1 | G18: / Habilidad de Subclase | I18: Subclase 3 | R18: =LOOKUP($X18+$A$48+$A$53,$X$2:$X$101,$Y$2:$Y$101) -> 5 | S18: =LOOKUP($X18+$B$48+$B$53,$X$2:$X$101,$Y$2:$Y$101) -> 4 | T18: =LOOKUP($X18+$C$48+$C$53,$X$2:$X$101,$Y$2:$Y$101) -> 2 | U18: =LOOKUP($X18+$A$50+$A$55,$X$2:$X$101,$Y$2:$Y$101) -> 3 | V18: =LOOKUP($X18+$B$50+$B$55,$X$2:$X$101,$Y$2:$Y$101) -> 4 | W18: =LOOKUP($X18+$C$50+$C$55,$X$2:$X$101,$Y$2:$Y$101) -> 2 | X18: 17 | Y18: 3 | Z18: =Z17+($F$9) -> 103 | AA18: =AA17+($F$9*X18+X18*1) -> 1071
A19: 34-35 | B19: 5 | E19: 9 | F19: 0 | G19: / Habilidad de Subclase | I19: Subclase 4 | R19: =LOOKUP($X19+$A$48+$A$53,$X$2:$X$101,$Y$2:$Y$101) -> 5 | S19: =LOOKUP($X19+$B$48+$B$53,$X$2:$X$101,$Y$2:$Y$101) -> 4 | T19: =LOOKUP($X19+$C$48+$C$53,$X$2:$X$101,$Y$2:$Y$101) -> 2 | U19: =LOOKUP($X19+$A$50+$A$55,$X$2:$X$101,$Y$2:$Y$101) -> 4 | V19: =LOOKUP($X19+$B$50+$B$55,$X$2:$X$101,$Y$2:$Y$101) -> 5 | W19: =LOOKUP($X19+$C$50+$C$55,$X$2:$X$101,$Y$2:$Y$101) -> 2 | X19: 18 | Y19: 4 | Z19: =Z18+($F$9) -> 109 | AA19: =AA18+($F$9*X19+X19*1) -> 1197
A20: 36-37 | B20: 6 | E20: 11 | F20: 1 | G20: / Habilidad de Subclase | I20: Subclase 5 | R20: =LOOKUP($X20+$A$48+$A$53,$X$2:$X$101,$Y$2:$Y$101) -> 6 | S20: =LOOKUP($X20+$B$48+$B$53,$X$2:$X$101,$Y$2:$Y$101) -> 5 | T20: =LOOKUP($X20+$C$48+$C$53,$X$2:$X$101,$Y$2:$Y$101) -> 3 | U20: =LOOKUP($X20+$A$50+$A$55,$X$2:$X$101,$Y$2:$Y$101) -> 4 | V20: =LOOKUP($X20+$B$50+$B$55,$X$2:$X$101,$Y$2:$Y$101) -> 5 | W20: =LOOKUP($X20+$C$50+$C$55,$X$2:$X$101,$Y$2:$Y$101) -> 3 | X20: 19 | Y20: 4 | Z20: =Z19+($F$9) -> 115 | AA20: =AA19+($F$9*X20+X20*1) -> 1330
A21: 38-39 | B21: 6 | E21: 13 | F21: 0 | G21: / Habilidad de Subclase | I21: Subclase 6 | R21: =LOOKUP($X21+$A$48+$A$53,$X$2:$X$101,$Y$2:$Y$101) -> 6 | S21: =LOOKUP($X21+$B$48+$B$53,$X$2:$X$101,$Y$2:$Y$101) -> 5 | T21: =LOOKUP($X21+$C$48+$C$53,$X$2:$X$101,$Y$2:$Y$101) -> 3 | U21: =LOOKUP($X21+$A$50+$A$55,$X$2:$X$101,$Y$2:$Y$101) -> 5 | V21: =LOOKUP($X21+$B$50+$B$55,$X$2:$X$101,$Y$2:$Y$101) -> 6 | W21: =LOOKUP($X21+$C$50+$C$55,$X$2:$X$101,$Y$2:$Y$101) -> 3 | X21: 20 | Y21: 5 | Z21: =Z20+($F$9) -> 121 | AA21: =AA20+($F$9*X21+X21*1) -> 1470
A22: 40-41 | B22: 7 | E22: 15 | F22: 1 | G22: / Habilidad de Subclase | I22: Subclase 7 | X22: 21 | Y22: 5 | Z22: =Z21+($F$9) -> 127 | AA22: =AA21+($F$9*X22+X22*1) -> 1617
A23: 42-43 | B23: 7 | E23: 17 | F23: 0 | G23: / Habilidad de Subclase | I23: Subclase 8 | X23: 22 | Y23: 6 | Z23: =Z22+($F$9) -> 133 | AA23: =AA22+($F$9*X23+X23*1) -> 1771
A24: 44-45 | B24: 8 | X24: 23 | Y24: 6 | Z24: =Z23+($F$9) -> 139 | AA24: =AA23+($F$9*X24+X24*1) -> 1932
A25: 46-47 | B25: 8 | X25: 24 | Y25: 7 | Z25: =Z24+($F$9) -> 145 | AA25: =AA24+($F$9*X25+X25*1) -> 2100
A26: 48-49 | B26: 9 | X26: 25 | Y26: 7 | Z26: =Z25+($F$9) -> 151 | AA26: =AA25+($F$9*X26+X26*1) -> 2275
A27: 50-51 | B27: 9 | X27: 26 | Y27: 8 | Z27: =Z26+($F$9) -> 157 | AA27: =AA26+($F$9*X27+X27*1) -> 2457
A28: 52-53 | B28: 10 | X28: 27 | Y28: 8 | Z28: =Z27+($F$9) -> 163 | AA28: =AA27+($F$9*X28+X28*1) -> 2646
A29: 54-55 | B29: 10 | X29: 28 | Y29: 9 | Z29: =Z28+($F$9) -> 169 | AA29: =AA28+($F$9*X29+X29*1) -> 2842
A30: 56-57 | B30: 11 | X30: 29 | Y30: 9 | Z30: =Z29+($F$9) -> 175 | AA30: =AA29+($F$9*X30+X30*1) -> 3045
A31: 58-59 | B31: 11 | X31: 30 | Y31: 10 | Z31: =Z30+($F$9) -> 181 | AA31: =AA30+($F$9*X31+X31*1) -> 3255
A32: 60-61 | B32: 12 | X32: 31 | Y32: 0 | Z32: =Z31+($F$9) -> 187 | AA32: =AA31+($F$9*X32+X32*1) -> 3472
A33: 62-63 | B33: 12 | X33: 32 | Y33: 0 | Z33: =Z32+($F$9) -> 193 | AA33: =AA32+($F$9*X33+X33*1) -> 3696
A34: 64-65 | B34: 13 | X34: 33 | Y34: 0 | Z34: =Z33+($F$9) -> 199 | AA34: =AA33+($F$9*X34+X34*1) -> 3927
A35: 66-67 | B35: 13 | X35: 34 | Y35: 0 | Z35: =Z34+($F$9) -> 205 | AA35: =AA34+($F$9*X35+X35*1) -> 4165
... A37: 70-71 | B37: 14 | X37: 36 | Y37: 0 | Z37: =Z36+($F$9) -> 217 | AA37: =AA36+($F$9*X37+X37*1) -> 4662
X38: 37 | Y38: 0 | Z38: =Z37+($F$9) -> 223 | AA38: =AA37+($F$9*X38+X38*1) -> 4921
X39: 38 | Y39: 0 | Z39: =Z38+($F$9) -> 229 | AA39: =AA38+($F$9*X39+X39*1) -> 5187
X40: 39 | Y40: 0 | Z40: =Z39+($F$9) -> 235 | AA40: =AA39+($F$9*X40+X40*1) -> 5460
A41: Resultado final | X41: 40 | Y41: 0 | Z41: =Z40+($F$9) -> 241 | AA41: =AA40+($F$9*X41+X41*1) -> 5740
...

Sheet Clases
A1: Class | C1: Subclass | D1: Proficiencies | F1: Hit Dice | G1: Saving Throws | I1: Vida | J1: Saving Throws | K1: Weapon Proficiencies | L1: Armor Proficiency | M1: Starting Equipment | N1: Funciones | O1: 1 | P1: 2 | Q1: 3 | R1: 4 | S1: 5 | T1: 6 | U1: 7 | V1: 8 | W1: 9 | X1: 10 | Y1: 11 | Z1: 12 | AA1: 13 | AB1: 14 | AC1: 15 | AD1: 16 | AE1: 17 | AF1: 18 | AG1: 19 | AH1: 20 | AI1: Caster; | AK1: spell modifier
A2: PALADIN | D2: 2 | E2: ='Habilidades de Rol'!D29 -> Atletismo, Perspicacia, Intimidacion, Medicina, Persuasion, Religion, | F2: 10 | G2: SAB | H2: CAR | J2: SAB + CAR | K2: simple, martial | L2: Todo tipo de Armadura y escudos | M2: Any Martial Weapon and Shield; Any Two Martial Weapons, Javelin; (x5); Any Simple Melee Weapon, Priest's Pack; Explorer's Pack, Chain mail, holy symbol | O2: Divine Sense,Lay on Hands | P2: Fighting Style,Divine Smite | Q2: Divine Health, Channel Divinity | R2: Ability Score Improvement | S2: Extra Attack | T2: Aura of Protection | U2: Aura of Devotion | V2: Ability Score Improvement | W2: - | X2: Aura of Courage | Y2: Improved Divine Smite | Z2: Ability Score Improvement | AA2: - | AB2: Cleansing Touch | AC2: Aura of Devotion | AD2: Ability Score Improvement | AE2: - | AF2: Aura Improvement | AG2: Ability Score Improvement | AH2: Holy Nimbus | AI2: Half | AJ2: Car | AK2: --
A3: PALADIN | B3: GUERRERO | C3: Caballero templario | D3: 3 | E3: =D2&" Escogidas anteriormente + 1 de: "&+E14 -> 2 Escogidas anteriormente + 1 de: Acrobacias, Trato con animales, Atletismo, Historia, Perspicacia, Intimidacion, Percepcion, Supervivencia, | F3: =F14&" + "&I3 -> 10 + CONS | G3: =J2 -> SAB + CAR | H3: =J14 -> FUE + CONS | I3: CONS | J3: CONS + FUE + SAB | K3: Simple, Marcial, Experto en dos Armas | L3: =L14 -> Todo tipo de Armadura y escudos | N3: Armas con filo. Pelea sin armas. Moral. | AI3: Half | AJ3: Sab | AK3: --
A4: PALADIN | B4: MAGO | C4: Guardian elemental | E4: ="2 Escogidas anteriormente + 1 de: "&+E14 -> 2 Escogidas anteriormente + 1 de: Acrobacias, Trato con animales, Atletismo, Historia, Perspicacia, Intimidacion, Percepcion, Supervivencia, | F4: 6 | G4: INT, SAB | H4: SAB, CAR | J4: INT + CAR +SAB
A5: PALADIN | B5: HECHICERO | C5: Gladiador arcano | E5: ="2 Escogidas anteriormente + 1 de: "&+E14 -> 2 Escogidas anteriormente + 1 de: Acrobacias, Trato con animales, Atletismo, Historia, Perspicacia, Intimidacion, Percepcion, Supervivencia, | F5: 6 | G5: CON, CAR | H5: SAB, CAR | J5: CAR + SAB +CON
A6: PALADIN | B6: BRUJO | C6: Apóstata | D6: 3 | E6: =D2&" Escogidas anteriormente + 1 de: "&+E50 -> 2 Escogidas anteriormente + 1 de: Arcano, Engaño, Historia, Intimidacion, Investigacion, Naturaleza, Religion, | F6: =F50&" + "&I6 -> 8 + CAR | G6: =J2 -> SAB + CAR | H6: =J50 -> SAB + CAR | I6: CAR | J6: CAR+1 + SAB+1 | K6: Simple | L6: Ligera | AI6: Full | AJ6: Car
A7: PALADIN | B7: PÍCARO | C7: Portador de secretos | E7: ="2 Escogidas anteriormente + 1 de: "&+E14 -> 2 Escogidas anteriormente + 1 de: Acrobacias, Trato con animales, Atletismo, Historia, Perspicacia, Intimidacion, Percepcion, Supervivencia, | F7: 8 | G7: DES, INT | H7: SAB, CAR
A8: PALADIN | B8: BARDO | C8: Trotamundos | E8: ="2 Escogidas anteriormente + 1 de: "&+E14 -> 2 Escogidas anteriormente + 1 de: Acrobacias, Trato con animales, Atletismo, Historia, Perspicacia, Intimidacion, Percepcion, Supervivencia, | F8: 8 | G8: DES, CAR | H8: SAB, CAR
A9: PALADIN | B9: BÁRBARO | C9: Hermano de sangre | D9: 3 | E9: =D2&" Escogidas anteriormente + 1 de: "&+E86 -> 2 Escogidas anteriormente + 1 de: Trato con animales, Atletismo, Intimidacion, Naturaleza, Percepcion, Supervivencia, | F9: =F86&" + "&I9 -> 12 + CONS | G9: =J2 -> SAB + CAR | H9: =J86 -> FUE + CONS | I9: CONS | J9: FUE + CONS + CAR | K9: =K86& ", Experto en habilidades de combate cuerpo a cuerpo" -> Simple, Martial, Experto en habilidades de combate cuerpo a cuerpo | L9: =L86 -> Armaduras ligeras y medianas, Escudos | AI9: Half | AJ9: Car
A10: PALADIN | B10: ARTIFICIERO | C10: Adorador de la polvora | E10: ="2 Escogidas anteriormente + 1 de: "&+E14 -> 2 Escogidas anteriormente + 1 de: Acrobacias, Trato con animales, Atletismo, Historia, Perspicacia, Intimidacion, Percepcion, Supervivencia, | F10: 10 | G10: CONS, INT | H10: SAB, CAR
A11: PALADIN | B11: DRUIDA | C11: Devoto del bosque | D11: 3 | E11: =D2&" Escogidas anteriormente + 1 de: "&+E110 -> 2 Escogidas anteriormente + 1 de: Trato con animales, Arcano, Perspicacia, Medicina, Naturaleza, Percepcion, Religion, Supervivencia, | F11: =F110&" + "&I11 -> 8 + SAB | G11: =J2 -> SAB + CAR | H11: =J110 -> INT + SAB | I11: SAB | J11: INT + SAB + CAR | K11: =K110 -> Club, Dagger, Dart, Javelin, mace, quarterstaff, scimitar, sickle, sling, spear | L11: =L110 -> Armaduras ligeras y medianas, Escudos (No metalicas) | AI11: Full | AJ11: INT
A12: PALADIN | B12: CAZADOR | C12: Domador Celestial | E12: ="2 Escogidas anteriormente + 1 de: "&+E14 -> 2 Escogidas anteriormente + 1 de: Acrobacias, Trato con animales, Atletismo, Historia, Perspicacia, Intimidacion, Percepcion, Supervivencia, | F12: 10 | G12: FUE, DES | H12: SAB, CAR
A13: PALADIN | B13: CHAMÁN | C13: Alto Iluminado | E13: ="2 Escogidas anteriormente + 1 de: "&+E14 -> 2 Escogidas anteriormente + 1 de: Acrobacias, Trato con animales, Atletismo, Historia, Perspicacia, Intimidacion, Percepcion, Supervivencia, | F13: 8 | G13: FUE, DES | H13: SAB, CAR
A14: GUERRERO | D14: 2 | E14: ='Habilidades de Rol'!D27 -> Acrobacias, Trato con animales, Atletismo, Historia, Perspicacia, Intimidacion, Percepcion, Supervivencia, | F14: 10 | G14: Strength | H14: Constitution | J14: FUE + CONS | K14: simple, martial | L14: Todo tipo de Armadura y escudos | M14: Chain Mail;Leather Armor;Longbow,Any Martial weapon and shield;OR;Any Two Martial Weapons,Light Crossbow;OR;Handaxe X2,Dungeoneer's Pack;OR;Explorer's Pack | O14: Fighting Style,Second Wind | P14: Action Surge (1) | Q14: Combat Superiority,Student of War | R14: Ability Score Improvement | S14: Extra Attack | T14: Ability Score Improvement | U14: Know Your Enemy | V14: Ability Score Improvement | W14: Indomitable (1) | X14: Improved Combat Superiority | Y14: Extra Attack (3) | Z14: Ability Score Improvement | AA14: Indomitable (2) | AB14: Ability Score Improvement | AC14: Relentless | AD14: Ability Score Improvement | AE14: Action Surge (2), Indomitable (3) | AF14: Improved Combat Superiority | AG14: Ability Score Improvement | AH14: Extra Attack (3) | AI14: No | AJ14: -
A15: GUERRERO | B15: MAGO | C15: Guerrero arcano
A16: GUERRERO | B16: HECHICERO | C16: Nacido del trueno | D16: 3 | E16: =D14&" Escogidas anteriormente + 1 de: "&+E38 -> 2 Escogidas anteriormente + 1 de: Arcano, Engaño, Perspicacia, Intimidacion, Persuasion, Religion, | F16: =F38&" + "&I16 -> 6 + CONS | G16: =J14 -> FUE + CONS | H16: =J38 -> CON + CAR | I16: CONS | J16: FUE + CONS + CAR | K16: =K38 -> dagger, dart, sling, quarterstaff, light crossbow | L16: =L38 -> Túnica
A17: GUERRERO | B17: BRUJO | C17: Caballero profano
A18: GUERRERO | B18: PÍCARO | C18: Hoja escurridiza
A19: GUERRERO | B19: BARDO | C19: Feriante | D19: 3 | E19: =D14&" Escogidas anteriormente + 1 de: "&+E74 -> 2 Escogidas anteriormente + 1 de: Acrobacias, Trato con animales, Arcano, Atletismo, Engaño, Historia, Perspicacia, Intimidacion, Investigacion, Medicina, Naturaleza, Percepcion, Interpretacion, Persuasion, Religion, Juego de Manos, Sigilo, Supervivencia, | F19: =F74&" + "&I19 -> 8 + CAR | G19: =J14 -> FUE + CONS | H19: =J74 -> DES + CAR | I19: CAR | J19: FUE + DES + CAR | K19: =K74 -> Simple, hand crossbow, longsword, rapier, shortsword | L19: =L74 -> Armaduras ligeras
A20: GUERRERO | B20: BÁRBARO | C20: Guerrero del puño cortante | D20: 3 | E20: =D14&" Escogidas anteriormente + 1 de: "&+E86 -> 2 Escogidas anteriormente + 1 de: Trato con animales, Atletismo, Intimidacion, Naturaleza, Percepcion, Supervivencia, | F20: =F86&" + "&I20 -> 12 + CONS | G20: =J14 -> FUE + CONS | H20: =J86 -> FUE + CONS | I20: CONS | J20: FUE +1 + CONS +1 | K20: =K86 -> Simple, Martial | L20: =L86 -> Armaduras ligeras y medianas, Escudos
A21: GUERRERO | B21: ARTIFICIERO | C21: Artillero
A22: GUERRERO | B22: DRUIDA | C22: -
A23: GUERRERO | B23: CAZADOR | C23: Mercenario
A24: GUERRERO | B24: CHAMÁN | C24: -
A25: GUERRERO | B25: PALADIN | C25: - | G25: SAB, CAR
A26: MAGO | D26: 2 | E26: ='Habilidades de Rol'!D34 -> Arcano, Historia, Perspicacia, Investigacion, Medicina, Religion, | F26: 6 | G26: Intelligence | H26: Wisdom | J26: INT + SAB | K26: dagger, dart, sling, quarterstaff, light crossbow | L26: Túnica | M26: Quarterstaff;OR;Dagger,Component pouch;OR;arcane focus,Scholar's Pack;OR;Explorer's Pack,SpellBook | O26: Spellcasting, Arcane Recovery | P26: Abjuration Savant,Arcane Ward | Q26: - | R26: Ability Score Improvement | S26: - | T26: Projected Ward | U26: - | V26: Ability Score Improvement | W26: - | X26: Improved Abjuration | Y26: - | Z26: Ability Score Improvement | AA26: - | AB26: Spell Resistance | AC26: - | AD26: Ability Score Improvement | AF26: Spell Mastery | AG26: Ability Score Improvement | AH26: Signature Spell | AI26: Full | AJ26: Int | AK26: --
A27: MAGO | B27: HECHICERO | C27: Señor de los astros | D27: 3 | E27: =D26&" Escogidas anteriormente + 1 de: "&+E38 -> 2 Escogidas anteriormente + 1 de: Arcano, Engaño, Perspicacia, Intimidacion, Persuasion, Religion, | F27: =F86&" + "&I27 -> 12 + SAB | G27: =J26 -> INT + SAB | H27: =J38 -> CON + CAR | I27: SAB | J27: INT + SAB + CAR
A28: MAGO | B28: BRUJO | C28: Llamado por la oscuridad
A29: MAGO | B29: PÍCARO | C29: Mago del paso ligero | D29: 3 | E29: =D26&" Escogidas anteriormente + 1 de: "&+E62 -> 2 Escogidas anteriormente + 1 de: Acrobacias, Atletismo, Engaño, Perspicacia, Intimidacion, Investigacion, Percepcion, Interpretacion, Persuasion, Juego de Manos, Sigilo, | F29: =F62&" + "&I29 -> 8 + INT | G29: =J26 -> INT + SAB | H29: =J62 -> DES + INT | I29: INT | J29: INT + DES + SAB
A30: MAGO | B30: BARDO | C30: -
A31: MAGO | B31: BÁRBARO | C31: Destructor rúnico
A32: MAGO | B32: ARTIFICIERO | C32: Tirador arcano
A33: MAGO | B33: DRUIDA | C33: Mago lunar
A34: MAGO | B34: CAZADOR | C34: Invocador de bestias
A35: MAGO | B35: CHAMÁN | C35: Domador de elementos | D35: 3 | E35: =D26&" Escogidas anteriormente + 1 de: "&+E134 -> 2 Escogidas anteriormente + 1 de: Acrobacias, Atletismo, Historia, Perspicacia, Religion, Sigilo, | F35: =F134&" + "&I35 -> 8 + SAB | G35: =J26 -> INT + SAB | H35: =J134 -> DES + SAB | I35: SAB | J35: INT + SAB + DES
A36: MAGO | B36: PALADIN | C36: - | G36: SAB, CAR
A37: MAGO | B37: GUERRERO | C37: -
A38: HECHICERO | D38: 2 | E38: ='Habilidades de Rol'!D32 -> Arcano, Engaño, Perspicacia, Intimidacion, Persuasion, Religion, | F38: 6 | G38: Constitution | H38: Charisma | J38: CON + CAR | K38: dagger, dart, sling, quarterstaff, light crossbow | L38: Túnica | M38: Light Crossbow;Any Simple Weapon, ; ;Dagger X2,Component pouch;Arcane Focus,Dungeoneer's pack;Explorer's Pack | O38: Dragon Ancestery | P38: Font of Magic | Q38: Metamagic | R38: Ability Score Improvement | S38: - | T38: Elemental Affinity | U38: - | V38: Ability Score Improvement | W38: - | X38: Metamagic | Y38: - | Z38: Ability Score Improvement | AA38: - | AB38: Dragon Wings | AC38: - | AD38: Ability Score Improvement | AE38: Metamagic | AF38: Draconic Presence | AG38: Ability Score Improvement | AH38: Sorcerous Restoration | AI38: Full | AJ38: Car | AK38: --
A39: HECHICERO | B39: BRUJO | C39: -
A40: HECHICERO | B40: PÍCARO | C40: -
...

Sheet Sheet1
C1: Templario
A2: Nivel | B2: Proficiency Bonus | C2: Características | D2: 1st Level Slots | E2: 2nd Level Slots | F2: 3rd Level Slots | G2: 4th Level Slots | H2: 5th Level Slots
A3: 1 | B3: =+2 -> 2 | C3: Oraciones Menores, Sentido Divino, Manos Sanadoras | D3: 2 | E3: – | F3: – | G3: – | H3: –
A4: 2 | B4: =+2 -> 2 | C4: Estilo de Combate, Golpe Divino Menor | D4: 2 | E4: – | F4: – | G4: – | H4: –
A5: 3 | B5: =+2 -> 2 | C5: Magia de Fe (Nivel 1), Canalizar Divinidad | D5: 3 | E5: – | F5: – | G5: – | H5: –
A6: 4 | B6: =+2 -> 2 | C6: Mejora de Características | D6: 3 | E6: – | F6: – | G6: – | H6: –
A7: 5 | B7: =+3 -> 3 | C7: Ataque Extra (1) | D7: 4 | E7: 2 | F7: – | G7: – | H7: –
A8: 6 | B8: =+3 -> 3 | C8: Aura de Protección | D8: 4 | E8: 2 | F8: – | G8: – | H8: –
A9: 7 | B9: =+3 -> 3 | C9: Escudo de Fe Mayor | D9: 4 | E9: 3 | F9: – | G9: – | H9: –
A10: 8 | B10: =+3 -> 3 | C10: Mejora de Características | D10: 4 | E10: 3 | F10: – | G10: – | H10: –
A11: 9 | B11: =+4 -> 4 | C11: Aura de Fe | D11: 4 | E11: 3 | F11: 2 | G11: – | H11: –
A12: 10 | B12: =+4 -> 4 | C12: Invocación de Camarada de Luz | D12: 4 | E12: 3 | F12: 2 | G12: – | H12: –
A13: 11 | B13: =+4 -> 4 | C13: Luz Sagrada Mejorada | D13: 4 | E13: 3 | F13: 3 | G13: – | H13: –
A14: 12 | B14: =+4 -> 4 | C14: Aura de Coraje | D14: 4 | E14: 3 | F14: 3 | G14: – | H14: –
A15: 13 | B15: =+5 -> 5 | C15: Escudo de Fe Celestial | D15: 4 | E15: 3 | F15: 3 | G15: 1 | H15: –
A16: 14 | B16: =+5 -> 5 | C16: Mejora de Características | D16: 4 | E16: 3 | F16: 3 | G16: 1 | H16: –
A17: 15 | B17: =+5 -> 5 | C17: Rayo de Justicia | D17: 4 | E17: 3 | F17: 3 | G17: 2 | H17: –
A18: 16 | B18: =+5 -> 5 | C18: Aura de Protección Mayor | D18: 4 | E18: 3 | F18: 3 | G18: 2 | H18: –
A19: 17 | B19: =+6 -> 6 | C19: Mejora de Características | D19: 4 | E19: 3 | F19: 3 | G19: 3 | H19: 1
A20: 18 | B20: =+6 -> 6 | C20: Potenciación Suprema | D20: 4 | E20: 3 | F20: 3 | G20: 3 | H20: 1
A21: 19 | B21: =+6 -> 6 | C21: Aura de Fe Mejorada | D21: 4 | E21: 3 | F21: 3 | G21: 3 | H21: 2
A22: 20 | B22: =+6 -> 6 | C22: Forma Divina | D22: 4 | E22: 3 | F22: 3 | G22: 3 | H22: 2
C24: Apostat
A25: Nivel | B25: Proficiency Bonus | C25: Características | D25: 1st Level Slots | E25: 2nd Level Slots | F25: 3rd Level Slots | G25: 4th Level Slots | H25: 5th Level Slots
A26: 1 | B26: =+2 -> 2 | C26: Marca de la Oscuridad, Sacrificio de Vida | D26: 2 | E26: - | F26: - | G26: - | H26: -
A27: 2 | B27: =+2 -> 2 | C27: Maldición Menor, Escudo de Sombras | D27: 2 | E27: - | F27: - | G27: - | H27: -
A28: 3 | B28: =+2 -> 2 | C28: Invocación de Sombras, Sacrificio de Vida (Mejorado) | D28: 3 | E28: - | F28: - | G28: - | H28: -
A29: 4 | B29: =+2 -> 2 | C29: Mejora de Características | D29: 3 | E29: - | F29: - | G29: - | H29: -
A30: 5 | B30: =+3 -> 3 | C30: Maldición de la Muerte | D30: 4 | E30: 2 | F30: - | G30: - | H30: -
A31: 6 | B31: =+3 -> 3 | C31: Escudo de Sombras Mejorado | D31: 4 | E31: 2 | F31: - | G31: - | H31: -
A32: 7 | B32: =+3 -> 3 | C32: Maldición de Dolor | D32: 4 | E32: 3 | F32: - | G32: - | H32: -
A33: 8 | B33: =+3 -> 3 | C33: Mejora de Características | D33: 4 | E33: 3 | F33: - | G33: - | H33: -
A34: 9 | B34: =+4 -> 4 | C34: Maldición de la Desesperación | D34: 4 | E34: 3 | F34: 2 | G34: - | H34: -
A35: 10 | B35: =+4 -> 4 | C35: Bendición Profana Mejorada | D35: 4 | E35: 3 | F35: 2 | G35: - | H35: -
A36: 11 | B36: =+4 -> 4 | C36: Escudo Oscuro Definitivo | D36: 4 | E36: 3 | F36: 3 | G36: - | H36: -
A37: 12 | B37: =+4 -> 4 | C37: Mejora de Características | D37: 4 | E37: 3 | F37: 3 | G37: - | H37: -
A38: 13 | B38: =+5 -> 5 | C38: Rayo de Oscuridad | D38: 4 | E38: 3 | F38: 3 | G38: 1 | H38: -
A39: 14 | B39: =+5 -> 5 | C39: Maestro de Maldiciones | D39: 4 | E39: 3 | F39: 3 | G39: 1 | H39: -
A40: 15 | B40: =+5 -> 5 | C40: Maldición de Agonía | D40: 4 | E40: 3 | F40: 3 | G40: 2 | H40: -
A41: 16 | B41: =+5 -> 5 | C41: Mejora de Características | D41: 4 | E41: 3 | F41: 3 | G41: 2 | H41: -
...

Sheet Razas
A1: Race | B1: Subrace | C1: Region | D1: AL legal? | E1: Dark Vision | F1: Incidence | G1: Size | H1: Speed | I1: Nadar | J1: Volar | K1: Language | L1: Str | M1: Dex | N1: Con | O1: Int | P1: Wis | Q1: Cha | R1: Profecys | S1: Extra | T1: Source
A2: Hombres Lagarto
A3: Hombres Lagarto | B3: (none) | D3: AL | E3: 60 | F3: Very Rare | G3: M | H3: 30 | I3: 30 | K3: Common, Draconic | L3: - | M3: - | N3: 2 | O3: - | P3: 1 | Q3: - | R3: ="2 skills: "&'Habilidades de Rol'!D60 -> 2 skills: Trato con animales, Naturaleza, Percepcion, Sigilo, Supervivencia, | S3: Hold breath 15min; Bite; Hungry Jaws; Natural Armor; Cunning Artisan | T3: Volo's 111
A4: Hombres Lagarto | B4: (none) | D4: AL | E4: 60 | F4: Monster | G4: S | H4: 30 | K4: Common, Draconic | L4: - | M4: 2 | N4: - | O4: 1 | P4: - | Q4: - | R4: ="1 skills: "&'Habilidades de Rol'!D61 -> 1 skills: Trato con animales, Naturaleza, Percepcion, Sigilo, Supervivencia, | S4: Sunlight Sensitivity; Grovel, Cower, Beg; Pack Tactics | T4: Volo's 119
A5: Hombres Pájaro
A6: Hombres Pájaro | B6: (none) | E6: 0 | F6: Very Rare | G6: M | H6: 25 | J6: 50 | K6: Common, Aarakocra, Auran | L6: - | M6: 2 | N6: - | O6: - | P6: 1 | Q6: - | R6: ="1 skills: "&'Habilidades de Rol'!D63 -> 1 skills: | S6: Talons (1d4) | T6: EE 4
A7: Hombres Pájaro | B7: Protector | D7: AL | E7: 20 | H7: 25 | L7: - | M7: - | N7: - | O7: - | P7: 1 | Q7: 2 | R7: ="1 skills: "&'Habilidades de Rol'!D64 -> 1 skills: | S7: Radiant Soul (mobility; damage buff) | T7: Volo's 105
A8: Hombres Gato
A9: Hombres Gato | B9: (none) | D9: AL | E9: 60 | F9: Rare | G9: M | H9: 30 | K9: Common, +1 | L9: - | M9: 2 | N9: - | O9: - | P9: - | Q9: 1 | R9: ="2 skills: "&'Habilidades de Rol'!D66 -> 2 skills: Percepcion, Sigilo, | S9: 20' climb; Feline Agility (temp. speed*2); Cat's Claws | T9: Volo's 113
A10: Hombres Gato | B10: Leonin | E10: 60 | F10: Rare | G10: M | H10: 35 | K10: Common, Leonin | L10: 1 | M10: - | N10: 2 | O10: - | P10: - | Q10: - | R10: ="1 skills: "&'Habilidades de Rol'!D67 -> 1 skills: | S10: Claws; Hunter's Instinct; Daunting Roar | T10: MOT
A11: Minotauros
A12: Minotauros | B12: (none) | E12: 0 | F12: Ravnica | G12: M | H12: 40 | K12: Common, Sylvan | L12: 2 | M12: - | N12: - | O12: - | P12: 1 | Q12: - | R12: ="2 skills: "&'Habilidades de Rol'!D69 -> 2 skills: | S12: Charge; Hooves; Equine Build; +1 skill (select); type fey | T12: Ravnica
A13: Sagas
A14: Sagas | B14: (none) | D14: AL | E14: 60 | F14: Rare | G14: M | H14: 30 | K14: Common, Elvish, Giant | L14: 1 | M14: - | N14: - | O14: - | P14: 2 | Q14: - | R14: ="1 skills: "&'Habilidades de Rol'!D71 -> 1 skills: | S14: Firbolg Magic; Hidden Step; Powerful Build; Speech of Beast/Leaf | T14: Volo's 106-107
A15: Sagas | B15: Avariel | E15: 60 | F15: Very Rare | H15: 30 | J15: 30 | K15: + Auran | L15: - | M15: 2 | N15: - | O15: - | P15: - | Q15: 1 | R15: ="1 skills: "&'Habilidades de Rol'!D72 -> 1 skills: | T15: Elf Sub
A16: Sagas | B16: Grugach | E16: 60 | F16: Greyhawk | H16: 30 | K16: - Common; + Sylvan | L16: 1 | M16: 2 | N16: - | O16: - | P16: - | Q16: - | R16: ="1 skills: "&'Habilidades de Rol'!D73 -> 1 skills: | S16: Grugach Weapon Training; Cantrip (Druid) | T16: Elf Sub
A17: Sagas | B17: (none) | E17: 60 | F17: Very Rare | G17: M | H17: 35 | K17: Common, Sylvan | L17: - | M17: 1 | N17: - | O17: - | P17: - | Q17: 2 | R17: ="2 skills: "&'Habilidades de Rol'!D74 -> 2 skills: Interpretacion, Persuasion, | S17: Fey; Ram (1d4 + Str); Magic Resistence; Mirthful Leaps; | T17: MOT
A18: Orc
A19: Orc | B19: (none) | D19: AL | E19: 60 | F19: Monster | G19: M | H19: 30 | K19: Common, Orc | L19: =+2 -> 2 | M19: - | N19: =+1 -> 1 | O19: - | P19: - | Q19: - | R19: ="1 skills: "&'Habilidades de Rol'!D76 -> 1 skills: Percepcion, | S19: Aggressive (bonus action Dash toward enemy); Powerful Build; Intimidation skill | T19: Volo's 120
A20: Half-Orc | B20: (none) | D20: AL | E20: 60 | F20: Uncommon | G20: M | H20: 30 | K20: Common, Orc | L20: 2 | M20: - | N20: 1 | O20: - | P20: - | Q20: - | R20: ="2 skills: "&'Habilidades de Rol'!D77 -> 2 skills: Intimidacion, | S20: Relentless Endurance; Savage Attacks | T20: PHB 40
A21: Orc | B21: Githyanki | D21: AL | E21: 60 | H21: 30 | K21: +1 | L21: 2 | M21: - | N21: - | O21: 1 | P21: - | Q21: - | R21: ="1 skills: "&'Habilidades de Rol'!D78 -> 1 skills: | S21: Light & Medium Armor prof.; Shortsword, Longsword, Greatsword prof.; +1 skill/tool; Githyanki Psionics (spells) | T21: Mordenkainen
A22: Enanos
A23: Medianos | B23: (choose one) | D23: AL | E23: 60 | F23: Common | G23: M | H23: 25 | K23: Common, Dwarf | L23: - | M23: - | N23: - | O23: - | P23: - | Q23: - | R23: ="1 skills: "&'Habilidades de Rol'!D80 -> 1 skills: | S23: Dwarven Combat Training; Stone-cunning; Adv. on poison saves; Poison Res.; Smith's/Brewer's/Mason's tools prof.; Speed not reduced by heavy armor | T23: PHB 18
A24: Dwarf | B24: Hill | D24: AL | E24: 60 | H24: 25 | L24: - | M24: - | N24: 2 | O24: - | P24: =+1 -> 1 | Q24: - | R24: ="1 skills: "&'Habilidades de Rol'!D81 -> 1 skills: | S24: HP max +1 per level | T24: PHB 20
A25: Dwarf | B25: Mountain | D25: AL | E25: 60 | H25: 25 | L25: =+2 -> 2 | M25: - | N25: 2 | O25: - | P25: - | Q25: - | R25: ="1 skills: "&'Habilidades de Rol'!D82 -> 1 skills: | S25: Light & Medium Armor prof. | T25: PHB 20
A26: Dwarf | B26: Gray (Duergar) | D26: AL | E26: 120 | F26: Rare | H26: 25 | K26: + Undercommon | L26: =+1 -> 1 | M26: - | N26: 2 | O26: - | P26: - | Q26: - | R26: ="1 skills: "&'Habilidades de Rol'!D83 -> 1 skills: | S26: Sunlight Sens.; Duergar Magic; Illusion, charm and paralysis res. | T26: SCAG/Mord
A27: Elfos
A28: Elf | B28: High | D28: AL | E28: 60 | F28: Uncommon | H28: 30 | K28: +1 | L28: - | M28: 2 | N28: - | O28: =+1 -> 1 | P28: - | Q28: - | R28: ="1 skills: "&'Habilidades de Rol'!D85 -> 1 skills: | S28: Elf Weapon Training; +1 Wizard cantrip | T28: PHB 23, Rav
A29: Elf | B29: Wood | D29: AL | E29: 60 | F29: Uncommon | H29: 35 | L29: - | M29: 2 | N29: - | O29: - | P29: =+1 -> 1 | Q29: - | R29: ="1 skills: "&'Habilidades de Rol'!D86 -> 1 skills: | S29: Elf Weapon Training; Mask of the Wild | T29: PHB 24, Rav
A30: Elf | B30: Drow | D30: AL | E30: 120 | F30: Uncommon | H30: 30 | L30: - | M30: 2 | N30: - | O30: - | P30: - | Q30: =+1 -> 1 | R30: ="1 skills: "&'Habilidades de Rol'!D87 -> 1 skills: | S30: Sunlight Sens.; Drow Weapons Training; Drow Magic (spells) | T30: PHB 24, Rav
A31: Elf | B31: Eladrin | E31: 60 | F31: Very Rare | H31: 30 | L31: - | M31: 2 | N31: - | O31: =+1 -> 1 | P31: - | Q31: - | R31: ="1 skills: "&'Habilidades de Rol'!D88 -> 1 skills: | S31: Elf Weapon Training; Fey Step | T31: DMG 286
A32: Half-Elf | B32: Half-Wood | D32: AL | E32: 45 | F32: Extremly rare | H32: 30 | L32: - | M32: 1 | N32: - | O32: - | P32: - | Q32: 2 | R32: ="1 skills: "&'Habilidades de Rol'!D89 -> 1 skills: | S32: (-Skill Versatility); Elf Weapon Training or Fleet of Foot or Mask of the Wild | T32: SCAG 116
A33: Half-Elf | B33: Half-Moon/Sun | D33: AL | E33: 45 | F33: Extremly rare | H33: 30 | L33: - | M33: 1 | N33: - | O33: - | P33: - | Q33: 2 | R33: ="1 skills: "&'Habilidades de Rol'!D90 -> 1 skills: | S33: (-Skill Versatility); Elf Weapon Training or +1 Wizard cantrip | T33: SCAG 116
A34: Gnomos
A35: Gnome | B35: Forest | D35: AL | E35: 60 | H35: 25 | L35: - | M35: 1 | N35: - | O35: 2 | P35: - | Q35: - | R35: ="1 skills: "&'Habilidades de Rol'!D92 -> 1 skills: | S35: Minor Illusion cantrip; Speak with Small Beasts | T35: PHB 37
A36: Gnome | B36: Rock | D36: AL | E36: 60 | H36: 25 | L36: - | M36: - | N36: 1 | O36: 2 | P36: - | Q36: - | R36: ="1 skills: "&'Habilidades de Rol'!D93 -> 1 skills: | S36: Artificer's Lore; Tinker | T36: PHB 37
A37: Gnome | B37: Deep | D37: AL | E37: 120 | F37: Rare | H37: 25 | K37: + Undercommon | L37: - | M37: 1 | N37: - | O37: 2 | P37: - | Q37: - | R37: ="1 skills: "&'Habilidades de Rol'!D94 -> 1 skills: | S37: Adv. on Stealth to hide in rocky terrain; (Feat opportunity: Svirfneblin Magic) | T37: SCAG/Mord
A38: Yokai
A39: Yokai | B39: (none) | F39: Krynn | G39: S | H39: 25 | K39: Common, Kenderspeak | L39: - | M39: 1 | N39: - | O39: 2 | P39: - | Q39: 1 | R39: ="1 skills: "&'Habilidades de Rol'!D96 -> 1 skills: | S39: Immune to Frightened; Taunt; Kender Pockets | T39: Playtest: Races 11
A40: Locathah | B40: (none) | F40: Very Rare | G40: M | H40: 30 | I40: 30 | K40: Common, Aquan | L40: 2 | M40: 1 | N40: - | O40: - | P40: - | Q40: - | R40: ="1 skills: "&'Habilidades de Rol'!D97 -> 1 skills: | S40: Natural Armor; Athletics & Perception skills; Leviathan Will (Saving throws advantage); Limited Amphibiousness | T40: Locathah Rising
...

Sheet Habilidades de Rol
D1: Background | R1: Class | AE1: Gods
A2: Skill | C2: Ability Score | D2: =A37 -> Acolito | E2: =A38 -> Charalatan | F2: =A39 -> Criminal | G2: =A40 -> Artista | H2: =A41 -> Heroe del pueblo | I2: =A42 -> Artista Gremial | J2: =A43 -> Hermitaño | K2: =A44 -> Noble | L2: =A45 -> Fujitivo | M2: =A46 -> Sabio | N2: =A47 -> Marinero | O2: =A48 -> Soldado | P2: =A49 -> Huerfano | R2: =A23 -> BÁRBARO | S2: =A24 -> BARDO | T2: =A25 -> ARTIFICIERO | U2: =A26 -> DRUIDA | V2: =A27 -> GUERRERO | W2: =A28 -> CHAMÁN | X2: =A29 -> PALADIN | Y2: =A30 -> CAZADOR | Z2: =A31 -> PÍCARO | AA2: =A32 -> HECHICERO | AB2: =A33 -> BRUJO | AC2: =A34 -> MAGO | AE2: =A52 -> EGOS | AF2: =A53 -> EROS | AG2: =A54 -> CHRONOS | AH2: =A55 -> SOFIA | AI2: =A56 -> ENVIDIA | AJ2: =A57 -> VIDA | AK2: =A58 -> MUERTE | AM2: =$A60 -> Hombres Lagarto | AN2: =$A61 -> Hombres Lagarto | AO2: =$A63 -> Hombres Pájaro | AP2: =$A64 -> Hombres Pájaro | AQ2: =$A66 -> Hombres Gato | AR2: =$A67 -> Hombres Gato | AS2: =$A69 -> Minotauros | AT2: =$A71 -> Sagas | AU2: =$A72 -> Sagas | AV2: =$A73 -> Sagas | AW2: =$A74 -> Sagas | AX2: =$A76 -> Orc | AY2: =$A77 -> Half-Orc | AZ2: =$A78 -> Orc | BA2: =$A80 -> Medianos | BB2: =$A81 -> Dwarf | BC2: =$A82 -> Dwarf | BD2: =$A83 -> Dwarf | BE2: =$A85 -> Elf | BF2: =$A86 -> Elf | BG2: =$A87 -> Elf | BH2: =$A88 -> Elf | BI2: =$A89 -> Half-Elf | BJ2: =$A90 -> Half-Elf | BK2: =$A92 -> Gnome | BL2: =$A93 -> Gnome | BM2: =$A94 -> Gnome | BN2: =$A96 -> Yokai | BO2: =$A97 -> Locathah | BP2: =$A98 -> Loxodon | BQ2: =$A100 -> Tiefling | BR2: =$A101 -> Tiefling | BS2: =$A102 -> Tiefling | BT2: =$A103 -> Tiefling | BU2: =$A105 -> No Muertos | BV2: =$A106 -> No Muertos | BW2: =$A107 -> No Muertos | BX2: =$A109 -> Nagas | BY2: =$A110 -> Nagas | BZ2: =$A111 -> Nagas | CA2: =$A113 -> Dracónidos | CB2: =$A114 -> Dracónidos | CC2: =$A115 -> Dracónidos | CD2: =$A116 -> Dracónidos | CE2: =$A117 -> Dracónidos | CF2: =$A118 -> Dracónidos | CG2: =$A120 -> Human | CH2: =$A121 -> Aegroum | CI2: =$A122 -> Ascaria | CJ2: =$A123 -> Bastrea | CK2: =$A124 -> Bastrea - Semi-Elfo | CL2: =$A125 -> Perdidos | CM2: =$A127 -> Elemental | CN2: =$A128 -> Elemental | CO2: =$A129 -> Elemental | CP2: =$A130 -> Elemental | CQ2: =$A131 -> Elemental | CR2: =$A132 -> Elemental | CS2: =$A134 -> Goblin | CT2: =$A135 -> Goblin | CU2: =$A136 -> Goblin | CV2: =$A137 -> Hobgoblin | CW2: =$A138 -> Verdan
A4: Acrobacias | C4: Destreza | G4: X | S4: X | V4: X | W4: X | Z4: X
A5: Trato con animales | C5: Sabiduria | H5: X | R5: X | S5: X | U5: X | V5: X | Y5: X | AM5: X | AN5: X
A6: Arcano | C6: Inteligencia | M6: X | S6: X | T6: X | U6: X | AA6: X | AB6: X | AC6: X
A7: Atletismo | C7: Fuerza | L7: X | N7: X | O7: X | R7: X | S7: X | T7: X | V7: X | W7: X | X7: X | Y7: X | Z7: X
A8: Engaño | C8: Carisma | E8: X | F8: X | S8: X | Z8: X | AA8: X | AB8: X | BZ8: X
A9: Historia | C9: Inteligencia | K9: X | M9: X | S9: X | T9: X | V9: X | W9: X | AB9: X | AC9: X
A10: Perspicacia | C10: Sabiduria | D10: X | I10: X | S10: X | T10: X | U10: X | V10: X | W10: X | X10: X | Y10: X | Z10: X | AA10: X | AC10: X
A11: Intimidacion | C11: Carisma | O11: X | R11: X | S11: X | V11: X | X11: X | Z11: X | AA11: X | AB11: X | AY11: X
A12: Investigacion | C12: Inteligencia | S12: X | T12: X | Y12: X | Z12: X | AB12: X | AC12: X
A13: Medicina | C13: Sabiduria | J13: X | S13: X | T13: X | U13: X | X13: X | AC13: X
A14: Naturaleza | C14: Inteligencia | R14: X | S14: X | T14: X | U14: X | Y14: X | AB14: X | AM14: X | AN14: X
A15: Percepcion | C15: Sabiduria | N15: X | R15: X | S15: X | T15: X | U15: X | V15: X | Y15: X | Z15: X | AM15: X | AN15: X | AQ15: X | AX15: X
A16: Interpretacion | C16: Carisma | G16: X | S16: X | Z16: X | AW16: X
A17: Persuasion | C17: Carisma | I17: X | K17: X | S17: X | X17: X | Z17: X | AA17: X | AW17: X | BZ17: X
A18: Religion | C18: Inteligencia | D18: X | J18: X | S18: X | U18: X | W18: X | X18: X | AA18: X | AB18: X | AC18: X
A19: Juego de Manos | C19: Destreza | E19: X | P19: X | S19: X | T19: X | Z19: X | BY19: X
A20: Sigilo | C20: Destreza | F20: X | P20: X | S20: X | W20: X | Y20: X | Z20: X | AM20: X | AN20: X | AQ20: X | BY20: X
A21: Supervivencia | C21: Sabiduria | H21: X | L21: X | R21: X | S21: X | U21: X | V21: X | Y21: X | AM21: X | AN21: X
A23: BÁRBARO | D23: =IF(R4="X",$A$4&", ","")&IF(R5="X",$A$5&", ","")&IF(R6="X",$A$6&", ","")&IF(R7="X",$A$7&", ","")&IF(R8="X",$A$8&", ","")&IF(R9="X",$A$9&", ","")&IF(R10="X",$A$10&", ","")&IF(R11="X",$A$11&", ","")&IF(R12="X",$A12&", ","")&IF(R13="X",$A13&", ","")&IF(R14="X",$A14&", ","")&IF(R15="X",$A15&", ","")&IF(R16="X",$A16&", ","")&IF(R17="X",$A17&", ","")&IF(R18="X",$A18&", ","")&IF(R19="X",$A19&", ","")&IF(R20="X",$A20&", ","")&IF(R21="X",$A21&", ","") -> Trato con animales, Atletismo, Intimidacion, Naturaleza, Percepcion, Supervivencia,
A24: BARDO | D24: =IF(S4="X",$A$4&", ","")&IF(S5="X",$A$5&", ","")&IF(S6="X",$A$6&", ","")&IF(S7="X",$A$7&", ","")&IF(S8="X",$A$8&", ","")&IF(S9="X",$A$9&", ","")&IF(S10="X",$A$10&", ","")&IF(S11="X",$A$11&", ","")&IF(S12="X",$A12&", ","")&IF(S13="X",$A13&", ","")&IF(S14="X",$A14&", ","")&IF(S15="X",$A15&", ","")&IF(S16="X",$A16&", ","")&IF(S17="X",$A17&", ","")&IF(S18="X",$A18&", ","")&IF(S19="X",$A19&", ","")&IF(S20="X",$A20&", ","")&IF(S21="X",$A21&", ","") -> Acrobacias, Trato con animales, Arcano, Atletismo, Engaño, Historia, Perspicacia, Intimidacion, Investigacion, Medicina, Naturaleza, Percepcion, Interpretacion, Persuasion, Religion, Juego de Manos, Sigilo, Supervivencia,
A25: ARTIFICIERO | D25: =IF(T4="X",$A$4&", ","")&IF(T5="X",$A$5&", ","")&IF(T6="X",$A$6&", ","")&IF(T7="X",$A$7&", ","")&IF(T8="X",$A$8&", ","")&IF(T9="X",$A$9&", ","")&IF(T10="X",$A$10&", ","")&IF(T11="X",$A$11&", ","")&IF(T12="X",$A12&", ","")&IF(T13="X",$A13&", ","")&IF(T14="X",$A14&", ","")&IF(T15="X",$A15&", ","")&IF(T16="X",$A16&", ","")&IF(T17="X",$A17&", ","")&IF(T18="X",$A18&", ","")&IF(T19="X",$A19&", ","")&IF(T20="X",$A20&", ","")&IF(T21="X",$A21&", ","") -> Arcano, Atletismo, Historia, Perspicacia, Investigacion, Medicina, Naturaleza, Percepcion, Juego de Manos,
A26: DRUIDA | D26: =IF(U4="X",$A$4&", ","")&IF(U5="X",$A$5&", ","")&IF(U6="X",$A$6&", ","")&IF(U7="X",$A$7&", ","")&IF(U8="X",$A$8&", ","")&IF(U9="X",$A$9&", ","")&IF(U10="X",$A$10&", ","")&IF(U11="X",$A$11&", ","")&IF(U12="X",$A12&", ","")&IF(U13="X",$A13&", ","")&IF(U14="X",$A14&", ","")&IF(U15="X",$A15&", ","")&IF(U16="X",$A16&", ","")&IF(U17="X",$A17&", ","")&IF(U18="X",$A18&", ","")&IF(U19="X",$A19&", ","")&IF(U20="X",$A20&", ","")&IF(U21="X",$A21&", ","") -> Trato con animales, Arcano, Perspicacia, Medicina, Naturaleza, Percepcion, Religion, Supervivencia,
A27: GUERRERO | D27: =IF(V4="X",$A$4&", ","")&IF(V5="X",$A$5&", ","")&IF(V6="X",$A$6&", ","")&IF(V7="X",$A$7&", ","")&IF(V8="X",$A$8&", ","")&IF(V9="X",$A$9&", ","")&IF(V10="X",$A$10&", ","")&IF(V11="X",$A$11&", ","")&IF(V12="X",$A12&", ","")&IF(V13="X",$A13&", ","")&IF(V14="X",$A14&", ","")&IF(V15="X",$A15&", ","")&IF(V16="X",$A16&", ","")&IF(V17="X",$A17&", ","")&IF(V18="X",$A18&", ","")&IF(V19="X",$A19&", ","")&IF(V20="X",$A20&", ","")&IF(V21="X",$A21&", ","") -> Acrobacias, Trato con animales, Atletismo, Historia, Perspicacia, Intimidacion, Percepcion, Supervivencia,
A28: CHAMÁN | D28: =IF(W4="X",$A$4&", ","")&IF(W5="X",$A$5&", ","")&IF(W6="X",$A$6&", ","")&IF(W7="X",$A$7&", ","")&IF(W8="X",$A$8&", ","")&IF(W9="X",$A$9&", ","")&IF(W10="X",$A$10&", ","")&IF(W11="X",$A$11&", ","")&IF(W12="X",$A12&", ","")&IF(W13="X",$A13&", ","")&IF(W14="X",$A14&", ","")&IF(W15="X",$A15&", ","")&IF(W16="X",$A16&", ","")&IF(W17="X",$A17&", ","")&IF(W18="X",$A18&", ","")&IF(W19="X",$A19&", ","")&IF(W20="X",$A20&", ","")&IF(W21="X",$A21&", ","") -> Acrobacias, Atletismo, Historia, Perspicacia, Religion, Sigilo,
A29: PALADIN | D29: =IF(X4="X",$A$4&", ","")&IF(X5="X",$A$5&", ","")&IF(X6="X",$A$6&", ","")&IF(X7="X",$A$7&", ","")&IF(X8="X",$A$8&", ","")&IF(X9="X",$A$9&", ","")&IF(X10="X",$A$10&", ","")&IF(X11="X",$A$11&", ","")&IF(X12="X",$A12&", ","")&IF(X13="X",$A13&", ","")&IF(X14="X",$A14&", ","")&IF(X15="X",$A15&", ","")&IF(X16="X",$A16&", ","")&IF(X17="X",$A17&", ","")&IF(X18="X",$A18&", ","")&IF(X19="X",$A19&", ","")&IF(X20="X",$A20&", ","")&IF(X21="X",$A21&", ","") -> Atletismo, Perspicacia, Intimidacion, Medicina, Persuasion, Religion,
A30: CAZADOR | D30: =IF(Y4="X",$A$4&", ","")&IF(Y5="X",$A$5&", ","")&IF(Y6="X",$A$6&", ","")&IF(Y7="X",$A$7&", ","")&IF(Y8="X",$A$8&", ","")&IF(Y9="X",$A$9&", ","")&IF(Y10="X",$A$10&", ","")&IF(Y11="X",$A$11&", ","")&IF(Y12="X",$A12&", ","")&IF(Y13="X",$A13&", ","")&IF(Y14="X",$A14&", ","")&IF(Y15="X",$A15&", ","")&IF(Y16="X",$A16&", ","")&IF(Y17="X",$A17&", ","")&IF(Y18="X",$A18&", ","")&IF(Y19="X",$A19&", ","")&IF(Y20="X",$A20&", ","")&IF(Y21="X",$A21&", ","") -> Trato con animales, Atletismo, Perspicacia, Investigacion, Naturaleza, Percepcion, Sigilo, Supervivencia,
A31: PÍCARO | D31: =IF(Z4="X",$A$4&", ","")&IF(Z5="X",$A$5&", ","")&IF(Z6="X",$A$6&", ","")&IF(Z7="X",$A$7&", ","")&IF(Z8="X",$A$8&", ","")&IF(Z9="X",$A$9&", ","")&IF(Z10="X",$A$10&", ","")&IF(Z11="X",$A$11&", ","")&IF(Z12="X",$A12&", ","")&IF(Z13="X",$A13&", ","")&IF(Z14="X",$A14&", ","")&IF(Z15="X",$A15&", ","")&IF(Z16="X",$A16&", ","")&IF(Z17="X",$A17&", ","")&IF(Z18="X",$A18&", ","")&IF(Z19="X",$A19&", ","")&IF(Z20="X",$A20&", ","")&IF(Z21="X",$A21&", ","") -> Acrobacias, Atletismo, Engaño, Perspicacia, Intimidacion, Investigacion, Percepcion, Interpretacion, Persuasion, Juego de Manos, Sigilo,
A32: HECHICERO | D32: =IF(AA4="X",$A$4&", ","")&IF(AA5="X",$A$5&", ","")&IF(AA6="X",$A$6&", ","")&IF(AA7="X",$A$7&", ","")&IF(AA8="X",$A$8&", ","")&IF(AA9="X",$A$9&", ","")&IF(AA10="X",$A$10&", ","")&IF(AA11="X",$A$11&", ","")&IF(AA12="X",$A12&", ","")&IF(AA13="X",$A13&", ","")&IF(AA14="X",$A14&", ","")&IF(AA15="X",$A15&", ","")&IF(AA16="X",$A16&", ","")&IF(AA17="X",$A17&", ","")&IF(AA18="X",$A18&", ","")&IF(AA19="X",$A19&", ","")&IF(AA20="X",$A20&", ","")&IF(AA21="X",$A21&", ","") -> Arcano, Engaño, Perspicacia, Intimidacion, Persuasion, Religion,
A33: BRUJO | D33: =IF(AB4="X",$A$4&", ","")&IF(AB5="X",$A$5&", ","")&IF(AB6="X",$A$6&", ","")&IF(AB7="X",$A$7&", ","")&IF(AB8="X",$A$8&", ","")&IF(AB9="X",$A$9&", ","")&IF(AB10="X",$A$10&", ","")&IF(AB11="X",$A$11&", ","")&IF(AB12="X",$A12&", ","")&IF(AB13="X",$A13&", ","")&IF(AB14="X",$A14&", ","")&IF(AB15="X",$A15&", ","")&IF(AB16="X",$A16&", ","")&IF(AB17="X",$A17&", ","")&IF(AB18="X",$A18&", ","")&IF(AB19="X",$A19&", ","")&IF(AB20="X",$A20&", ","")&IF(AB21="X",$A21&", ","") -> Arcano, Engaño, Historia, Intimidacion, Investigacion, Naturaleza, Religion,
A34: MAGO | D34: =IF(AC4="X",$A$4&", ","")&IF(AC5="X",$A$5&", ","")&IF(AC6="X",$A$6&", ","")&IF(AC7="X",$A$7&", ","")&IF(AC8="X",$A$8&", ","")&IF(AC9="X",$A$9&", ","")&IF(AC10="X",$A$10&", ","")&IF(AC11="X",$A$11&", ","")&IF(AC12="X",$A12&", ","")&IF(AC13="X",$A13&", ","")&IF(AC14="X",$A14&", ","")&IF(AC15="X",$A15&", ","")&IF(AC16="X",$A16&", ","")&IF(AC17="X",$A17&", ","")&IF(AC18="X",$A18&", ","")&IF(AC19="X",$A19&", ","")&IF(AC20="X",$A20&", ","")&IF(AC21="X",$A21&", ","") -> Arcano, Historia, Perspicacia, Investigacion, Medicina, Religion,
A37: Acolito | D37: =IF(D4="X",$A$4&", ","")&IF(D5="X",$A$5&", ","")&IF(D6="X",$A$6&", ","")&IF(D7="X",$A$7&", ","")&IF(D8="X",$A$8&", ","")&IF(D9="X",$A$9&", ","")&IF(D10="X",$A$10&", ","")&IF(D11="X",$A$11&", ","")&IF(D12="X",$A12&", ","")&IF(D13="X",$A13&", ","")&IF(D14="X",$A14&", ","")&IF(D15="X",$A15&", ","")&IF(D16="X",$A16&", ","")&IF(D17="X",$A17&", ","")&IF(D18="X",$A18&", ","")&IF(D19="X",$A19&", ","")&IF(D20="X",$A20&", ","")&IF(D21="X",$A21&", ","") -> Perspicacia, Religion,
A38: Charalatan | D38: =IF(E4="X",$A$4&", ","")&IF(E5="X",$A$5&", ","")&IF(E6="X",$A$6&", ","")&IF(E7="X",$A$7&", ","")&IF(E8="X",$A$8&", ","")&IF(E9="X",$A$9&", ","")&IF(E10="X",$A$10&", ","")&IF(E11="X",$A$11&", ","")&IF(E12="X",$A12&", ","")&IF(E13="X",$A13&", ","")&IF(E14="X",$A14&", ","")&IF(E15="X",$A15&", ","")&IF(E16="X",$A16&", ","")&IF(E17="X",$A17&", ","")&IF(E18="X",$A18&", ","")&IF(E19="X",$A19&", ","")&IF(E20="X",$A20&", ","")&IF(E21="X",$A21&", ","") -> Engaño, Juego de Manos,
A39: Criminal | D39: =IF(F4="X",$A$4&", ","")&IF(F5="X",$A$5&", ","")&IF(F6="X",$A$6&", ","")&IF(F7="X",$A$7&", ","")&IF(F8="X",$A$8&", ","")&IF(F9="X",$A$9&", ","")&IF(F10="X",$A$10&", ","")&IF(F11="X",$A$11&", ","")&IF(F12="X",$A12&", ","")&IF(F13="X",$A13&", ","")&IF(F14="X",$A14&", ","")&IF(F15="X",$A15&", ","")&IF(F16="X",$A16&", ","")&IF(F17="X",$A17&", ","")&IF(F18="X",$A18&", ","")&IF(F19="X",$A19&", ","")&IF(F20="X",$A20&", ","")&IF(F21="X",$A21&", ","") -> Engaño, Sigilo,
A40: Artista | D40: =IF(G4="X",$A$4&", ","")&IF(G5="X",$A$5&", ","")&IF(G6="X",$A$6&", ","")&IF(G7="X",$A$7&", ","")&IF(G8="X",$A$8&", ","")&IF(G9="X",$A$9&", ","")&IF(G10="X",$A$10&", ","")&IF(G11="X",$A$11&", ","")&IF(G12="X",$A12&", ","")&IF(G13="X",$A13&", ","")&IF(G14="X",$A14&", ","")&IF(G15="X",$A15&", ","")&IF(G16="X",$A16&", ","")&IF(G17="X",$A17&", ","")&IF(G18="X",$A18&", ","")&IF(G19="X",$A19&", ","")&IF(G20="X",$A20&", ","")&IF(G21="X",$A21&", ","") -> Acrobacias, Interpretacion,
A41: Heroe del pueblo | D41: =IF(H4="X",$A$4&", ","")&IF(H5="X",$A$5&", ","")&IF(H6="X",$A$6&", ","")&IF(H7="X",$A$7&", ","")&IF(H8="X",$A$8&", ","")&IF(H9="X",$A$9&", ","")&IF(H10="X",$A$10&", ","")&IF(H11="X",$A$11&", ","")&IF(H12="X",$A12&", ","")&IF(H13="X",$A13&", ","")&IF(H14="X",$A14&", ","")&IF(H15="X",$A15&", ","")&IF(H16="X",$A16&", ","")&IF(H17="X",$A17&", ","")&IF(H18="X",$A18&", ","")&IF(H19="X",$A19&", ","")&IF(H20="X",$A20&", ","")&IF(H21="X",$A21&", ","") -> Trato con animales, Supervivencia,
A42: Artista Gremial | D42: =IF(I4="X",$A$4&", ","")&IF(I5="X",$A$5&", ","")&IF(I6="X",$A$6&", ","")&IF(I7="X",$A$7&", ","")&IF(I8="X",$A$8&", ","")&IF(I9="X",$A$9&", ","")&IF(I10="X",$A$10&", ","")&IF(I11="X",$A$11&", ","")&IF(I12="X",$A12&", ","")&IF(I13="X",$A13&", ","")&IF(I14="X",$A14&", ","")&IF(I15="X",$A15&", ","")&IF(I16="X",$A16&", ","")&IF(I17="X",$A17&", ","")&IF(I18="X",$A18&", ","")&IF(I19="X",$A19&", ","")&IF(I20="X",$A20&", ","")&IF(I21="X",$A21&", ","") -> Perspicacia, Persuasion,
A43: Hermitaño | D43: =IF(J4="X",$A$4&", ","")&IF(J5="X",$A$5&", ","")&IF(J6="X",$A$6&", ","")&IF(J7="X",$A$7&", ","")&IF(J8="X",$A$8&", ","")&IF(J9="X",$A$9&", ","")&IF(J10="X",$A$10&", ","")&IF(J11="X",$A$11&", ","")&IF(J12="X",$A12&", ","")&IF(J13="X",$A13&", ","")&IF(J14="X",$A14&", ","")&IF(J15="X",$A15&", ","")&IF(J16="X",$A16&", ","")&IF(J17="X",$A17&", ","")&IF(J18="X",$A18&", ","")&IF(J19="X",$A19&", ","")&IF(J20="X",$A20&", ","")&IF(J21="X",$A21&", ","") -> Medicina, Religion,
A44: Noble | D44: =IF(K4="X",$A$4&", ","")&IF(K5="X",$A$5&", ","")&IF(K6="X",$A$6&", ","")&IF(K7="X",$A$7&", ","")&IF(K8="X",$A$8&", ","")&IF(K9="X",$A$9&", ","")&IF(K10="X",$A$10&", ","")&IF(K11="X",$A$11&", ","")&IF(K12="X",$A12&", ","")&IF(K13="X",$A13&", ","")&IF(K14="X",$A14&", ","")&IF(K15="X",$A15&", ","")&IF(K16="X",$A16&", ","")&IF(K17="X",$A17&", ","")&IF(K18="X",$A18&", ","")&IF(K19="X",$A19&", ","")&IF(K20="X",$A20&", ","")&IF(K21="X",$A21&", ","") -> Historia, Persuasion,
...
